2025-04-21 12:26:22,933 - ERROR - Unhandled exception: Traceback (most recent call last):   File "/Users/nagabhaskar.alaparthi/hackweek-ai-debugger/services/example_service.py", line 21, in simulate_divide_by_zero_error     result = 1 / 0              ~~^~~ ZeroDivisionError: division by zero  The above exception was the direct cause of the following exception:  Traceback (most recent call last):   File "/Users/nagabhaskar.alaparthi/hackweek-ai-debugger/venv/lib/python3.13/site-packages/starlette/middleware/errors.py", line 165, in __call__     await self.app(scope, receive, _send)   File "/Users/nagabhaskar.alaparthi/hackweek-ai-debugger/venv/lib/python3.13/site-packages/starlette/middleware/exceptions.py", line 62, in __call__     await wrap_app_handling_exceptions(self.app, conn)(scope, receive, send)   File "/Users/nagabhaskar.alaparthi/hackweek-ai-debugger/venv/lib/python3.13/site-packages/starlette/_exception_handler.py", line 53, in wrapped_app     raise exc   File "/Users/nagabhaskar.alaparthi/hackweek-ai-debugger/venv/lib/python3.13/site-packages/starlette/_exception_handler.py", line 42, in wrapped_app     await app(scope, receive, sender)   File "/Users/nagabhaskar.alaparthi/hackweek-ai-debugger/venv/lib/python3.13/site-packages/starlette/routing.py", line 714, in __call__     await self.middleware_stack(scope, receive, send)   File "/Users/nagabhaskar.alaparthi/hackweek-ai-debugger/venv/lib/python3.13/site-packages/starlette/routing.py", line 734, in app     await route.handle(scope, receive, send)   File "/Users/nagabhaskar.alaparthi/hackweek-ai-debugger/venv/lib/python3.13/site-packages/starlette/routing.py", line 288, in handle     await self.app(scope, receive, send)   File "/Users/nagabhaskar.alaparthi/hackweek-ai-debugger/venv/lib/python3.13/site-packages/starlette/routing.py", line 76, in app     await wrap_app_handling_exceptions(app, request)(scope, receive, send)   File "/Users/nagabhaskar.alaparthi/hackweek-ai-debugger/venv/lib/python3.13/site-packages/starlette/_exception_handler.py", line 53, in wrapped_app     raise exc   File "/Users/nagabhaskar.alaparthi/hackweek-ai-debugger/venv/lib/python3.13/site-packages/starlette/_exception_handler.py", line 42, in wrapped_app     await app(scope, receive, sender)   File "/Users/nagabhaskar.alaparthi/hackweek-ai-debugger/venv/lib/python3.13/site-packages/starlette/routing.py", line 73, in app     response = await f(request)                ^^^^^^^^^^^^^^^^   File "/Users/nagabhaskar.alaparthi/hackweek-ai-debugger/venv/lib/python3.13/site-packages/fastapi/routing.py", line 301, in app     raw_response = await run_endpoint_function(                    ^^^^^^^^^^^^^^^^^^^^^^^^^^^^     ...<3 lines>...     )     ^   File "/Users/nagabhaskar.alaparthi/hackweek-ai-debugger/venv/lib/python3.13/site-packages/fastapi/routing.py", line 214, in run_endpoint_function     return await run_in_threadpool(dependant.call, **values)            ^^^^^^^^^^^^^^^^^^^^^^^^^^^^^^^^^^^^^^^^^^^^^^^^^   File "/Users/nagabhaskar.alaparthi/hackweek-ai-debugger/venv/lib/python3.13/site-packages/starlette/concurrency.py", line 37, in run_in_threadpool     return await anyio.to_thread.run_sync(func)            ^^^^^^^^^^^^^^^^^^^^^^^^^^^^^^^^^^^^   File "/Users/nagabhaskar.alaparthi/hackweek-ai-debugger/venv/lib/python3.13/site-packages/anyio/to_thread.py", line 56, in run_sync     return await get_async_backend().run_sync_in_worker_thread(            ^^^^^^^^^^^^^^^^^^^^^^^^^^^^^^^^^^^^^^^^^^^^^^^^^^^^         func, args, abandon_on_cancel=abandon_on_cancel, limiter=limiter         ^^^^^^^^^^^^^^^^^^^^^^^^^^^^^^^^^^^^^^^^^^^^^^^^^^^^^^^^^^^^^^^^     )     ^   File "/Users/nagabhaskar.alaparthi/hackweek-ai-debugger/venv/lib/python3.13/site-packages/anyio/_backends/_asyncio.py", line 2470, in run_sync_in_worker_thread     return await future            ^^^^^^^^^^^^   File "/Users/nagabhaskar.alaparthi/hackweek-ai-debugger/venv/lib/python3.13/site-packages/anyio/_backends/_asyncio.py", line 967, in run     result = context.run(func, *args)   File "/Users/nagabhaskar.alaparthi/hackweek-ai-debugger/routers/example_router.py", line 20, in trigger_divide_by_zero_error     return ExampleService.simulate_divide_by_zero_error()            ~~~~~~~~~~~~~~~~~~~~~~~~~~~~~~~~~~~~~~~~~~~~^^   File "/Users/nagabhaskar.alaparthi/hackweek-ai-debugger/services/example_service.py", line 23, in simulate_divide_by_zero_error     raise RuntimeError("A division by zero error occurred.") from e RuntimeError: A division by zero error occurred. 
2025-04-21 12:27:41,985 - ERROR - Unhandled exception: Traceback (most recent call last):   File "/Users/nagabhaskar.alaparthi/hackweek-ai-debugger/services/example_service.py", line 21, in simulate_divide_by_zero_error     result = 1 / 0              ~~^~~ ZeroDivisionError: division by zero  The above exception was the direct cause of the following exception:  Traceback (most recent call last):   File "/Users/nagabhaskar.alaparthi/hackweek-ai-debugger/venv/lib/python3.13/site-packages/starlette/middleware/errors.py", line 165, in __call__     await self.app(scope, receive, _send)   File "/Users/nagabhaskar.alaparthi/hackweek-ai-debugger/venv/lib/python3.13/site-packages/starlette/middleware/exceptions.py", line 62, in __call__     await wrap_app_handling_exceptions(self.app, conn)(scope, receive, send)   File "/Users/nagabhaskar.alaparthi/hackweek-ai-debugger/venv/lib/python3.13/site-packages/starlette/_exception_handler.py", line 53, in wrapped_app     raise exc   File "/Users/nagabhaskar.alaparthi/hackweek-ai-debugger/venv/lib/python3.13/site-packages/starlette/_exception_handler.py", line 42, in wrapped_app     await app(scope, receive, sender)   File "/Users/nagabhaskar.alaparthi/hackweek-ai-debugger/venv/lib/python3.13/site-packages/starlette/routing.py", line 714, in __call__     await self.middleware_stack(scope, receive, send)   File "/Users/nagabhaskar.alaparthi/hackweek-ai-debugger/venv/lib/python3.13/site-packages/starlette/routing.py", line 734, in app     await route.handle(scope, receive, send)   File "/Users/nagabhaskar.alaparthi/hackweek-ai-debugger/venv/lib/python3.13/site-packages/starlette/routing.py", line 288, in handle     await self.app(scope, receive, send)   File "/Users/nagabhaskar.alaparthi/hackweek-ai-debugger/venv/lib/python3.13/site-packages/starlette/routing.py", line 76, in app     await wrap_app_handling_exceptions(app, request)(scope, receive, send)   File "/Users/nagabhaskar.alaparthi/hackweek-ai-debugger/venv/lib/python3.13/site-packages/starlette/_exception_handler.py", line 53, in wrapped_app     raise exc   File "/Users/nagabhaskar.alaparthi/hackweek-ai-debugger/venv/lib/python3.13/site-packages/starlette/_exception_handler.py", line 42, in wrapped_app     await app(scope, receive, sender)   File "/Users/nagabhaskar.alaparthi/hackweek-ai-debugger/venv/lib/python3.13/site-packages/starlette/routing.py", line 73, in app     response = await f(request)                ^^^^^^^^^^^^^^^^   File "/Users/nagabhaskar.alaparthi/hackweek-ai-debugger/venv/lib/python3.13/site-packages/fastapi/routing.py", line 301, in app     raw_response = await run_endpoint_function(                    ^^^^^^^^^^^^^^^^^^^^^^^^^^^^     ...<3 lines>...     )     ^   File "/Users/nagabhaskar.alaparthi/hackweek-ai-debugger/venv/lib/python3.13/site-packages/fastapi/routing.py", line 214, in run_endpoint_function     return await run_in_threadpool(dependant.call, **values)            ^^^^^^^^^^^^^^^^^^^^^^^^^^^^^^^^^^^^^^^^^^^^^^^^^   File "/Users/nagabhaskar.alaparthi/hackweek-ai-debugger/venv/lib/python3.13/site-packages/starlette/concurrency.py", line 37, in run_in_threadpool     return await anyio.to_thread.run_sync(func)            ^^^^^^^^^^^^^^^^^^^^^^^^^^^^^^^^^^^^   File "/Users/nagabhaskar.alaparthi/hackweek-ai-debugger/venv/lib/python3.13/site-packages/anyio/to_thread.py", line 56, in run_sync     return await get_async_backend().run_sync_in_worker_thread(            ^^^^^^^^^^^^^^^^^^^^^^^^^^^^^^^^^^^^^^^^^^^^^^^^^^^^         func, args, abandon_on_cancel=abandon_on_cancel, limiter=limiter         ^^^^^^^^^^^^^^^^^^^^^^^^^^^^^^^^^^^^^^^^^^^^^^^^^^^^^^^^^^^^^^^^     )     ^   File "/Users/nagabhaskar.alaparthi/hackweek-ai-debugger/venv/lib/python3.13/site-packages/anyio/_backends/_asyncio.py", line 2470, in run_sync_in_worker_thread     return await future            ^^^^^^^^^^^^   File "/Users/nagabhaskar.alaparthi/hackweek-ai-debugger/venv/lib/python3.13/site-packages/anyio/_backends/_asyncio.py", line 967, in run     result = context.run(func, *args)   File "/Users/nagabhaskar.alaparthi/hackweek-ai-debugger/routers/example_router.py", line 20, in trigger_divide_by_zero_error     return ExampleService.simulate_divide_by_zero_error()            ~~~~~~~~~~~~~~~~~~~~~~~~~~~~~~~~~~~~~~~~~~~~^^   File "/Users/nagabhaskar.alaparthi/hackweek-ai-debugger/services/example_service.py", line 23, in simulate_divide_by_zero_error     raise RuntimeError("A division by zero error occurred.") from e RuntimeError: A division by zero error occurred. 
2025-04-21 12:32:35,876 - ERROR - Unhandled exception: Traceback (most recent call last):   File "/Users/nagabhaskar.alaparthi/hackweek-ai-debugger/services/example_service.py", line 21, in simulate_divide_by_zero_error     result = 1 / 0              ~~^~~ ZeroDivisionError: division by zero  The above exception was the direct cause of the following exception:  Traceback (most recent call last):   File "/Users/nagabhaskar.alaparthi/hackweek-ai-debugger/venv/lib/python3.13/site-packages/starlette/middleware/errors.py", line 165, in __call__     await self.app(scope, receive, _send)   File "/Users/nagabhaskar.alaparthi/hackweek-ai-debugger/venv/lib/python3.13/site-packages/starlette/middleware/exceptions.py", line 62, in __call__     await wrap_app_handling_exceptions(self.app, conn)(scope, receive, send)   File "/Users/nagabhaskar.alaparthi/hackweek-ai-debugger/venv/lib/python3.13/site-packages/starlette/_exception_handler.py", line 53, in wrapped_app     raise exc   File "/Users/nagabhaskar.alaparthi/hackweek-ai-debugger/venv/lib/python3.13/site-packages/starlette/_exception_handler.py", line 42, in wrapped_app     await app(scope, receive, sender)   File "/Users/nagabhaskar.alaparthi/hackweek-ai-debugger/venv/lib/python3.13/site-packages/starlette/routing.py", line 714, in __call__     await self.middleware_stack(scope, receive, send)   File "/Users/nagabhaskar.alaparthi/hackweek-ai-debugger/venv/lib/python3.13/site-packages/starlette/routing.py", line 734, in app     await route.handle(scope, receive, send)   File "/Users/nagabhaskar.alaparthi/hackweek-ai-debugger/venv/lib/python3.13/site-packages/starlette/routing.py", line 288, in handle     await self.app(scope, receive, send)   File "/Users/nagabhaskar.alaparthi/hackweek-ai-debugger/venv/lib/python3.13/site-packages/starlette/routing.py", line 76, in app     await wrap_app_handling_exceptions(app, request)(scope, receive, send)   File "/Users/nagabhaskar.alaparthi/hackweek-ai-debugger/venv/lib/python3.13/site-packages/starlette/_exception_handler.py", line 53, in wrapped_app     raise exc   File "/Users/nagabhaskar.alaparthi/hackweek-ai-debugger/venv/lib/python3.13/site-packages/starlette/_exception_handler.py", line 42, in wrapped_app     await app(scope, receive, sender)   File "/Users/nagabhaskar.alaparthi/hackweek-ai-debugger/venv/lib/python3.13/site-packages/starlette/routing.py", line 73, in app     response = await f(request)                ^^^^^^^^^^^^^^^^   File "/Users/nagabhaskar.alaparthi/hackweek-ai-debugger/venv/lib/python3.13/site-packages/fastapi/routing.py", line 301, in app     raw_response = await run_endpoint_function(                    ^^^^^^^^^^^^^^^^^^^^^^^^^^^^     ...<3 lines>...     )     ^   File "/Users/nagabhaskar.alaparthi/hackweek-ai-debugger/venv/lib/python3.13/site-packages/fastapi/routing.py", line 214, in run_endpoint_function     return await run_in_threadpool(dependant.call, **values)            ^^^^^^^^^^^^^^^^^^^^^^^^^^^^^^^^^^^^^^^^^^^^^^^^^   File "/Users/nagabhaskar.alaparthi/hackweek-ai-debugger/venv/lib/python3.13/site-packages/starlette/concurrency.py", line 37, in run_in_threadpool     return await anyio.to_thread.run_sync(func)            ^^^^^^^^^^^^^^^^^^^^^^^^^^^^^^^^^^^^   File "/Users/nagabhaskar.alaparthi/hackweek-ai-debugger/venv/lib/python3.13/site-packages/anyio/to_thread.py", line 56, in run_sync     return await get_async_backend().run_sync_in_worker_thread(            ^^^^^^^^^^^^^^^^^^^^^^^^^^^^^^^^^^^^^^^^^^^^^^^^^^^^         func, args, abandon_on_cancel=abandon_on_cancel, limiter=limiter         ^^^^^^^^^^^^^^^^^^^^^^^^^^^^^^^^^^^^^^^^^^^^^^^^^^^^^^^^^^^^^^^^     )     ^   File "/Users/nagabhaskar.alaparthi/hackweek-ai-debugger/venv/lib/python3.13/site-packages/anyio/_backends/_asyncio.py", line 2470, in run_sync_in_worker_thread     return await future            ^^^^^^^^^^^^   File "/Users/nagabhaskar.alaparthi/hackweek-ai-debugger/venv/lib/python3.13/site-packages/anyio/_backends/_asyncio.py", line 967, in run     result = context.run(func, *args)   File "/Users/nagabhaskar.alaparthi/hackweek-ai-debugger/routers/example_router.py", line 20, in trigger_divide_by_zero_error     return ExampleService.simulate_divide_by_zero_error()            ~~~~~~~~~~~~~~~~~~~~~~~~~~~~~~~~~~~~~~~~~~~~^^   File "/Users/nagabhaskar.alaparthi/hackweek-ai-debugger/services/example_service.py", line 23, in simulate_divide_by_zero_error     raise RuntimeError("A division by zero error occurred.") from e RuntimeError: A division by zero error occurred. 
2025-04-21 12:33:39,397 - ERROR - Unhandled exception: Traceback (most recent call last):   File "/Users/nagabhaskar.alaparthi/hackweek-ai-debugger/services/example_service.py", line 21, in simulate_divide_by_zero_error     result = 1 / 0              ~~^~~ ZeroDivisionError: division by zero  The above exception was the direct cause of the following exception:  Traceback (most recent call last):   File "/Users/nagabhaskar.alaparthi/hackweek-ai-debugger/venv/lib/python3.13/site-packages/starlette/middleware/errors.py", line 165, in __call__     await self.app(scope, receive, _send)   File "/Users/nagabhaskar.alaparthi/hackweek-ai-debugger/venv/lib/python3.13/site-packages/starlette/middleware/exceptions.py", line 62, in __call__     await wrap_app_handling_exceptions(self.app, conn)(scope, receive, send)   File "/Users/nagabhaskar.alaparthi/hackweek-ai-debugger/venv/lib/python3.13/site-packages/starlette/_exception_handler.py", line 53, in wrapped_app     raise exc   File "/Users/nagabhaskar.alaparthi/hackweek-ai-debugger/venv/lib/python3.13/site-packages/starlette/_exception_handler.py", line 42, in wrapped_app     await app(scope, receive, sender)   File "/Users/nagabhaskar.alaparthi/hackweek-ai-debugger/venv/lib/python3.13/site-packages/starlette/routing.py", line 714, in __call__     await self.middleware_stack(scope, receive, send)   File "/Users/nagabhaskar.alaparthi/hackweek-ai-debugger/venv/lib/python3.13/site-packages/starlette/routing.py", line 734, in app     await route.handle(scope, receive, send)   File "/Users/nagabhaskar.alaparthi/hackweek-ai-debugger/venv/lib/python3.13/site-packages/starlette/routing.py", line 288, in handle     await self.app(scope, receive, send)   File "/Users/nagabhaskar.alaparthi/hackweek-ai-debugger/venv/lib/python3.13/site-packages/starlette/routing.py", line 76, in app     await wrap_app_handling_exceptions(app, request)(scope, receive, send)   File "/Users/nagabhaskar.alaparthi/hackweek-ai-debugger/venv/lib/python3.13/site-packages/starlette/_exception_handler.py", line 53, in wrapped_app     raise exc   File "/Users/nagabhaskar.alaparthi/hackweek-ai-debugger/venv/lib/python3.13/site-packages/starlette/_exception_handler.py", line 42, in wrapped_app     await app(scope, receive, sender)   File "/Users/nagabhaskar.alaparthi/hackweek-ai-debugger/venv/lib/python3.13/site-packages/starlette/routing.py", line 73, in app     response = await f(request)                ^^^^^^^^^^^^^^^^   File "/Users/nagabhaskar.alaparthi/hackweek-ai-debugger/venv/lib/python3.13/site-packages/fastapi/routing.py", line 301, in app     raw_response = await run_endpoint_function(                    ^^^^^^^^^^^^^^^^^^^^^^^^^^^^     ...<3 lines>...     )     ^   File "/Users/nagabhaskar.alaparthi/hackweek-ai-debugger/venv/lib/python3.13/site-packages/fastapi/routing.py", line 214, in run_endpoint_function     return await run_in_threadpool(dependant.call, **values)            ^^^^^^^^^^^^^^^^^^^^^^^^^^^^^^^^^^^^^^^^^^^^^^^^^   File "/Users/nagabhaskar.alaparthi/hackweek-ai-debugger/venv/lib/python3.13/site-packages/starlette/concurrency.py", line 37, in run_in_threadpool     return await anyio.to_thread.run_sync(func)            ^^^^^^^^^^^^^^^^^^^^^^^^^^^^^^^^^^^^   File "/Users/nagabhaskar.alaparthi/hackweek-ai-debugger/venv/lib/python3.13/site-packages/anyio/to_thread.py", line 56, in run_sync     return await get_async_backend().run_sync_in_worker_thread(            ^^^^^^^^^^^^^^^^^^^^^^^^^^^^^^^^^^^^^^^^^^^^^^^^^^^^         func, args, abandon_on_cancel=abandon_on_cancel, limiter=limiter         ^^^^^^^^^^^^^^^^^^^^^^^^^^^^^^^^^^^^^^^^^^^^^^^^^^^^^^^^^^^^^^^^     )     ^   File "/Users/nagabhaskar.alaparthi/hackweek-ai-debugger/venv/lib/python3.13/site-packages/anyio/_backends/_asyncio.py", line 2470, in run_sync_in_worker_thread     return await future            ^^^^^^^^^^^^   File "/Users/nagabhaskar.alaparthi/hackweek-ai-debugger/venv/lib/python3.13/site-packages/anyio/_backends/_asyncio.py", line 967, in run     result = context.run(func, *args)   File "/Users/nagabhaskar.alaparthi/hackweek-ai-debugger/routers/example_router.py", line 20, in trigger_divide_by_zero_error     return ExampleService.simulate_divide_by_zero_error()            ~~~~~~~~~~~~~~~~~~~~~~~~~~~~~~~~~~~~~~~~~~~~^^   File "/Users/nagabhaskar.alaparthi/hackweek-ai-debugger/services/example_service.py", line 23, in simulate_divide_by_zero_error     raise RuntimeError("A division by zero error occurred.") from e RuntimeError: A division by zero error occurred. 
2025-04-21 12:34:43,742 - ERROR - Unhandled exception: Traceback (most recent call last):   File "/Users/nagabhaskar.alaparthi/hackweek-ai-debugger/services/example_service.py", line 21, in simulate_divide_by_zero_error     result = 1 / 0              ~~^~~ ZeroDivisionError: division by zero  The above exception was the direct cause of the following exception:  Traceback (most recent call last):   File "/Users/nagabhaskar.alaparthi/hackweek-ai-debugger/venv/lib/python3.13/site-packages/starlette/middleware/errors.py", line 165, in __call__     await self.app(scope, receive, _send)   File "/Users/nagabhaskar.alaparthi/hackweek-ai-debugger/venv/lib/python3.13/site-packages/starlette/middleware/exceptions.py", line 62, in __call__     await wrap_app_handling_exceptions(self.app, conn)(scope, receive, send)   File "/Users/nagabhaskar.alaparthi/hackweek-ai-debugger/venv/lib/python3.13/site-packages/starlette/_exception_handler.py", line 53, in wrapped_app     raise exc   File "/Users/nagabhaskar.alaparthi/hackweek-ai-debugger/venv/lib/python3.13/site-packages/starlette/_exception_handler.py", line 42, in wrapped_app     await app(scope, receive, sender)   File "/Users/nagabhaskar.alaparthi/hackweek-ai-debugger/venv/lib/python3.13/site-packages/starlette/routing.py", line 714, in __call__     await self.middleware_stack(scope, receive, send)   File "/Users/nagabhaskar.alaparthi/hackweek-ai-debugger/venv/lib/python3.13/site-packages/starlette/routing.py", line 734, in app     await route.handle(scope, receive, send)   File "/Users/nagabhaskar.alaparthi/hackweek-ai-debugger/venv/lib/python3.13/site-packages/starlette/routing.py", line 288, in handle     await self.app(scope, receive, send)   File "/Users/nagabhaskar.alaparthi/hackweek-ai-debugger/venv/lib/python3.13/site-packages/starlette/routing.py", line 76, in app     await wrap_app_handling_exceptions(app, request)(scope, receive, send)   File "/Users/nagabhaskar.alaparthi/hackweek-ai-debugger/venv/lib/python3.13/site-packages/starlette/_exception_handler.py", line 53, in wrapped_app     raise exc   File "/Users/nagabhaskar.alaparthi/hackweek-ai-debugger/venv/lib/python3.13/site-packages/starlette/_exception_handler.py", line 42, in wrapped_app     await app(scope, receive, sender)   File "/Users/nagabhaskar.alaparthi/hackweek-ai-debugger/venv/lib/python3.13/site-packages/starlette/routing.py", line 73, in app     response = await f(request)                ^^^^^^^^^^^^^^^^   File "/Users/nagabhaskar.alaparthi/hackweek-ai-debugger/venv/lib/python3.13/site-packages/fastapi/routing.py", line 301, in app     raw_response = await run_endpoint_function(                    ^^^^^^^^^^^^^^^^^^^^^^^^^^^^     ...<3 lines>...     )     ^   File "/Users/nagabhaskar.alaparthi/hackweek-ai-debugger/venv/lib/python3.13/site-packages/fastapi/routing.py", line 214, in run_endpoint_function     return await run_in_threadpool(dependant.call, **values)            ^^^^^^^^^^^^^^^^^^^^^^^^^^^^^^^^^^^^^^^^^^^^^^^^^   File "/Users/nagabhaskar.alaparthi/hackweek-ai-debugger/venv/lib/python3.13/site-packages/starlette/concurrency.py", line 37, in run_in_threadpool     return await anyio.to_thread.run_sync(func)            ^^^^^^^^^^^^^^^^^^^^^^^^^^^^^^^^^^^^   File "/Users/nagabhaskar.alaparthi/hackweek-ai-debugger/venv/lib/python3.13/site-packages/anyio/to_thread.py", line 56, in run_sync     return await get_async_backend().run_sync_in_worker_thread(            ^^^^^^^^^^^^^^^^^^^^^^^^^^^^^^^^^^^^^^^^^^^^^^^^^^^^         func, args, abandon_on_cancel=abandon_on_cancel, limiter=limiter         ^^^^^^^^^^^^^^^^^^^^^^^^^^^^^^^^^^^^^^^^^^^^^^^^^^^^^^^^^^^^^^^^     )     ^   File "/Users/nagabhaskar.alaparthi/hackweek-ai-debugger/venv/lib/python3.13/site-packages/anyio/_backends/_asyncio.py", line 2470, in run_sync_in_worker_thread     return await future            ^^^^^^^^^^^^   File "/Users/nagabhaskar.alaparthi/hackweek-ai-debugger/venv/lib/python3.13/site-packages/anyio/_backends/_asyncio.py", line 967, in run     result = context.run(func, *args)   File "/Users/nagabhaskar.alaparthi/hackweek-ai-debugger/routers/example_router.py", line 20, in trigger_divide_by_zero_error     return ExampleService.simulate_divide_by_zero_error()            ~~~~~~~~~~~~~~~~~~~~~~~~~~~~~~~~~~~~~~~~~~~~^^   File "/Users/nagabhaskar.alaparthi/hackweek-ai-debugger/services/example_service.py", line 23, in simulate_divide_by_zero_error     raise RuntimeError("A division by zero error occurred.") from e RuntimeError: A division by zero error occurred. 
2025-04-21 12:42:12,155 - ERROR - Unhandled exception: Traceback (most recent call last):   File "/Users/nagabhaskar.alaparthi/hackweek-ai-debugger/services/example_service.py", line 21, in simulate_divide_by_zero_error     result = 1 / 0              ~~^~~ ZeroDivisionError: division by zero  The above exception was the direct cause of the following exception:  Traceback (most recent call last):   File "/Users/nagabhaskar.alaparthi/hackweek-ai-debugger/venv/lib/python3.13/site-packages/starlette/middleware/errors.py", line 165, in __call__     await self.app(scope, receive, _send)   File "/Users/nagabhaskar.alaparthi/hackweek-ai-debugger/venv/lib/python3.13/site-packages/starlette/middleware/exceptions.py", line 62, in __call__     await wrap_app_handling_exceptions(self.app, conn)(scope, receive, send)   File "/Users/nagabhaskar.alaparthi/hackweek-ai-debugger/venv/lib/python3.13/site-packages/starlette/_exception_handler.py", line 53, in wrapped_app     raise exc   File "/Users/nagabhaskar.alaparthi/hackweek-ai-debugger/venv/lib/python3.13/site-packages/starlette/_exception_handler.py", line 42, in wrapped_app     await app(scope, receive, sender)   File "/Users/nagabhaskar.alaparthi/hackweek-ai-debugger/venv/lib/python3.13/site-packages/starlette/routing.py", line 714, in __call__     await self.middleware_stack(scope, receive, send)   File "/Users/nagabhaskar.alaparthi/hackweek-ai-debugger/venv/lib/python3.13/site-packages/starlette/routing.py", line 734, in app     await route.handle(scope, receive, send)   File "/Users/nagabhaskar.alaparthi/hackweek-ai-debugger/venv/lib/python3.13/site-packages/starlette/routing.py", line 288, in handle     await self.app(scope, receive, send)   File "/Users/nagabhaskar.alaparthi/hackweek-ai-debugger/venv/lib/python3.13/site-packages/starlette/routing.py", line 76, in app     await wrap_app_handling_exceptions(app, request)(scope, receive, send)   File "/Users/nagabhaskar.alaparthi/hackweek-ai-debugger/venv/lib/python3.13/site-packages/starlette/_exception_handler.py", line 53, in wrapped_app     raise exc   File "/Users/nagabhaskar.alaparthi/hackweek-ai-debugger/venv/lib/python3.13/site-packages/starlette/_exception_handler.py", line 42, in wrapped_app     await app(scope, receive, sender)   File "/Users/nagabhaskar.alaparthi/hackweek-ai-debugger/venv/lib/python3.13/site-packages/starlette/routing.py", line 73, in app     response = await f(request)                ^^^^^^^^^^^^^^^^   File "/Users/nagabhaskar.alaparthi/hackweek-ai-debugger/venv/lib/python3.13/site-packages/fastapi/routing.py", line 301, in app     raw_response = await run_endpoint_function(                    ^^^^^^^^^^^^^^^^^^^^^^^^^^^^     ...<3 lines>...     )     ^   File "/Users/nagabhaskar.alaparthi/hackweek-ai-debugger/venv/lib/python3.13/site-packages/fastapi/routing.py", line 214, in run_endpoint_function     return await run_in_threadpool(dependant.call, **values)            ^^^^^^^^^^^^^^^^^^^^^^^^^^^^^^^^^^^^^^^^^^^^^^^^^   File "/Users/nagabhaskar.alaparthi/hackweek-ai-debugger/venv/lib/python3.13/site-packages/starlette/concurrency.py", line 37, in run_in_threadpool     return await anyio.to_thread.run_sync(func)            ^^^^^^^^^^^^^^^^^^^^^^^^^^^^^^^^^^^^   File "/Users/nagabhaskar.alaparthi/hackweek-ai-debugger/venv/lib/python3.13/site-packages/anyio/to_thread.py", line 56, in run_sync     return await get_async_backend().run_sync_in_worker_thread(            ^^^^^^^^^^^^^^^^^^^^^^^^^^^^^^^^^^^^^^^^^^^^^^^^^^^^         func, args, abandon_on_cancel=abandon_on_cancel, limiter=limiter         ^^^^^^^^^^^^^^^^^^^^^^^^^^^^^^^^^^^^^^^^^^^^^^^^^^^^^^^^^^^^^^^^     )     ^   File "/Users/nagabhaskar.alaparthi/hackweek-ai-debugger/venv/lib/python3.13/site-packages/anyio/_backends/_asyncio.py", line 2470, in run_sync_in_worker_thread     return await future            ^^^^^^^^^^^^   File "/Users/nagabhaskar.alaparthi/hackweek-ai-debugger/venv/lib/python3.13/site-packages/anyio/_backends/_asyncio.py", line 967, in run     result = context.run(func, *args)   File "/Users/nagabhaskar.alaparthi/hackweek-ai-debugger/routers/example_router.py", line 20, in trigger_divide_by_zero_error     return ExampleService.simulate_divide_by_zero_error()            ~~~~~~~~~~~~~~~~~~~~~~~~~~~~~~~~~~~~~~~~~~~~^^   File "/Users/nagabhaskar.alaparthi/hackweek-ai-debugger/services/example_service.py", line 23, in simulate_divide_by_zero_error     raise RuntimeError("A division by zero error occurred.") from e RuntimeError: A division by zero error occurred. 
2025-04-21 12:42:13,530 - ERROR - Unhandled exception: Traceback (most recent call last):   File "/Users/nagabhaskar.alaparthi/hackweek-ai-debugger/services/example_service.py", line 21, in simulate_divide_by_zero_error     result = 1 / 0              ~~^~~ ZeroDivisionError: division by zero  The above exception was the direct cause of the following exception:  Traceback (most recent call last):   File "/Users/nagabhaskar.alaparthi/hackweek-ai-debugger/venv/lib/python3.13/site-packages/starlette/middleware/errors.py", line 165, in __call__     await self.app(scope, receive, _send)   File "/Users/nagabhaskar.alaparthi/hackweek-ai-debugger/venv/lib/python3.13/site-packages/starlette/middleware/exceptions.py", line 62, in __call__     await wrap_app_handling_exceptions(self.app, conn)(scope, receive, send)   File "/Users/nagabhaskar.alaparthi/hackweek-ai-debugger/venv/lib/python3.13/site-packages/starlette/_exception_handler.py", line 53, in wrapped_app     raise exc   File "/Users/nagabhaskar.alaparthi/hackweek-ai-debugger/venv/lib/python3.13/site-packages/starlette/_exception_handler.py", line 42, in wrapped_app     await app(scope, receive, sender)   File "/Users/nagabhaskar.alaparthi/hackweek-ai-debugger/venv/lib/python3.13/site-packages/starlette/routing.py", line 714, in __call__     await self.middleware_stack(scope, receive, send)   File "/Users/nagabhaskar.alaparthi/hackweek-ai-debugger/venv/lib/python3.13/site-packages/starlette/routing.py", line 734, in app     await route.handle(scope, receive, send)   File "/Users/nagabhaskar.alaparthi/hackweek-ai-debugger/venv/lib/python3.13/site-packages/starlette/routing.py", line 288, in handle     await self.app(scope, receive, send)   File "/Users/nagabhaskar.alaparthi/hackweek-ai-debugger/venv/lib/python3.13/site-packages/starlette/routing.py", line 76, in app     await wrap_app_handling_exceptions(app, request)(scope, receive, send)   File "/Users/nagabhaskar.alaparthi/hackweek-ai-debugger/venv/lib/python3.13/site-packages/starlette/_exception_handler.py", line 53, in wrapped_app     raise exc   File "/Users/nagabhaskar.alaparthi/hackweek-ai-debugger/venv/lib/python3.13/site-packages/starlette/_exception_handler.py", line 42, in wrapped_app     await app(scope, receive, sender)   File "/Users/nagabhaskar.alaparthi/hackweek-ai-debugger/venv/lib/python3.13/site-packages/starlette/routing.py", line 73, in app     response = await f(request)                ^^^^^^^^^^^^^^^^   File "/Users/nagabhaskar.alaparthi/hackweek-ai-debugger/venv/lib/python3.13/site-packages/fastapi/routing.py", line 301, in app     raw_response = await run_endpoint_function(                    ^^^^^^^^^^^^^^^^^^^^^^^^^^^^     ...<3 lines>...     )     ^   File "/Users/nagabhaskar.alaparthi/hackweek-ai-debugger/venv/lib/python3.13/site-packages/fastapi/routing.py", line 214, in run_endpoint_function     return await run_in_threadpool(dependant.call, **values)            ^^^^^^^^^^^^^^^^^^^^^^^^^^^^^^^^^^^^^^^^^^^^^^^^^   File "/Users/nagabhaskar.alaparthi/hackweek-ai-debugger/venv/lib/python3.13/site-packages/starlette/concurrency.py", line 37, in run_in_threadpool     return await anyio.to_thread.run_sync(func)            ^^^^^^^^^^^^^^^^^^^^^^^^^^^^^^^^^^^^   File "/Users/nagabhaskar.alaparthi/hackweek-ai-debugger/venv/lib/python3.13/site-packages/anyio/to_thread.py", line 56, in run_sync     return await get_async_backend().run_sync_in_worker_thread(            ^^^^^^^^^^^^^^^^^^^^^^^^^^^^^^^^^^^^^^^^^^^^^^^^^^^^         func, args, abandon_on_cancel=abandon_on_cancel, limiter=limiter         ^^^^^^^^^^^^^^^^^^^^^^^^^^^^^^^^^^^^^^^^^^^^^^^^^^^^^^^^^^^^^^^^     )     ^   File "/Users/nagabhaskar.alaparthi/hackweek-ai-debugger/venv/lib/python3.13/site-packages/anyio/_backends/_asyncio.py", line 2470, in run_sync_in_worker_thread     return await future            ^^^^^^^^^^^^   File "/Users/nagabhaskar.alaparthi/hackweek-ai-debugger/venv/lib/python3.13/site-packages/anyio/_backends/_asyncio.py", line 967, in run     result = context.run(func, *args)   File "/Users/nagabhaskar.alaparthi/hackweek-ai-debugger/routers/example_router.py", line 20, in trigger_divide_by_zero_error     return ExampleService.simulate_divide_by_zero_error()            ~~~~~~~~~~~~~~~~~~~~~~~~~~~~~~~~~~~~~~~~~~~~^^   File "/Users/nagabhaskar.alaparthi/hackweek-ai-debugger/services/example_service.py", line 23, in simulate_divide_by_zero_error     raise RuntimeError("A division by zero error occurred.") from e RuntimeError: A division by zero error occurred. 
2025-04-21 12:45:07,659 - ERROR - Unhandled exception: Traceback (most recent call last):   File "/Users/nagabhaskar.alaparthi/hackweek-ai-debugger/services/example_service.py", line 21, in simulate_divide_by_zero_error     result = 1 / 0              ~~^~~ ZeroDivisionError: division by zero  The above exception was the direct cause of the following exception:  Traceback (most recent call last):   File "/Users/nagabhaskar.alaparthi/hackweek-ai-debugger/venv/lib/python3.13/site-packages/starlette/middleware/errors.py", line 165, in __call__     await self.app(scope, receive, _send)   File "/Users/nagabhaskar.alaparthi/hackweek-ai-debugger/venv/lib/python3.13/site-packages/starlette/middleware/exceptions.py", line 62, in __call__     await wrap_app_handling_exceptions(self.app, conn)(scope, receive, send)   File "/Users/nagabhaskar.alaparthi/hackweek-ai-debugger/venv/lib/python3.13/site-packages/starlette/_exception_handler.py", line 53, in wrapped_app     raise exc   File "/Users/nagabhaskar.alaparthi/hackweek-ai-debugger/venv/lib/python3.13/site-packages/starlette/_exception_handler.py", line 42, in wrapped_app     await app(scope, receive, sender)   File "/Users/nagabhaskar.alaparthi/hackweek-ai-debugger/venv/lib/python3.13/site-packages/starlette/routing.py", line 714, in __call__     await self.middleware_stack(scope, receive, send)   File "/Users/nagabhaskar.alaparthi/hackweek-ai-debugger/venv/lib/python3.13/site-packages/starlette/routing.py", line 734, in app     await route.handle(scope, receive, send)   File "/Users/nagabhaskar.alaparthi/hackweek-ai-debugger/venv/lib/python3.13/site-packages/starlette/routing.py", line 288, in handle     await self.app(scope, receive, send)   File "/Users/nagabhaskar.alaparthi/hackweek-ai-debugger/venv/lib/python3.13/site-packages/starlette/routing.py", line 76, in app     await wrap_app_handling_exceptions(app, request)(scope, receive, send)   File "/Users/nagabhaskar.alaparthi/hackweek-ai-debugger/venv/lib/python3.13/site-packages/starlette/_exception_handler.py", line 53, in wrapped_app     raise exc   File "/Users/nagabhaskar.alaparthi/hackweek-ai-debugger/venv/lib/python3.13/site-packages/starlette/_exception_handler.py", line 42, in wrapped_app     await app(scope, receive, sender)   File "/Users/nagabhaskar.alaparthi/hackweek-ai-debugger/venv/lib/python3.13/site-packages/starlette/routing.py", line 73, in app     response = await f(request)                ^^^^^^^^^^^^^^^^   File "/Users/nagabhaskar.alaparthi/hackweek-ai-debugger/venv/lib/python3.13/site-packages/fastapi/routing.py", line 301, in app     raw_response = await run_endpoint_function(                    ^^^^^^^^^^^^^^^^^^^^^^^^^^^^     ...<3 lines>...     )     ^   File "/Users/nagabhaskar.alaparthi/hackweek-ai-debugger/venv/lib/python3.13/site-packages/fastapi/routing.py", line 214, in run_endpoint_function     return await run_in_threadpool(dependant.call, **values)            ^^^^^^^^^^^^^^^^^^^^^^^^^^^^^^^^^^^^^^^^^^^^^^^^^   File "/Users/nagabhaskar.alaparthi/hackweek-ai-debugger/venv/lib/python3.13/site-packages/starlette/concurrency.py", line 37, in run_in_threadpool     return await anyio.to_thread.run_sync(func)            ^^^^^^^^^^^^^^^^^^^^^^^^^^^^^^^^^^^^   File "/Users/nagabhaskar.alaparthi/hackweek-ai-debugger/venv/lib/python3.13/site-packages/anyio/to_thread.py", line 56, in run_sync     return await get_async_backend().run_sync_in_worker_thread(            ^^^^^^^^^^^^^^^^^^^^^^^^^^^^^^^^^^^^^^^^^^^^^^^^^^^^         func, args, abandon_on_cancel=abandon_on_cancel, limiter=limiter         ^^^^^^^^^^^^^^^^^^^^^^^^^^^^^^^^^^^^^^^^^^^^^^^^^^^^^^^^^^^^^^^^     )     ^   File "/Users/nagabhaskar.alaparthi/hackweek-ai-debugger/venv/lib/python3.13/site-packages/anyio/_backends/_asyncio.py", line 2470, in run_sync_in_worker_thread     return await future            ^^^^^^^^^^^^   File "/Users/nagabhaskar.alaparthi/hackweek-ai-debugger/venv/lib/python3.13/site-packages/anyio/_backends/_asyncio.py", line 967, in run     result = context.run(func, *args)   File "/Users/nagabhaskar.alaparthi/hackweek-ai-debugger/routers/example_router.py", line 20, in trigger_divide_by_zero_error     return ExampleService.simulate_divide_by_zero_error()            ~~~~~~~~~~~~~~~~~~~~~~~~~~~~~~~~~~~~~~~~~~~~^^   File "/Users/nagabhaskar.alaparthi/hackweek-ai-debugger/services/example_service.py", line 23, in simulate_divide_by_zero_error     raise RuntimeError("A division by zero error occurred.") from e RuntimeError: A division by zero error occurred. 
2025-04-21 12:46:27,101 - ERROR - Unhandled exception: Traceback (most recent call last):   File "/Users/nagabhaskar.alaparthi/hackweek-ai-debugger/services/example_service.py", line 21, in simulate_divide_by_zero_error     result = 1 / 0              ~~^~~ ZeroDivisionError: division by zero  The above exception was the direct cause of the following exception:  Traceback (most recent call last):   File "/Users/nagabhaskar.alaparthi/hackweek-ai-debugger/venv/lib/python3.13/site-packages/starlette/middleware/errors.py", line 165, in __call__     await self.app(scope, receive, _send)   File "/Users/nagabhaskar.alaparthi/hackweek-ai-debugger/venv/lib/python3.13/site-packages/starlette/middleware/exceptions.py", line 62, in __call__     await wrap_app_handling_exceptions(self.app, conn)(scope, receive, send)   File "/Users/nagabhaskar.alaparthi/hackweek-ai-debugger/venv/lib/python3.13/site-packages/starlette/_exception_handler.py", line 53, in wrapped_app     raise exc   File "/Users/nagabhaskar.alaparthi/hackweek-ai-debugger/venv/lib/python3.13/site-packages/starlette/_exception_handler.py", line 42, in wrapped_app     await app(scope, receive, sender)   File "/Users/nagabhaskar.alaparthi/hackweek-ai-debugger/venv/lib/python3.13/site-packages/starlette/routing.py", line 714, in __call__     await self.middleware_stack(scope, receive, send)   File "/Users/nagabhaskar.alaparthi/hackweek-ai-debugger/venv/lib/python3.13/site-packages/starlette/routing.py", line 734, in app     await route.handle(scope, receive, send)   File "/Users/nagabhaskar.alaparthi/hackweek-ai-debugger/venv/lib/python3.13/site-packages/starlette/routing.py", line 288, in handle     await self.app(scope, receive, send)   File "/Users/nagabhaskar.alaparthi/hackweek-ai-debugger/venv/lib/python3.13/site-packages/starlette/routing.py", line 76, in app     await wrap_app_handling_exceptions(app, request)(scope, receive, send)   File "/Users/nagabhaskar.alaparthi/hackweek-ai-debugger/venv/lib/python3.13/site-packages/starlette/_exception_handler.py", line 53, in wrapped_app     raise exc   File "/Users/nagabhaskar.alaparthi/hackweek-ai-debugger/venv/lib/python3.13/site-packages/starlette/_exception_handler.py", line 42, in wrapped_app     await app(scope, receive, sender)   File "/Users/nagabhaskar.alaparthi/hackweek-ai-debugger/venv/lib/python3.13/site-packages/starlette/routing.py", line 73, in app     response = await f(request)                ^^^^^^^^^^^^^^^^   File "/Users/nagabhaskar.alaparthi/hackweek-ai-debugger/venv/lib/python3.13/site-packages/fastapi/routing.py", line 301, in app     raw_response = await run_endpoint_function(                    ^^^^^^^^^^^^^^^^^^^^^^^^^^^^     ...<3 lines>...     )     ^   File "/Users/nagabhaskar.alaparthi/hackweek-ai-debugger/venv/lib/python3.13/site-packages/fastapi/routing.py", line 214, in run_endpoint_function     return await run_in_threadpool(dependant.call, **values)            ^^^^^^^^^^^^^^^^^^^^^^^^^^^^^^^^^^^^^^^^^^^^^^^^^   File "/Users/nagabhaskar.alaparthi/hackweek-ai-debugger/venv/lib/python3.13/site-packages/starlette/concurrency.py", line 37, in run_in_threadpool     return await anyio.to_thread.run_sync(func)            ^^^^^^^^^^^^^^^^^^^^^^^^^^^^^^^^^^^^   File "/Users/nagabhaskar.alaparthi/hackweek-ai-debugger/venv/lib/python3.13/site-packages/anyio/to_thread.py", line 56, in run_sync     return await get_async_backend().run_sync_in_worker_thread(            ^^^^^^^^^^^^^^^^^^^^^^^^^^^^^^^^^^^^^^^^^^^^^^^^^^^^         func, args, abandon_on_cancel=abandon_on_cancel, limiter=limiter         ^^^^^^^^^^^^^^^^^^^^^^^^^^^^^^^^^^^^^^^^^^^^^^^^^^^^^^^^^^^^^^^^     )     ^   File "/Users/nagabhaskar.alaparthi/hackweek-ai-debugger/venv/lib/python3.13/site-packages/anyio/_backends/_asyncio.py", line 2470, in run_sync_in_worker_thread     return await future            ^^^^^^^^^^^^   File "/Users/nagabhaskar.alaparthi/hackweek-ai-debugger/venv/lib/python3.13/site-packages/anyio/_backends/_asyncio.py", line 967, in run     result = context.run(func, *args)   File "/Users/nagabhaskar.alaparthi/hackweek-ai-debugger/routers/example_router.py", line 20, in trigger_divide_by_zero_error     return ExampleService.simulate_divide_by_zero_error()            ~~~~~~~~~~~~~~~~~~~~~~~~~~~~~~~~~~~~~~~~~~~~^^   File "/Users/nagabhaskar.alaparthi/hackweek-ai-debugger/services/example_service.py", line 23, in simulate_divide_by_zero_error     raise RuntimeError("A division by zero error occurred.") from e RuntimeError: A division by zero error occurred. 
2025-04-21 12:56:43,634 - ERROR - Unhandled exception: Traceback (most recent call last):   File "/Users/nagabhaskar.alaparthi/hackweek-ai-debugger/services/example_service.py", line 21, in simulate_divide_by_zero_error     result = 1 / 0              ~~^~~ ZeroDivisionError: division by zero  The above exception was the direct cause of the following exception:  Traceback (most recent call last):   File "/Users/nagabhaskar.alaparthi/hackweek-ai-debugger/venv/lib/python3.13/site-packages/starlette/middleware/errors.py", line 165, in __call__     await self.app(scope, receive, _send)   File "/Users/nagabhaskar.alaparthi/hackweek-ai-debugger/venv/lib/python3.13/site-packages/starlette/middleware/exceptions.py", line 62, in __call__     await wrap_app_handling_exceptions(self.app, conn)(scope, receive, send)   File "/Users/nagabhaskar.alaparthi/hackweek-ai-debugger/venv/lib/python3.13/site-packages/starlette/_exception_handler.py", line 53, in wrapped_app     raise exc   File "/Users/nagabhaskar.alaparthi/hackweek-ai-debugger/venv/lib/python3.13/site-packages/starlette/_exception_handler.py", line 42, in wrapped_app     await app(scope, receive, sender)   File "/Users/nagabhaskar.alaparthi/hackweek-ai-debugger/venv/lib/python3.13/site-packages/starlette/routing.py", line 714, in __call__     await self.middleware_stack(scope, receive, send)   File "/Users/nagabhaskar.alaparthi/hackweek-ai-debugger/venv/lib/python3.13/site-packages/starlette/routing.py", line 734, in app     await route.handle(scope, receive, send)   File "/Users/nagabhaskar.alaparthi/hackweek-ai-debugger/venv/lib/python3.13/site-packages/starlette/routing.py", line 288, in handle     await self.app(scope, receive, send)   File "/Users/nagabhaskar.alaparthi/hackweek-ai-debugger/venv/lib/python3.13/site-packages/starlette/routing.py", line 76, in app     await wrap_app_handling_exceptions(app, request)(scope, receive, send)   File "/Users/nagabhaskar.alaparthi/hackweek-ai-debugger/venv/lib/python3.13/site-packages/starlette/_exception_handler.py", line 53, in wrapped_app     raise exc   File "/Users/nagabhaskar.alaparthi/hackweek-ai-debugger/venv/lib/python3.13/site-packages/starlette/_exception_handler.py", line 42, in wrapped_app     await app(scope, receive, sender)   File "/Users/nagabhaskar.alaparthi/hackweek-ai-debugger/venv/lib/python3.13/site-packages/starlette/routing.py", line 73, in app     response = await f(request)                ^^^^^^^^^^^^^^^^   File "/Users/nagabhaskar.alaparthi/hackweek-ai-debugger/venv/lib/python3.13/site-packages/fastapi/routing.py", line 301, in app     raw_response = await run_endpoint_function(                    ^^^^^^^^^^^^^^^^^^^^^^^^^^^^     ...<3 lines>...     )     ^   File "/Users/nagabhaskar.alaparthi/hackweek-ai-debugger/venv/lib/python3.13/site-packages/fastapi/routing.py", line 214, in run_endpoint_function     return await run_in_threadpool(dependant.call, **values)            ^^^^^^^^^^^^^^^^^^^^^^^^^^^^^^^^^^^^^^^^^^^^^^^^^   File "/Users/nagabhaskar.alaparthi/hackweek-ai-debugger/venv/lib/python3.13/site-packages/starlette/concurrency.py", line 37, in run_in_threadpool     return await anyio.to_thread.run_sync(func)            ^^^^^^^^^^^^^^^^^^^^^^^^^^^^^^^^^^^^   File "/Users/nagabhaskar.alaparthi/hackweek-ai-debugger/venv/lib/python3.13/site-packages/anyio/to_thread.py", line 56, in run_sync     return await get_async_backend().run_sync_in_worker_thread(            ^^^^^^^^^^^^^^^^^^^^^^^^^^^^^^^^^^^^^^^^^^^^^^^^^^^^         func, args, abandon_on_cancel=abandon_on_cancel, limiter=limiter         ^^^^^^^^^^^^^^^^^^^^^^^^^^^^^^^^^^^^^^^^^^^^^^^^^^^^^^^^^^^^^^^^     )     ^   File "/Users/nagabhaskar.alaparthi/hackweek-ai-debugger/venv/lib/python3.13/site-packages/anyio/_backends/_asyncio.py", line 2470, in run_sync_in_worker_thread     return await future            ^^^^^^^^^^^^   File "/Users/nagabhaskar.alaparthi/hackweek-ai-debugger/venv/lib/python3.13/site-packages/anyio/_backends/_asyncio.py", line 967, in run     result = context.run(func, *args)   File "/Users/nagabhaskar.alaparthi/hackweek-ai-debugger/routers/example_router.py", line 20, in trigger_divide_by_zero_error     return ExampleService.simulate_divide_by_zero_error()            ~~~~~~~~~~~~~~~~~~~~~~~~~~~~~~~~~~~~~~~~~~~~^^   File "/Users/nagabhaskar.alaparthi/hackweek-ai-debugger/services/example_service.py", line 23, in simulate_divide_by_zero_error     raise RuntimeError("A division by zero error occurred.") from e RuntimeError: A division by zero error occurred. 
2025-04-21 12:58:27,751 - ERROR - Unhandled exception: Traceback (most recent call last):   File "/Users/nagabhaskar.alaparthi/hackweek-ai-debugger/services/example_service.py", line 21, in simulate_divide_by_zero_error     result = 1 / 0              ~~^~~ ZeroDivisionError: division by zero  The above exception was the direct cause of the following exception:  Traceback (most recent call last):   File "/Users/nagabhaskar.alaparthi/hackweek-ai-debugger/venv/lib/python3.13/site-packages/starlette/middleware/errors.py", line 165, in __call__     await self.app(scope, receive, _send)   File "/Users/nagabhaskar.alaparthi/hackweek-ai-debugger/venv/lib/python3.13/site-packages/starlette/middleware/exceptions.py", line 62, in __call__     await wrap_app_handling_exceptions(self.app, conn)(scope, receive, send)   File "/Users/nagabhaskar.alaparthi/hackweek-ai-debugger/venv/lib/python3.13/site-packages/starlette/_exception_handler.py", line 53, in wrapped_app     raise exc   File "/Users/nagabhaskar.alaparthi/hackweek-ai-debugger/venv/lib/python3.13/site-packages/starlette/_exception_handler.py", line 42, in wrapped_app     await app(scope, receive, sender)   File "/Users/nagabhaskar.alaparthi/hackweek-ai-debugger/venv/lib/python3.13/site-packages/starlette/routing.py", line 714, in __call__     await self.middleware_stack(scope, receive, send)   File "/Users/nagabhaskar.alaparthi/hackweek-ai-debugger/venv/lib/python3.13/site-packages/starlette/routing.py", line 734, in app     await route.handle(scope, receive, send)   File "/Users/nagabhaskar.alaparthi/hackweek-ai-debugger/venv/lib/python3.13/site-packages/starlette/routing.py", line 288, in handle     await self.app(scope, receive, send)   File "/Users/nagabhaskar.alaparthi/hackweek-ai-debugger/venv/lib/python3.13/site-packages/starlette/routing.py", line 76, in app     await wrap_app_handling_exceptions(app, request)(scope, receive, send)   File "/Users/nagabhaskar.alaparthi/hackweek-ai-debugger/venv/lib/python3.13/site-packages/starlette/_exception_handler.py", line 53, in wrapped_app     raise exc   File "/Users/nagabhaskar.alaparthi/hackweek-ai-debugger/venv/lib/python3.13/site-packages/starlette/_exception_handler.py", line 42, in wrapped_app     await app(scope, receive, sender)   File "/Users/nagabhaskar.alaparthi/hackweek-ai-debugger/venv/lib/python3.13/site-packages/starlette/routing.py", line 73, in app     response = await f(request)                ^^^^^^^^^^^^^^^^   File "/Users/nagabhaskar.alaparthi/hackweek-ai-debugger/venv/lib/python3.13/site-packages/fastapi/routing.py", line 301, in app     raw_response = await run_endpoint_function(                    ^^^^^^^^^^^^^^^^^^^^^^^^^^^^     ...<3 lines>...     )     ^   File "/Users/nagabhaskar.alaparthi/hackweek-ai-debugger/venv/lib/python3.13/site-packages/fastapi/routing.py", line 214, in run_endpoint_function     return await run_in_threadpool(dependant.call, **values)            ^^^^^^^^^^^^^^^^^^^^^^^^^^^^^^^^^^^^^^^^^^^^^^^^^   File "/Users/nagabhaskar.alaparthi/hackweek-ai-debugger/venv/lib/python3.13/site-packages/starlette/concurrency.py", line 37, in run_in_threadpool     return await anyio.to_thread.run_sync(func)            ^^^^^^^^^^^^^^^^^^^^^^^^^^^^^^^^^^^^   File "/Users/nagabhaskar.alaparthi/hackweek-ai-debugger/venv/lib/python3.13/site-packages/anyio/to_thread.py", line 56, in run_sync     return await get_async_backend().run_sync_in_worker_thread(            ^^^^^^^^^^^^^^^^^^^^^^^^^^^^^^^^^^^^^^^^^^^^^^^^^^^^         func, args, abandon_on_cancel=abandon_on_cancel, limiter=limiter         ^^^^^^^^^^^^^^^^^^^^^^^^^^^^^^^^^^^^^^^^^^^^^^^^^^^^^^^^^^^^^^^^     )     ^   File "/Users/nagabhaskar.alaparthi/hackweek-ai-debugger/venv/lib/python3.13/site-packages/anyio/_backends/_asyncio.py", line 2470, in run_sync_in_worker_thread     return await future            ^^^^^^^^^^^^   File "/Users/nagabhaskar.alaparthi/hackweek-ai-debugger/venv/lib/python3.13/site-packages/anyio/_backends/_asyncio.py", line 967, in run     result = context.run(func, *args)   File "/Users/nagabhaskar.alaparthi/hackweek-ai-debugger/routers/example_router.py", line 20, in trigger_divide_by_zero_error     return ExampleService.simulate_divide_by_zero_error()            ~~~~~~~~~~~~~~~~~~~~~~~~~~~~~~~~~~~~~~~~~~~~^^   File "/Users/nagabhaskar.alaparthi/hackweek-ai-debugger/services/example_service.py", line 23, in simulate_divide_by_zero_error     raise RuntimeError("A division by zero error occurred.") from e RuntimeError: A division by zero error occurred. 
2025-04-21 12:59:14,866 - ERROR - Unhandled exception: Traceback (most recent call last):   File "/Users/nagabhaskar.alaparthi/hackweek-ai-debugger/services/example_service.py", line 21, in simulate_divide_by_zero_error     result = 1 / 0              ~~^~~ ZeroDivisionError: division by zero  The above exception was the direct cause of the following exception:  Traceback (most recent call last):   File "/Users/nagabhaskar.alaparthi/hackweek-ai-debugger/venv/lib/python3.13/site-packages/starlette/middleware/errors.py", line 165, in __call__     await self.app(scope, receive, _send)   File "/Users/nagabhaskar.alaparthi/hackweek-ai-debugger/venv/lib/python3.13/site-packages/starlette/middleware/exceptions.py", line 62, in __call__     await wrap_app_handling_exceptions(self.app, conn)(scope, receive, send)   File "/Users/nagabhaskar.alaparthi/hackweek-ai-debugger/venv/lib/python3.13/site-packages/starlette/_exception_handler.py", line 53, in wrapped_app     raise exc   File "/Users/nagabhaskar.alaparthi/hackweek-ai-debugger/venv/lib/python3.13/site-packages/starlette/_exception_handler.py", line 42, in wrapped_app     await app(scope, receive, sender)   File "/Users/nagabhaskar.alaparthi/hackweek-ai-debugger/venv/lib/python3.13/site-packages/starlette/routing.py", line 714, in __call__     await self.middleware_stack(scope, receive, send)   File "/Users/nagabhaskar.alaparthi/hackweek-ai-debugger/venv/lib/python3.13/site-packages/starlette/routing.py", line 734, in app     await route.handle(scope, receive, send)   File "/Users/nagabhaskar.alaparthi/hackweek-ai-debugger/venv/lib/python3.13/site-packages/starlette/routing.py", line 288, in handle     await self.app(scope, receive, send)   File "/Users/nagabhaskar.alaparthi/hackweek-ai-debugger/venv/lib/python3.13/site-packages/starlette/routing.py", line 76, in app     await wrap_app_handling_exceptions(app, request)(scope, receive, send)   File "/Users/nagabhaskar.alaparthi/hackweek-ai-debugger/venv/lib/python3.13/site-packages/starlette/_exception_handler.py", line 53, in wrapped_app     raise exc   File "/Users/nagabhaskar.alaparthi/hackweek-ai-debugger/venv/lib/python3.13/site-packages/starlette/_exception_handler.py", line 42, in wrapped_app     await app(scope, receive, sender)   File "/Users/nagabhaskar.alaparthi/hackweek-ai-debugger/venv/lib/python3.13/site-packages/starlette/routing.py", line 73, in app     response = await f(request)                ^^^^^^^^^^^^^^^^   File "/Users/nagabhaskar.alaparthi/hackweek-ai-debugger/venv/lib/python3.13/site-packages/fastapi/routing.py", line 301, in app     raw_response = await run_endpoint_function(                    ^^^^^^^^^^^^^^^^^^^^^^^^^^^^     ...<3 lines>...     )     ^   File "/Users/nagabhaskar.alaparthi/hackweek-ai-debugger/venv/lib/python3.13/site-packages/fastapi/routing.py", line 214, in run_endpoint_function     return await run_in_threadpool(dependant.call, **values)            ^^^^^^^^^^^^^^^^^^^^^^^^^^^^^^^^^^^^^^^^^^^^^^^^^   File "/Users/nagabhaskar.alaparthi/hackweek-ai-debugger/venv/lib/python3.13/site-packages/starlette/concurrency.py", line 37, in run_in_threadpool     return await anyio.to_thread.run_sync(func)            ^^^^^^^^^^^^^^^^^^^^^^^^^^^^^^^^^^^^   File "/Users/nagabhaskar.alaparthi/hackweek-ai-debugger/venv/lib/python3.13/site-packages/anyio/to_thread.py", line 56, in run_sync     return await get_async_backend().run_sync_in_worker_thread(            ^^^^^^^^^^^^^^^^^^^^^^^^^^^^^^^^^^^^^^^^^^^^^^^^^^^^         func, args, abandon_on_cancel=abandon_on_cancel, limiter=limiter         ^^^^^^^^^^^^^^^^^^^^^^^^^^^^^^^^^^^^^^^^^^^^^^^^^^^^^^^^^^^^^^^^     )     ^   File "/Users/nagabhaskar.alaparthi/hackweek-ai-debugger/venv/lib/python3.13/site-packages/anyio/_backends/_asyncio.py", line 2470, in run_sync_in_worker_thread     return await future            ^^^^^^^^^^^^   File "/Users/nagabhaskar.alaparthi/hackweek-ai-debugger/venv/lib/python3.13/site-packages/anyio/_backends/_asyncio.py", line 967, in run     result = context.run(func, *args)   File "/Users/nagabhaskar.alaparthi/hackweek-ai-debugger/routers/example_router.py", line 20, in trigger_divide_by_zero_error     return ExampleService.simulate_divide_by_zero_error()            ~~~~~~~~~~~~~~~~~~~~~~~~~~~~~~~~~~~~~~~~~~~~^^   File "/Users/nagabhaskar.alaparthi/hackweek-ai-debugger/services/example_service.py", line 23, in simulate_divide_by_zero_error     raise RuntimeError("A division by zero error occurred.") from e RuntimeError: A division by zero error occurred. 
2025-04-22 11:43:46,165 - ERROR - Unhandled exception: Traceback (most recent call last):   File "/Users/nagabhaskar.alaparthi/hackweek-ai-debugger/services/example_service.py", line 21, in simulate_divide_by_zero_error     result = 1 / 0              ~~^~~ ZeroDivisionError: division by zero  The above exception was the direct cause of the following exception:  Traceback (most recent call last):   File "/Users/nagabhaskar.alaparthi/hackweek-ai-debugger/venv/lib/python3.13/site-packages/starlette/middleware/errors.py", line 165, in __call__     await self.app(scope, receive, _send)   File "/Users/nagabhaskar.alaparthi/hackweek-ai-debugger/venv/lib/python3.13/site-packages/starlette/middleware/exceptions.py", line 62, in __call__     await wrap_app_handling_exceptions(self.app, conn)(scope, receive, send)   File "/Users/nagabhaskar.alaparthi/hackweek-ai-debugger/venv/lib/python3.13/site-packages/starlette/_exception_handler.py", line 53, in wrapped_app     raise exc   File "/Users/nagabhaskar.alaparthi/hackweek-ai-debugger/venv/lib/python3.13/site-packages/starlette/_exception_handler.py", line 42, in wrapped_app     await app(scope, receive, sender)   File "/Users/nagabhaskar.alaparthi/hackweek-ai-debugger/venv/lib/python3.13/site-packages/starlette/routing.py", line 714, in __call__     await self.middleware_stack(scope, receive, send)   File "/Users/nagabhaskar.alaparthi/hackweek-ai-debugger/venv/lib/python3.13/site-packages/starlette/routing.py", line 734, in app     await route.handle(scope, receive, send)   File "/Users/nagabhaskar.alaparthi/hackweek-ai-debugger/venv/lib/python3.13/site-packages/starlette/routing.py", line 288, in handle     await self.app(scope, receive, send)   File "/Users/nagabhaskar.alaparthi/hackweek-ai-debugger/venv/lib/python3.13/site-packages/starlette/routing.py", line 76, in app     await wrap_app_handling_exceptions(app, request)(scope, receive, send)   File "/Users/nagabhaskar.alaparthi/hackweek-ai-debugger/venv/lib/python3.13/site-packages/starlette/_exception_handler.py", line 53, in wrapped_app     raise exc   File "/Users/nagabhaskar.alaparthi/hackweek-ai-debugger/venv/lib/python3.13/site-packages/starlette/_exception_handler.py", line 42, in wrapped_app     await app(scope, receive, sender)   File "/Users/nagabhaskar.alaparthi/hackweek-ai-debugger/venv/lib/python3.13/site-packages/starlette/routing.py", line 73, in app     response = await f(request)                ^^^^^^^^^^^^^^^^   File "/Users/nagabhaskar.alaparthi/hackweek-ai-debugger/venv/lib/python3.13/site-packages/fastapi/routing.py", line 301, in app     raw_response = await run_endpoint_function(                    ^^^^^^^^^^^^^^^^^^^^^^^^^^^^     ...<3 lines>...     )     ^   File "/Users/nagabhaskar.alaparthi/hackweek-ai-debugger/venv/lib/python3.13/site-packages/fastapi/routing.py", line 214, in run_endpoint_function     return await run_in_threadpool(dependant.call, **values)            ^^^^^^^^^^^^^^^^^^^^^^^^^^^^^^^^^^^^^^^^^^^^^^^^^   File "/Users/nagabhaskar.alaparthi/hackweek-ai-debugger/venv/lib/python3.13/site-packages/starlette/concurrency.py", line 37, in run_in_threadpool     return await anyio.to_thread.run_sync(func)            ^^^^^^^^^^^^^^^^^^^^^^^^^^^^^^^^^^^^   File "/Users/nagabhaskar.alaparthi/hackweek-ai-debugger/venv/lib/python3.13/site-packages/anyio/to_thread.py", line 56, in run_sync     return await get_async_backend().run_sync_in_worker_thread(            ^^^^^^^^^^^^^^^^^^^^^^^^^^^^^^^^^^^^^^^^^^^^^^^^^^^^         func, args, abandon_on_cancel=abandon_on_cancel, limiter=limiter         ^^^^^^^^^^^^^^^^^^^^^^^^^^^^^^^^^^^^^^^^^^^^^^^^^^^^^^^^^^^^^^^^     )     ^   File "/Users/nagabhaskar.alaparthi/hackweek-ai-debugger/venv/lib/python3.13/site-packages/anyio/_backends/_asyncio.py", line 2470, in run_sync_in_worker_thread     return await future            ^^^^^^^^^^^^   File "/Users/nagabhaskar.alaparthi/hackweek-ai-debugger/venv/lib/python3.13/site-packages/anyio/_backends/_asyncio.py", line 967, in run     result = context.run(func, *args)   File "/Users/nagabhaskar.alaparthi/hackweek-ai-debugger/routers/example_router.py", line 20, in trigger_divide_by_zero_error     return ExampleService.simulate_divide_by_zero_error()            ~~~~~~~~~~~~~~~~~~~~~~~~~~~~~~~~~~~~~~~~~~~~^^   File "/Users/nagabhaskar.alaparthi/hackweek-ai-debugger/services/example_service.py", line 23, in simulate_divide_by_zero_error     raise RuntimeError("A division by zero error occurred.") from e RuntimeError: A division by zero error occurred. 
2025-04-22 11:45:07,360 - ERROR - Unhandled exception: Traceback (most recent call last):   File "/Users/nagabhaskar.alaparthi/hackweek-ai-debugger/services/example_service.py", line 21, in simulate_divide_by_zero_error     result = 1 / 0              ~~^~~ ZeroDivisionError: division by zero  The above exception was the direct cause of the following exception:  Traceback (most recent call last):   File "/Users/nagabhaskar.alaparthi/hackweek-ai-debugger/venv/lib/python3.13/site-packages/starlette/middleware/errors.py", line 165, in __call__     await self.app(scope, receive, _send)   File "/Users/nagabhaskar.alaparthi/hackweek-ai-debugger/venv/lib/python3.13/site-packages/starlette/middleware/exceptions.py", line 62, in __call__     await wrap_app_handling_exceptions(self.app, conn)(scope, receive, send)   File "/Users/nagabhaskar.alaparthi/hackweek-ai-debugger/venv/lib/python3.13/site-packages/starlette/_exception_handler.py", line 53, in wrapped_app     raise exc   File "/Users/nagabhaskar.alaparthi/hackweek-ai-debugger/venv/lib/python3.13/site-packages/starlette/_exception_handler.py", line 42, in wrapped_app     await app(scope, receive, sender)   File "/Users/nagabhaskar.alaparthi/hackweek-ai-debugger/venv/lib/python3.13/site-packages/starlette/routing.py", line 714, in __call__     await self.middleware_stack(scope, receive, send)   File "/Users/nagabhaskar.alaparthi/hackweek-ai-debugger/venv/lib/python3.13/site-packages/starlette/routing.py", line 734, in app     await route.handle(scope, receive, send)   File "/Users/nagabhaskar.alaparthi/hackweek-ai-debugger/venv/lib/python3.13/site-packages/starlette/routing.py", line 288, in handle     await self.app(scope, receive, send)   File "/Users/nagabhaskar.alaparthi/hackweek-ai-debugger/venv/lib/python3.13/site-packages/starlette/routing.py", line 76, in app     await wrap_app_handling_exceptions(app, request)(scope, receive, send)   File "/Users/nagabhaskar.alaparthi/hackweek-ai-debugger/venv/lib/python3.13/site-packages/starlette/_exception_handler.py", line 53, in wrapped_app     raise exc   File "/Users/nagabhaskar.alaparthi/hackweek-ai-debugger/venv/lib/python3.13/site-packages/starlette/_exception_handler.py", line 42, in wrapped_app     await app(scope, receive, sender)   File "/Users/nagabhaskar.alaparthi/hackweek-ai-debugger/venv/lib/python3.13/site-packages/starlette/routing.py", line 73, in app     response = await f(request)                ^^^^^^^^^^^^^^^^   File "/Users/nagabhaskar.alaparthi/hackweek-ai-debugger/venv/lib/python3.13/site-packages/fastapi/routing.py", line 301, in app     raw_response = await run_endpoint_function(                    ^^^^^^^^^^^^^^^^^^^^^^^^^^^^     ...<3 lines>...     )     ^   File "/Users/nagabhaskar.alaparthi/hackweek-ai-debugger/venv/lib/python3.13/site-packages/fastapi/routing.py", line 214, in run_endpoint_function     return await run_in_threadpool(dependant.call, **values)            ^^^^^^^^^^^^^^^^^^^^^^^^^^^^^^^^^^^^^^^^^^^^^^^^^   File "/Users/nagabhaskar.alaparthi/hackweek-ai-debugger/venv/lib/python3.13/site-packages/starlette/concurrency.py", line 37, in run_in_threadpool     return await anyio.to_thread.run_sync(func)            ^^^^^^^^^^^^^^^^^^^^^^^^^^^^^^^^^^^^   File "/Users/nagabhaskar.alaparthi/hackweek-ai-debugger/venv/lib/python3.13/site-packages/anyio/to_thread.py", line 56, in run_sync     return await get_async_backend().run_sync_in_worker_thread(            ^^^^^^^^^^^^^^^^^^^^^^^^^^^^^^^^^^^^^^^^^^^^^^^^^^^^         func, args, abandon_on_cancel=abandon_on_cancel, limiter=limiter         ^^^^^^^^^^^^^^^^^^^^^^^^^^^^^^^^^^^^^^^^^^^^^^^^^^^^^^^^^^^^^^^^     )     ^   File "/Users/nagabhaskar.alaparthi/hackweek-ai-debugger/venv/lib/python3.13/site-packages/anyio/_backends/_asyncio.py", line 2470, in run_sync_in_worker_thread     return await future            ^^^^^^^^^^^^   File "/Users/nagabhaskar.alaparthi/hackweek-ai-debugger/venv/lib/python3.13/site-packages/anyio/_backends/_asyncio.py", line 967, in run     result = context.run(func, *args)   File "/Users/nagabhaskar.alaparthi/hackweek-ai-debugger/routers/example_router.py", line 20, in trigger_divide_by_zero_error     return ExampleService.simulate_divide_by_zero_error()            ~~~~~~~~~~~~~~~~~~~~~~~~~~~~~~~~~~~~~~~~~~~~^^   File "/Users/nagabhaskar.alaparthi/hackweek-ai-debugger/services/example_service.py", line 23, in simulate_divide_by_zero_error     raise RuntimeError("A division by zero error occurred.") from e RuntimeError: A division by zero error occurred. 
2025-04-22 11:50:03,354 - ERROR - Unhandled exception: Traceback (most recent call last):   File "/Users/nagabhaskar.alaparthi/hackweek-ai-debugger/services/example_service.py", line 21, in simulate_divide_by_zero_error     result = 1 / 0              ~~^~~ ZeroDivisionError: division by zero  The above exception was the direct cause of the following exception:  Traceback (most recent call last):   File "/Users/nagabhaskar.alaparthi/hackweek-ai-debugger/venv/lib/python3.13/site-packages/starlette/middleware/errors.py", line 165, in __call__     await self.app(scope, receive, _send)   File "/Users/nagabhaskar.alaparthi/hackweek-ai-debugger/venv/lib/python3.13/site-packages/starlette/middleware/exceptions.py", line 62, in __call__     await wrap_app_handling_exceptions(self.app, conn)(scope, receive, send)   File "/Users/nagabhaskar.alaparthi/hackweek-ai-debugger/venv/lib/python3.13/site-packages/starlette/_exception_handler.py", line 53, in wrapped_app     raise exc   File "/Users/nagabhaskar.alaparthi/hackweek-ai-debugger/venv/lib/python3.13/site-packages/starlette/_exception_handler.py", line 42, in wrapped_app     await app(scope, receive, sender)   File "/Users/nagabhaskar.alaparthi/hackweek-ai-debugger/venv/lib/python3.13/site-packages/starlette/routing.py", line 714, in __call__     await self.middleware_stack(scope, receive, send)   File "/Users/nagabhaskar.alaparthi/hackweek-ai-debugger/venv/lib/python3.13/site-packages/starlette/routing.py", line 734, in app     await route.handle(scope, receive, send)   File "/Users/nagabhaskar.alaparthi/hackweek-ai-debugger/venv/lib/python3.13/site-packages/starlette/routing.py", line 288, in handle     await self.app(scope, receive, send)   File "/Users/nagabhaskar.alaparthi/hackweek-ai-debugger/venv/lib/python3.13/site-packages/starlette/routing.py", line 76, in app     await wrap_app_handling_exceptions(app, request)(scope, receive, send)   File "/Users/nagabhaskar.alaparthi/hackweek-ai-debugger/venv/lib/python3.13/site-packages/starlette/_exception_handler.py", line 53, in wrapped_app     raise exc   File "/Users/nagabhaskar.alaparthi/hackweek-ai-debugger/venv/lib/python3.13/site-packages/starlette/_exception_handler.py", line 42, in wrapped_app     await app(scope, receive, sender)   File "/Users/nagabhaskar.alaparthi/hackweek-ai-debugger/venv/lib/python3.13/site-packages/starlette/routing.py", line 73, in app     response = await f(request)                ^^^^^^^^^^^^^^^^   File "/Users/nagabhaskar.alaparthi/hackweek-ai-debugger/venv/lib/python3.13/site-packages/fastapi/routing.py", line 301, in app     raw_response = await run_endpoint_function(                    ^^^^^^^^^^^^^^^^^^^^^^^^^^^^     ...<3 lines>...     )     ^   File "/Users/nagabhaskar.alaparthi/hackweek-ai-debugger/venv/lib/python3.13/site-packages/fastapi/routing.py", line 214, in run_endpoint_function     return await run_in_threadpool(dependant.call, **values)            ^^^^^^^^^^^^^^^^^^^^^^^^^^^^^^^^^^^^^^^^^^^^^^^^^   File "/Users/nagabhaskar.alaparthi/hackweek-ai-debugger/venv/lib/python3.13/site-packages/starlette/concurrency.py", line 37, in run_in_threadpool     return await anyio.to_thread.run_sync(func)            ^^^^^^^^^^^^^^^^^^^^^^^^^^^^^^^^^^^^   File "/Users/nagabhaskar.alaparthi/hackweek-ai-debugger/venv/lib/python3.13/site-packages/anyio/to_thread.py", line 56, in run_sync     return await get_async_backend().run_sync_in_worker_thread(            ^^^^^^^^^^^^^^^^^^^^^^^^^^^^^^^^^^^^^^^^^^^^^^^^^^^^         func, args, abandon_on_cancel=abandon_on_cancel, limiter=limiter         ^^^^^^^^^^^^^^^^^^^^^^^^^^^^^^^^^^^^^^^^^^^^^^^^^^^^^^^^^^^^^^^^     )     ^   File "/Users/nagabhaskar.alaparthi/hackweek-ai-debugger/venv/lib/python3.13/site-packages/anyio/_backends/_asyncio.py", line 2470, in run_sync_in_worker_thread     return await future            ^^^^^^^^^^^^   File "/Users/nagabhaskar.alaparthi/hackweek-ai-debugger/venv/lib/python3.13/site-packages/anyio/_backends/_asyncio.py", line 967, in run     result = context.run(func, *args)   File "/Users/nagabhaskar.alaparthi/hackweek-ai-debugger/routers/example_router.py", line 20, in trigger_divide_by_zero_error     return ExampleService.simulate_divide_by_zero_error()            ~~~~~~~~~~~~~~~~~~~~~~~~~~~~~~~~~~~~~~~~~~~~^^   File "/Users/nagabhaskar.alaparthi/hackweek-ai-debugger/services/example_service.py", line 23, in simulate_divide_by_zero_error     raise RuntimeError("A division by zero error occurred.") from e RuntimeError: A division by zero error occurred. 
2025-04-22 11:53:25,798 - ERROR - Unhandled exception: Traceback (most recent call last):   File "/Users/nagabhaskar.alaparthi/hackweek-ai-debugger/services/example_service.py", line 21, in simulate_divide_by_zero_error     result = 1 / 0              ~~^~~ ZeroDivisionError: division by zero  The above exception was the direct cause of the following exception:  Traceback (most recent call last):   File "/Users/nagabhaskar.alaparthi/hackweek-ai-debugger/venv/lib/python3.13/site-packages/starlette/middleware/errors.py", line 165, in __call__     await self.app(scope, receive, _send)   File "/Users/nagabhaskar.alaparthi/hackweek-ai-debugger/venv/lib/python3.13/site-packages/starlette/middleware/exceptions.py", line 62, in __call__     await wrap_app_handling_exceptions(self.app, conn)(scope, receive, send)   File "/Users/nagabhaskar.alaparthi/hackweek-ai-debugger/venv/lib/python3.13/site-packages/starlette/_exception_handler.py", line 53, in wrapped_app     raise exc   File "/Users/nagabhaskar.alaparthi/hackweek-ai-debugger/venv/lib/python3.13/site-packages/starlette/_exception_handler.py", line 42, in wrapped_app     await app(scope, receive, sender)   File "/Users/nagabhaskar.alaparthi/hackweek-ai-debugger/venv/lib/python3.13/site-packages/starlette/routing.py", line 714, in __call__     await self.middleware_stack(scope, receive, send)   File "/Users/nagabhaskar.alaparthi/hackweek-ai-debugger/venv/lib/python3.13/site-packages/starlette/routing.py", line 734, in app     await route.handle(scope, receive, send)   File "/Users/nagabhaskar.alaparthi/hackweek-ai-debugger/venv/lib/python3.13/site-packages/starlette/routing.py", line 288, in handle     await self.app(scope, receive, send)   File "/Users/nagabhaskar.alaparthi/hackweek-ai-debugger/venv/lib/python3.13/site-packages/starlette/routing.py", line 76, in app     await wrap_app_handling_exceptions(app, request)(scope, receive, send)   File "/Users/nagabhaskar.alaparthi/hackweek-ai-debugger/venv/lib/python3.13/site-packages/starlette/_exception_handler.py", line 53, in wrapped_app     raise exc   File "/Users/nagabhaskar.alaparthi/hackweek-ai-debugger/venv/lib/python3.13/site-packages/starlette/_exception_handler.py", line 42, in wrapped_app     await app(scope, receive, sender)   File "/Users/nagabhaskar.alaparthi/hackweek-ai-debugger/venv/lib/python3.13/site-packages/starlette/routing.py", line 73, in app     response = await f(request)                ^^^^^^^^^^^^^^^^   File "/Users/nagabhaskar.alaparthi/hackweek-ai-debugger/venv/lib/python3.13/site-packages/fastapi/routing.py", line 301, in app     raw_response = await run_endpoint_function(                    ^^^^^^^^^^^^^^^^^^^^^^^^^^^^     ...<3 lines>...     )     ^   File "/Users/nagabhaskar.alaparthi/hackweek-ai-debugger/venv/lib/python3.13/site-packages/fastapi/routing.py", line 214, in run_endpoint_function     return await run_in_threadpool(dependant.call, **values)            ^^^^^^^^^^^^^^^^^^^^^^^^^^^^^^^^^^^^^^^^^^^^^^^^^   File "/Users/nagabhaskar.alaparthi/hackweek-ai-debugger/venv/lib/python3.13/site-packages/starlette/concurrency.py", line 37, in run_in_threadpool     return await anyio.to_thread.run_sync(func)            ^^^^^^^^^^^^^^^^^^^^^^^^^^^^^^^^^^^^   File "/Users/nagabhaskar.alaparthi/hackweek-ai-debugger/venv/lib/python3.13/site-packages/anyio/to_thread.py", line 56, in run_sync     return await get_async_backend().run_sync_in_worker_thread(            ^^^^^^^^^^^^^^^^^^^^^^^^^^^^^^^^^^^^^^^^^^^^^^^^^^^^         func, args, abandon_on_cancel=abandon_on_cancel, limiter=limiter         ^^^^^^^^^^^^^^^^^^^^^^^^^^^^^^^^^^^^^^^^^^^^^^^^^^^^^^^^^^^^^^^^     )     ^   File "/Users/nagabhaskar.alaparthi/hackweek-ai-debugger/venv/lib/python3.13/site-packages/anyio/_backends/_asyncio.py", line 2470, in run_sync_in_worker_thread     return await future            ^^^^^^^^^^^^   File "/Users/nagabhaskar.alaparthi/hackweek-ai-debugger/venv/lib/python3.13/site-packages/anyio/_backends/_asyncio.py", line 967, in run     result = context.run(func, *args)   File "/Users/nagabhaskar.alaparthi/hackweek-ai-debugger/routers/example_router.py", line 20, in trigger_divide_by_zero_error     return ExampleService.simulate_divide_by_zero_error()            ~~~~~~~~~~~~~~~~~~~~~~~~~~~~~~~~~~~~~~~~~~~~^^   File "/Users/nagabhaskar.alaparthi/hackweek-ai-debugger/services/example_service.py", line 23, in simulate_divide_by_zero_error     raise RuntimeError("A division by zero error occurred.") from e RuntimeError: A division by zero error occurred. 
2025-04-22 12:00:17,450 - ERROR - Unhandled exception: Traceback (most recent call last):   File "/Users/nagabhaskar.alaparthi/hackweek-ai-debugger/services/example_service.py", line 21, in simulate_divide_by_zero_error     result = 1 / 0              ~~^~~ ZeroDivisionError: division by zero  The above exception was the direct cause of the following exception:  Traceback (most recent call last):   File "/Users/nagabhaskar.alaparthi/hackweek-ai-debugger/venv/lib/python3.13/site-packages/starlette/middleware/errors.py", line 165, in __call__     await self.app(scope, receive, _send)   File "/Users/nagabhaskar.alaparthi/hackweek-ai-debugger/venv/lib/python3.13/site-packages/starlette/middleware/exceptions.py", line 62, in __call__     await wrap_app_handling_exceptions(self.app, conn)(scope, receive, send)   File "/Users/nagabhaskar.alaparthi/hackweek-ai-debugger/venv/lib/python3.13/site-packages/starlette/_exception_handler.py", line 53, in wrapped_app     raise exc   File "/Users/nagabhaskar.alaparthi/hackweek-ai-debugger/venv/lib/python3.13/site-packages/starlette/_exception_handler.py", line 42, in wrapped_app     await app(scope, receive, sender)   File "/Users/nagabhaskar.alaparthi/hackweek-ai-debugger/venv/lib/python3.13/site-packages/starlette/routing.py", line 714, in __call__     await self.middleware_stack(scope, receive, send)   File "/Users/nagabhaskar.alaparthi/hackweek-ai-debugger/venv/lib/python3.13/site-packages/starlette/routing.py", line 734, in app     await route.handle(scope, receive, send)   File "/Users/nagabhaskar.alaparthi/hackweek-ai-debugger/venv/lib/python3.13/site-packages/starlette/routing.py", line 288, in handle     await self.app(scope, receive, send)   File "/Users/nagabhaskar.alaparthi/hackweek-ai-debugger/venv/lib/python3.13/site-packages/starlette/routing.py", line 76, in app     await wrap_app_handling_exceptions(app, request)(scope, receive, send)   File "/Users/nagabhaskar.alaparthi/hackweek-ai-debugger/venv/lib/python3.13/site-packages/starlette/_exception_handler.py", line 53, in wrapped_app     raise exc   File "/Users/nagabhaskar.alaparthi/hackweek-ai-debugger/venv/lib/python3.13/site-packages/starlette/_exception_handler.py", line 42, in wrapped_app     await app(scope, receive, sender)   File "/Users/nagabhaskar.alaparthi/hackweek-ai-debugger/venv/lib/python3.13/site-packages/starlette/routing.py", line 73, in app     response = await f(request)                ^^^^^^^^^^^^^^^^   File "/Users/nagabhaskar.alaparthi/hackweek-ai-debugger/venv/lib/python3.13/site-packages/fastapi/routing.py", line 301, in app     raw_response = await run_endpoint_function(                    ^^^^^^^^^^^^^^^^^^^^^^^^^^^^     ...<3 lines>...     )     ^   File "/Users/nagabhaskar.alaparthi/hackweek-ai-debugger/venv/lib/python3.13/site-packages/fastapi/routing.py", line 214, in run_endpoint_function     return await run_in_threadpool(dependant.call, **values)            ^^^^^^^^^^^^^^^^^^^^^^^^^^^^^^^^^^^^^^^^^^^^^^^^^   File "/Users/nagabhaskar.alaparthi/hackweek-ai-debugger/venv/lib/python3.13/site-packages/starlette/concurrency.py", line 37, in run_in_threadpool     return await anyio.to_thread.run_sync(func)            ^^^^^^^^^^^^^^^^^^^^^^^^^^^^^^^^^^^^   File "/Users/nagabhaskar.alaparthi/hackweek-ai-debugger/venv/lib/python3.13/site-packages/anyio/to_thread.py", line 56, in run_sync     return await get_async_backend().run_sync_in_worker_thread(            ^^^^^^^^^^^^^^^^^^^^^^^^^^^^^^^^^^^^^^^^^^^^^^^^^^^^         func, args, abandon_on_cancel=abandon_on_cancel, limiter=limiter         ^^^^^^^^^^^^^^^^^^^^^^^^^^^^^^^^^^^^^^^^^^^^^^^^^^^^^^^^^^^^^^^^     )     ^   File "/Users/nagabhaskar.alaparthi/hackweek-ai-debugger/venv/lib/python3.13/site-packages/anyio/_backends/_asyncio.py", line 2470, in run_sync_in_worker_thread     return await future            ^^^^^^^^^^^^   File "/Users/nagabhaskar.alaparthi/hackweek-ai-debugger/venv/lib/python3.13/site-packages/anyio/_backends/_asyncio.py", line 967, in run     result = context.run(func, *args)   File "/Users/nagabhaskar.alaparthi/hackweek-ai-debugger/routers/example_router.py", line 20, in trigger_divide_by_zero_error     return ExampleService.simulate_divide_by_zero_error()            ~~~~~~~~~~~~~~~~~~~~~~~~~~~~~~~~~~~~~~~~~~~~^^   File "/Users/nagabhaskar.alaparthi/hackweek-ai-debugger/services/example_service.py", line 23, in simulate_divide_by_zero_error     raise RuntimeError("A division by zero error occurred.") from e RuntimeError: A division by zero error occurred. 
2025-04-22 12:01:52,297 - ERROR - Unhandled exception: Traceback (most recent call last):   File "/Users/nagabhaskar.alaparthi/hackweek-ai-debugger/services/example_service.py", line 21, in simulate_divide_by_zero_error     result = 1 / 0              ~~^~~ ZeroDivisionError: division by zero  The above exception was the direct cause of the following exception:  Traceback (most recent call last):   File "/Users/nagabhaskar.alaparthi/hackweek-ai-debugger/venv/lib/python3.13/site-packages/starlette/middleware/errors.py", line 165, in __call__     await self.app(scope, receive, _send)   File "/Users/nagabhaskar.alaparthi/hackweek-ai-debugger/venv/lib/python3.13/site-packages/starlette/middleware/exceptions.py", line 62, in __call__     await wrap_app_handling_exceptions(self.app, conn)(scope, receive, send)   File "/Users/nagabhaskar.alaparthi/hackweek-ai-debugger/venv/lib/python3.13/site-packages/starlette/_exception_handler.py", line 53, in wrapped_app     raise exc   File "/Users/nagabhaskar.alaparthi/hackweek-ai-debugger/venv/lib/python3.13/site-packages/starlette/_exception_handler.py", line 42, in wrapped_app     await app(scope, receive, sender)   File "/Users/nagabhaskar.alaparthi/hackweek-ai-debugger/venv/lib/python3.13/site-packages/starlette/routing.py", line 714, in __call__     await self.middleware_stack(scope, receive, send)   File "/Users/nagabhaskar.alaparthi/hackweek-ai-debugger/venv/lib/python3.13/site-packages/starlette/routing.py", line 734, in app     await route.handle(scope, receive, send)   File "/Users/nagabhaskar.alaparthi/hackweek-ai-debugger/venv/lib/python3.13/site-packages/starlette/routing.py", line 288, in handle     await self.app(scope, receive, send)   File "/Users/nagabhaskar.alaparthi/hackweek-ai-debugger/venv/lib/python3.13/site-packages/starlette/routing.py", line 76, in app     await wrap_app_handling_exceptions(app, request)(scope, receive, send)   File "/Users/nagabhaskar.alaparthi/hackweek-ai-debugger/venv/lib/python3.13/site-packages/starlette/_exception_handler.py", line 53, in wrapped_app     raise exc   File "/Users/nagabhaskar.alaparthi/hackweek-ai-debugger/venv/lib/python3.13/site-packages/starlette/_exception_handler.py", line 42, in wrapped_app     await app(scope, receive, sender)   File "/Users/nagabhaskar.alaparthi/hackweek-ai-debugger/venv/lib/python3.13/site-packages/starlette/routing.py", line 73, in app     response = await f(request)                ^^^^^^^^^^^^^^^^   File "/Users/nagabhaskar.alaparthi/hackweek-ai-debugger/venv/lib/python3.13/site-packages/fastapi/routing.py", line 301, in app     raw_response = await run_endpoint_function(                    ^^^^^^^^^^^^^^^^^^^^^^^^^^^^     ...<3 lines>...     )     ^   File "/Users/nagabhaskar.alaparthi/hackweek-ai-debugger/venv/lib/python3.13/site-packages/fastapi/routing.py", line 214, in run_endpoint_function     return await run_in_threadpool(dependant.call, **values)            ^^^^^^^^^^^^^^^^^^^^^^^^^^^^^^^^^^^^^^^^^^^^^^^^^   File "/Users/nagabhaskar.alaparthi/hackweek-ai-debugger/venv/lib/python3.13/site-packages/starlette/concurrency.py", line 37, in run_in_threadpool     return await anyio.to_thread.run_sync(func)            ^^^^^^^^^^^^^^^^^^^^^^^^^^^^^^^^^^^^   File "/Users/nagabhaskar.alaparthi/hackweek-ai-debugger/venv/lib/python3.13/site-packages/anyio/to_thread.py", line 56, in run_sync     return await get_async_backend().run_sync_in_worker_thread(            ^^^^^^^^^^^^^^^^^^^^^^^^^^^^^^^^^^^^^^^^^^^^^^^^^^^^         func, args, abandon_on_cancel=abandon_on_cancel, limiter=limiter         ^^^^^^^^^^^^^^^^^^^^^^^^^^^^^^^^^^^^^^^^^^^^^^^^^^^^^^^^^^^^^^^^     )     ^   File "/Users/nagabhaskar.alaparthi/hackweek-ai-debugger/venv/lib/python3.13/site-packages/anyio/_backends/_asyncio.py", line 2470, in run_sync_in_worker_thread     return await future            ^^^^^^^^^^^^   File "/Users/nagabhaskar.alaparthi/hackweek-ai-debugger/venv/lib/python3.13/site-packages/anyio/_backends/_asyncio.py", line 967, in run     result = context.run(func, *args)   File "/Users/nagabhaskar.alaparthi/hackweek-ai-debugger/routers/example_router.py", line 20, in trigger_divide_by_zero_error     return ExampleService.simulate_divide_by_zero_error()            ~~~~~~~~~~~~~~~~~~~~~~~~~~~~~~~~~~~~~~~~~~~~^^   File "/Users/nagabhaskar.alaparthi/hackweek-ai-debugger/services/example_service.py", line 23, in simulate_divide_by_zero_error     raise RuntimeError("A division by zero error occurred.") from e RuntimeError: A division by zero error occurred. 
2025-04-22 12:02:27,145 - ERROR - Unhandled exception: Traceback (most recent call last):   File "/Users/nagabhaskar.alaparthi/hackweek-ai-debugger/services/example_service.py", line 21, in simulate_divide_by_zero_error     result = 1 / 0              ~~^~~ ZeroDivisionError: division by zero  The above exception was the direct cause of the following exception:  Traceback (most recent call last):   File "/Users/nagabhaskar.alaparthi/hackweek-ai-debugger/venv/lib/python3.13/site-packages/starlette/middleware/errors.py", line 165, in __call__     await self.app(scope, receive, _send)   File "/Users/nagabhaskar.alaparthi/hackweek-ai-debugger/venv/lib/python3.13/site-packages/starlette/middleware/exceptions.py", line 62, in __call__     await wrap_app_handling_exceptions(self.app, conn)(scope, receive, send)   File "/Users/nagabhaskar.alaparthi/hackweek-ai-debugger/venv/lib/python3.13/site-packages/starlette/_exception_handler.py", line 53, in wrapped_app     raise exc   File "/Users/nagabhaskar.alaparthi/hackweek-ai-debugger/venv/lib/python3.13/site-packages/starlette/_exception_handler.py", line 42, in wrapped_app     await app(scope, receive, sender)   File "/Users/nagabhaskar.alaparthi/hackweek-ai-debugger/venv/lib/python3.13/site-packages/starlette/routing.py", line 714, in __call__     await self.middleware_stack(scope, receive, send)   File "/Users/nagabhaskar.alaparthi/hackweek-ai-debugger/venv/lib/python3.13/site-packages/starlette/routing.py", line 734, in app     await route.handle(scope, receive, send)   File "/Users/nagabhaskar.alaparthi/hackweek-ai-debugger/venv/lib/python3.13/site-packages/starlette/routing.py", line 288, in handle     await self.app(scope, receive, send)   File "/Users/nagabhaskar.alaparthi/hackweek-ai-debugger/venv/lib/python3.13/site-packages/starlette/routing.py", line 76, in app     await wrap_app_handling_exceptions(app, request)(scope, receive, send)   File "/Users/nagabhaskar.alaparthi/hackweek-ai-debugger/venv/lib/python3.13/site-packages/starlette/_exception_handler.py", line 53, in wrapped_app     raise exc   File "/Users/nagabhaskar.alaparthi/hackweek-ai-debugger/venv/lib/python3.13/site-packages/starlette/_exception_handler.py", line 42, in wrapped_app     await app(scope, receive, sender)   File "/Users/nagabhaskar.alaparthi/hackweek-ai-debugger/venv/lib/python3.13/site-packages/starlette/routing.py", line 73, in app     response = await f(request)                ^^^^^^^^^^^^^^^^   File "/Users/nagabhaskar.alaparthi/hackweek-ai-debugger/venv/lib/python3.13/site-packages/fastapi/routing.py", line 301, in app     raw_response = await run_endpoint_function(                    ^^^^^^^^^^^^^^^^^^^^^^^^^^^^     ...<3 lines>...     )     ^   File "/Users/nagabhaskar.alaparthi/hackweek-ai-debugger/venv/lib/python3.13/site-packages/fastapi/routing.py", line 214, in run_endpoint_function     return await run_in_threadpool(dependant.call, **values)            ^^^^^^^^^^^^^^^^^^^^^^^^^^^^^^^^^^^^^^^^^^^^^^^^^   File "/Users/nagabhaskar.alaparthi/hackweek-ai-debugger/venv/lib/python3.13/site-packages/starlette/concurrency.py", line 37, in run_in_threadpool     return await anyio.to_thread.run_sync(func)            ^^^^^^^^^^^^^^^^^^^^^^^^^^^^^^^^^^^^   File "/Users/nagabhaskar.alaparthi/hackweek-ai-debugger/venv/lib/python3.13/site-packages/anyio/to_thread.py", line 56, in run_sync     return await get_async_backend().run_sync_in_worker_thread(            ^^^^^^^^^^^^^^^^^^^^^^^^^^^^^^^^^^^^^^^^^^^^^^^^^^^^         func, args, abandon_on_cancel=abandon_on_cancel, limiter=limiter         ^^^^^^^^^^^^^^^^^^^^^^^^^^^^^^^^^^^^^^^^^^^^^^^^^^^^^^^^^^^^^^^^     )     ^   File "/Users/nagabhaskar.alaparthi/hackweek-ai-debugger/venv/lib/python3.13/site-packages/anyio/_backends/_asyncio.py", line 2470, in run_sync_in_worker_thread     return await future            ^^^^^^^^^^^^   File "/Users/nagabhaskar.alaparthi/hackweek-ai-debugger/venv/lib/python3.13/site-packages/anyio/_backends/_asyncio.py", line 967, in run     result = context.run(func, *args)   File "/Users/nagabhaskar.alaparthi/hackweek-ai-debugger/routers/example_router.py", line 20, in trigger_divide_by_zero_error     return ExampleService.simulate_divide_by_zero_error()            ~~~~~~~~~~~~~~~~~~~~~~~~~~~~~~~~~~~~~~~~~~~~^^   File "/Users/nagabhaskar.alaparthi/hackweek-ai-debugger/services/example_service.py", line 23, in simulate_divide_by_zero_error     raise RuntimeError("A division by zero error occurred.") from e RuntimeError: A division by zero error occurred. 
2025-04-22 12:24:40,885 - ERROR - Unhandled exception: Traceback (most recent call last):   File "/Users/nagabhaskar.alaparthi/hackweek-ai-debugger/services/example_service.py", line 21, in simulate_divide_by_zero_error     result = 1 / 0              ~~^~~ ZeroDivisionError: division by zero  The above exception was the direct cause of the following exception:  Traceback (most recent call last):   File "/Users/nagabhaskar.alaparthi/hackweek-ai-debugger/venv/lib/python3.13/site-packages/starlette/middleware/errors.py", line 165, in __call__     await self.app(scope, receive, _send)   File "/Users/nagabhaskar.alaparthi/hackweek-ai-debugger/venv/lib/python3.13/site-packages/starlette/middleware/exceptions.py", line 62, in __call__     await wrap_app_handling_exceptions(self.app, conn)(scope, receive, send)   File "/Users/nagabhaskar.alaparthi/hackweek-ai-debugger/venv/lib/python3.13/site-packages/starlette/_exception_handler.py", line 53, in wrapped_app     raise exc   File "/Users/nagabhaskar.alaparthi/hackweek-ai-debugger/venv/lib/python3.13/site-packages/starlette/_exception_handler.py", line 42, in wrapped_app     await app(scope, receive, sender)   File "/Users/nagabhaskar.alaparthi/hackweek-ai-debugger/venv/lib/python3.13/site-packages/starlette/routing.py", line 714, in __call__     await self.middleware_stack(scope, receive, send)   File "/Users/nagabhaskar.alaparthi/hackweek-ai-debugger/venv/lib/python3.13/site-packages/starlette/routing.py", line 734, in app     await route.handle(scope, receive, send)   File "/Users/nagabhaskar.alaparthi/hackweek-ai-debugger/venv/lib/python3.13/site-packages/starlette/routing.py", line 288, in handle     await self.app(scope, receive, send)   File "/Users/nagabhaskar.alaparthi/hackweek-ai-debugger/venv/lib/python3.13/site-packages/starlette/routing.py", line 76, in app     await wrap_app_handling_exceptions(app, request)(scope, receive, send)   File "/Users/nagabhaskar.alaparthi/hackweek-ai-debugger/venv/lib/python3.13/site-packages/starlette/_exception_handler.py", line 53, in wrapped_app     raise exc   File "/Users/nagabhaskar.alaparthi/hackweek-ai-debugger/venv/lib/python3.13/site-packages/starlette/_exception_handler.py", line 42, in wrapped_app     await app(scope, receive, sender)   File "/Users/nagabhaskar.alaparthi/hackweek-ai-debugger/venv/lib/python3.13/site-packages/starlette/routing.py", line 73, in app     response = await f(request)                ^^^^^^^^^^^^^^^^   File "/Users/nagabhaskar.alaparthi/hackweek-ai-debugger/venv/lib/python3.13/site-packages/fastapi/routing.py", line 301, in app     raw_response = await run_endpoint_function(                    ^^^^^^^^^^^^^^^^^^^^^^^^^^^^     ...<3 lines>...     )     ^   File "/Users/nagabhaskar.alaparthi/hackweek-ai-debugger/venv/lib/python3.13/site-packages/fastapi/routing.py", line 214, in run_endpoint_function     return await run_in_threadpool(dependant.call, **values)            ^^^^^^^^^^^^^^^^^^^^^^^^^^^^^^^^^^^^^^^^^^^^^^^^^   File "/Users/nagabhaskar.alaparthi/hackweek-ai-debugger/venv/lib/python3.13/site-packages/starlette/concurrency.py", line 37, in run_in_threadpool     return await anyio.to_thread.run_sync(func)            ^^^^^^^^^^^^^^^^^^^^^^^^^^^^^^^^^^^^   File "/Users/nagabhaskar.alaparthi/hackweek-ai-debugger/venv/lib/python3.13/site-packages/anyio/to_thread.py", line 56, in run_sync     return await get_async_backend().run_sync_in_worker_thread(            ^^^^^^^^^^^^^^^^^^^^^^^^^^^^^^^^^^^^^^^^^^^^^^^^^^^^         func, args, abandon_on_cancel=abandon_on_cancel, limiter=limiter         ^^^^^^^^^^^^^^^^^^^^^^^^^^^^^^^^^^^^^^^^^^^^^^^^^^^^^^^^^^^^^^^^     )     ^   File "/Users/nagabhaskar.alaparthi/hackweek-ai-debugger/venv/lib/python3.13/site-packages/anyio/_backends/_asyncio.py", line 2470, in run_sync_in_worker_thread     return await future            ^^^^^^^^^^^^   File "/Users/nagabhaskar.alaparthi/hackweek-ai-debugger/venv/lib/python3.13/site-packages/anyio/_backends/_asyncio.py", line 967, in run     result = context.run(func, *args)   File "/Users/nagabhaskar.alaparthi/hackweek-ai-debugger/routers/example_router.py", line 20, in trigger_divide_by_zero_error     return ExampleService.simulate_divide_by_zero_error()            ~~~~~~~~~~~~~~~~~~~~~~~~~~~~~~~~~~~~~~~~~~~~^^   File "/Users/nagabhaskar.alaparthi/hackweek-ai-debugger/services/example_service.py", line 23, in simulate_divide_by_zero_error     raise RuntimeError("A division by zero error occurred.") from e RuntimeError: A division by zero error occurred. 
2025-04-22 12:27:48,289 - ERROR - Unhandled exception: Traceback (most recent call last):   File "/Users/nagabhaskar.alaparthi/hackweek-ai-debugger/services/example_service.py", line 21, in simulate_divide_by_zero_error     result = 1 / 0              ~~^~~ ZeroDivisionError: division by zero  The above exception was the direct cause of the following exception:  Traceback (most recent call last):   File "/Users/nagabhaskar.alaparthi/hackweek-ai-debugger/venv/lib/python3.13/site-packages/starlette/middleware/errors.py", line 165, in __call__     await self.app(scope, receive, _send)   File "/Users/nagabhaskar.alaparthi/hackweek-ai-debugger/venv/lib/python3.13/site-packages/starlette/middleware/exceptions.py", line 62, in __call__     await wrap_app_handling_exceptions(self.app, conn)(scope, receive, send)   File "/Users/nagabhaskar.alaparthi/hackweek-ai-debugger/venv/lib/python3.13/site-packages/starlette/_exception_handler.py", line 53, in wrapped_app     raise exc   File "/Users/nagabhaskar.alaparthi/hackweek-ai-debugger/venv/lib/python3.13/site-packages/starlette/_exception_handler.py", line 42, in wrapped_app     await app(scope, receive, sender)   File "/Users/nagabhaskar.alaparthi/hackweek-ai-debugger/venv/lib/python3.13/site-packages/starlette/routing.py", line 714, in __call__     await self.middleware_stack(scope, receive, send)   File "/Users/nagabhaskar.alaparthi/hackweek-ai-debugger/venv/lib/python3.13/site-packages/starlette/routing.py", line 734, in app     await route.handle(scope, receive, send)   File "/Users/nagabhaskar.alaparthi/hackweek-ai-debugger/venv/lib/python3.13/site-packages/starlette/routing.py", line 288, in handle     await self.app(scope, receive, send)   File "/Users/nagabhaskar.alaparthi/hackweek-ai-debugger/venv/lib/python3.13/site-packages/starlette/routing.py", line 76, in app     await wrap_app_handling_exceptions(app, request)(scope, receive, send)   File "/Users/nagabhaskar.alaparthi/hackweek-ai-debugger/venv/lib/python3.13/site-packages/starlette/_exception_handler.py", line 53, in wrapped_app     raise exc   File "/Users/nagabhaskar.alaparthi/hackweek-ai-debugger/venv/lib/python3.13/site-packages/starlette/_exception_handler.py", line 42, in wrapped_app     await app(scope, receive, sender)   File "/Users/nagabhaskar.alaparthi/hackweek-ai-debugger/venv/lib/python3.13/site-packages/starlette/routing.py", line 73, in app     response = await f(request)                ^^^^^^^^^^^^^^^^   File "/Users/nagabhaskar.alaparthi/hackweek-ai-debugger/venv/lib/python3.13/site-packages/fastapi/routing.py", line 301, in app     raw_response = await run_endpoint_function(                    ^^^^^^^^^^^^^^^^^^^^^^^^^^^^     ...<3 lines>...     )     ^   File "/Users/nagabhaskar.alaparthi/hackweek-ai-debugger/venv/lib/python3.13/site-packages/fastapi/routing.py", line 214, in run_endpoint_function     return await run_in_threadpool(dependant.call, **values)            ^^^^^^^^^^^^^^^^^^^^^^^^^^^^^^^^^^^^^^^^^^^^^^^^^   File "/Users/nagabhaskar.alaparthi/hackweek-ai-debugger/venv/lib/python3.13/site-packages/starlette/concurrency.py", line 37, in run_in_threadpool     return await anyio.to_thread.run_sync(func)            ^^^^^^^^^^^^^^^^^^^^^^^^^^^^^^^^^^^^   File "/Users/nagabhaskar.alaparthi/hackweek-ai-debugger/venv/lib/python3.13/site-packages/anyio/to_thread.py", line 56, in run_sync     return await get_async_backend().run_sync_in_worker_thread(            ^^^^^^^^^^^^^^^^^^^^^^^^^^^^^^^^^^^^^^^^^^^^^^^^^^^^         func, args, abandon_on_cancel=abandon_on_cancel, limiter=limiter         ^^^^^^^^^^^^^^^^^^^^^^^^^^^^^^^^^^^^^^^^^^^^^^^^^^^^^^^^^^^^^^^^     )     ^   File "/Users/nagabhaskar.alaparthi/hackweek-ai-debugger/venv/lib/python3.13/site-packages/anyio/_backends/_asyncio.py", line 2470, in run_sync_in_worker_thread     return await future            ^^^^^^^^^^^^   File "/Users/nagabhaskar.alaparthi/hackweek-ai-debugger/venv/lib/python3.13/site-packages/anyio/_backends/_asyncio.py", line 967, in run     result = context.run(func, *args)   File "/Users/nagabhaskar.alaparthi/hackweek-ai-debugger/routers/example_router.py", line 20, in trigger_divide_by_zero_error     return ExampleService.simulate_divide_by_zero_error()            ~~~~~~~~~~~~~~~~~~~~~~~~~~~~~~~~~~~~~~~~~~~~^^   File "/Users/nagabhaskar.alaparthi/hackweek-ai-debugger/services/example_service.py", line 23, in simulate_divide_by_zero_error     raise RuntimeError("A division by zero error occurred.") from e RuntimeError: A division by zero error occurred. 
2025-04-22 12:29:51,500 - ERROR - Unhandled exception: Traceback (most recent call last):   File "/Users/nagabhaskar.alaparthi/hackweek-ai-debugger/services/example_service.py", line 21, in simulate_divide_by_zero_error     result = 1 / 0              ~~^~~ ZeroDivisionError: division by zero  The above exception was the direct cause of the following exception:  Traceback (most recent call last):   File "/Users/nagabhaskar.alaparthi/hackweek-ai-debugger/venv/lib/python3.13/site-packages/starlette/middleware/errors.py", line 165, in __call__     await self.app(scope, receive, _send)   File "/Users/nagabhaskar.alaparthi/hackweek-ai-debugger/venv/lib/python3.13/site-packages/starlette/middleware/exceptions.py", line 62, in __call__     await wrap_app_handling_exceptions(self.app, conn)(scope, receive, send)   File "/Users/nagabhaskar.alaparthi/hackweek-ai-debugger/venv/lib/python3.13/site-packages/starlette/_exception_handler.py", line 53, in wrapped_app     raise exc   File "/Users/nagabhaskar.alaparthi/hackweek-ai-debugger/venv/lib/python3.13/site-packages/starlette/_exception_handler.py", line 42, in wrapped_app     await app(scope, receive, sender)   File "/Users/nagabhaskar.alaparthi/hackweek-ai-debugger/venv/lib/python3.13/site-packages/starlette/routing.py", line 714, in __call__     await self.middleware_stack(scope, receive, send)   File "/Users/nagabhaskar.alaparthi/hackweek-ai-debugger/venv/lib/python3.13/site-packages/starlette/routing.py", line 734, in app     await route.handle(scope, receive, send)   File "/Users/nagabhaskar.alaparthi/hackweek-ai-debugger/venv/lib/python3.13/site-packages/starlette/routing.py", line 288, in handle     await self.app(scope, receive, send)   File "/Users/nagabhaskar.alaparthi/hackweek-ai-debugger/venv/lib/python3.13/site-packages/starlette/routing.py", line 76, in app     await wrap_app_handling_exceptions(app, request)(scope, receive, send)   File "/Users/nagabhaskar.alaparthi/hackweek-ai-debugger/venv/lib/python3.13/site-packages/starlette/_exception_handler.py", line 53, in wrapped_app     raise exc   File "/Users/nagabhaskar.alaparthi/hackweek-ai-debugger/venv/lib/python3.13/site-packages/starlette/_exception_handler.py", line 42, in wrapped_app     await app(scope, receive, sender)   File "/Users/nagabhaskar.alaparthi/hackweek-ai-debugger/venv/lib/python3.13/site-packages/starlette/routing.py", line 73, in app     response = await f(request)                ^^^^^^^^^^^^^^^^   File "/Users/nagabhaskar.alaparthi/hackweek-ai-debugger/venv/lib/python3.13/site-packages/fastapi/routing.py", line 301, in app     raw_response = await run_endpoint_function(                    ^^^^^^^^^^^^^^^^^^^^^^^^^^^^     ...<3 lines>...     )     ^   File "/Users/nagabhaskar.alaparthi/hackweek-ai-debugger/venv/lib/python3.13/site-packages/fastapi/routing.py", line 214, in run_endpoint_function     return await run_in_threadpool(dependant.call, **values)            ^^^^^^^^^^^^^^^^^^^^^^^^^^^^^^^^^^^^^^^^^^^^^^^^^   File "/Users/nagabhaskar.alaparthi/hackweek-ai-debugger/venv/lib/python3.13/site-packages/starlette/concurrency.py", line 37, in run_in_threadpool     return await anyio.to_thread.run_sync(func)            ^^^^^^^^^^^^^^^^^^^^^^^^^^^^^^^^^^^^   File "/Users/nagabhaskar.alaparthi/hackweek-ai-debugger/venv/lib/python3.13/site-packages/anyio/to_thread.py", line 56, in run_sync     return await get_async_backend().run_sync_in_worker_thread(            ^^^^^^^^^^^^^^^^^^^^^^^^^^^^^^^^^^^^^^^^^^^^^^^^^^^^         func, args, abandon_on_cancel=abandon_on_cancel, limiter=limiter         ^^^^^^^^^^^^^^^^^^^^^^^^^^^^^^^^^^^^^^^^^^^^^^^^^^^^^^^^^^^^^^^^     )     ^   File "/Users/nagabhaskar.alaparthi/hackweek-ai-debugger/venv/lib/python3.13/site-packages/anyio/_backends/_asyncio.py", line 2470, in run_sync_in_worker_thread     return await future            ^^^^^^^^^^^^   File "/Users/nagabhaskar.alaparthi/hackweek-ai-debugger/venv/lib/python3.13/site-packages/anyio/_backends/_asyncio.py", line 967, in run     result = context.run(func, *args)   File "/Users/nagabhaskar.alaparthi/hackweek-ai-debugger/routers/example_router.py", line 20, in trigger_divide_by_zero_error     return ExampleService.simulate_divide_by_zero_error()            ~~~~~~~~~~~~~~~~~~~~~~~~~~~~~~~~~~~~~~~~~~~~^^   File "/Users/nagabhaskar.alaparthi/hackweek-ai-debugger/services/example_service.py", line 23, in simulate_divide_by_zero_error     raise RuntimeError("A division by zero error occurred.") from e RuntimeError: A division by zero error occurred. 
2025-04-22 12:30:21,958 - ERROR - Unhandled exception: Traceback (most recent call last):   File "/Users/nagabhaskar.alaparthi/hackweek-ai-debugger/services/example_service.py", line 21, in simulate_divide_by_zero_error     result = 1 / 0              ~~^~~ ZeroDivisionError: division by zero  The above exception was the direct cause of the following exception:  Traceback (most recent call last):   File "/Users/nagabhaskar.alaparthi/hackweek-ai-debugger/venv/lib/python3.13/site-packages/starlette/middleware/errors.py", line 165, in __call__     await self.app(scope, receive, _send)   File "/Users/nagabhaskar.alaparthi/hackweek-ai-debugger/venv/lib/python3.13/site-packages/starlette/middleware/exceptions.py", line 62, in __call__     await wrap_app_handling_exceptions(self.app, conn)(scope, receive, send)   File "/Users/nagabhaskar.alaparthi/hackweek-ai-debugger/venv/lib/python3.13/site-packages/starlette/_exception_handler.py", line 53, in wrapped_app     raise exc   File "/Users/nagabhaskar.alaparthi/hackweek-ai-debugger/venv/lib/python3.13/site-packages/starlette/_exception_handler.py", line 42, in wrapped_app     await app(scope, receive, sender)   File "/Users/nagabhaskar.alaparthi/hackweek-ai-debugger/venv/lib/python3.13/site-packages/starlette/routing.py", line 714, in __call__     await self.middleware_stack(scope, receive, send)   File "/Users/nagabhaskar.alaparthi/hackweek-ai-debugger/venv/lib/python3.13/site-packages/starlette/routing.py", line 734, in app     await route.handle(scope, receive, send)   File "/Users/nagabhaskar.alaparthi/hackweek-ai-debugger/venv/lib/python3.13/site-packages/starlette/routing.py", line 288, in handle     await self.app(scope, receive, send)   File "/Users/nagabhaskar.alaparthi/hackweek-ai-debugger/venv/lib/python3.13/site-packages/starlette/routing.py", line 76, in app     await wrap_app_handling_exceptions(app, request)(scope, receive, send)   File "/Users/nagabhaskar.alaparthi/hackweek-ai-debugger/venv/lib/python3.13/site-packages/starlette/_exception_handler.py", line 53, in wrapped_app     raise exc   File "/Users/nagabhaskar.alaparthi/hackweek-ai-debugger/venv/lib/python3.13/site-packages/starlette/_exception_handler.py", line 42, in wrapped_app     await app(scope, receive, sender)   File "/Users/nagabhaskar.alaparthi/hackweek-ai-debugger/venv/lib/python3.13/site-packages/starlette/routing.py", line 73, in app     response = await f(request)                ^^^^^^^^^^^^^^^^   File "/Users/nagabhaskar.alaparthi/hackweek-ai-debugger/venv/lib/python3.13/site-packages/fastapi/routing.py", line 301, in app     raw_response = await run_endpoint_function(                    ^^^^^^^^^^^^^^^^^^^^^^^^^^^^     ...<3 lines>...     )     ^   File "/Users/nagabhaskar.alaparthi/hackweek-ai-debugger/venv/lib/python3.13/site-packages/fastapi/routing.py", line 214, in run_endpoint_function     return await run_in_threadpool(dependant.call, **values)            ^^^^^^^^^^^^^^^^^^^^^^^^^^^^^^^^^^^^^^^^^^^^^^^^^   File "/Users/nagabhaskar.alaparthi/hackweek-ai-debugger/venv/lib/python3.13/site-packages/starlette/concurrency.py", line 37, in run_in_threadpool     return await anyio.to_thread.run_sync(func)            ^^^^^^^^^^^^^^^^^^^^^^^^^^^^^^^^^^^^   File "/Users/nagabhaskar.alaparthi/hackweek-ai-debugger/venv/lib/python3.13/site-packages/anyio/to_thread.py", line 56, in run_sync     return await get_async_backend().run_sync_in_worker_thread(            ^^^^^^^^^^^^^^^^^^^^^^^^^^^^^^^^^^^^^^^^^^^^^^^^^^^^         func, args, abandon_on_cancel=abandon_on_cancel, limiter=limiter         ^^^^^^^^^^^^^^^^^^^^^^^^^^^^^^^^^^^^^^^^^^^^^^^^^^^^^^^^^^^^^^^^     )     ^   File "/Users/nagabhaskar.alaparthi/hackweek-ai-debugger/venv/lib/python3.13/site-packages/anyio/_backends/_asyncio.py", line 2470, in run_sync_in_worker_thread     return await future            ^^^^^^^^^^^^   File "/Users/nagabhaskar.alaparthi/hackweek-ai-debugger/venv/lib/python3.13/site-packages/anyio/_backends/_asyncio.py", line 967, in run     result = context.run(func, *args)   File "/Users/nagabhaskar.alaparthi/hackweek-ai-debugger/routers/example_router.py", line 20, in trigger_divide_by_zero_error     return ExampleService.simulate_divide_by_zero_error()            ~~~~~~~~~~~~~~~~~~~~~~~~~~~~~~~~~~~~~~~~~~~~^^   File "/Users/nagabhaskar.alaparthi/hackweek-ai-debugger/services/example_service.py", line 23, in simulate_divide_by_zero_error     raise RuntimeError("A division by zero error occurred.") from e RuntimeError: A division by zero error occurred. 
2025-04-22 12:31:33,593 - ERROR - Unhandled exception: Traceback (most recent call last):   File "/Users/nagabhaskar.alaparthi/hackweek-ai-debugger/services/example_service.py", line 21, in simulate_divide_by_zero_error     result = 1 / 0              ~~^~~ ZeroDivisionError: division by zero  The above exception was the direct cause of the following exception:  Traceback (most recent call last):   File "/Users/nagabhaskar.alaparthi/hackweek-ai-debugger/venv/lib/python3.13/site-packages/starlette/middleware/errors.py", line 165, in __call__     await self.app(scope, receive, _send)   File "/Users/nagabhaskar.alaparthi/hackweek-ai-debugger/venv/lib/python3.13/site-packages/starlette/middleware/exceptions.py", line 62, in __call__     await wrap_app_handling_exceptions(self.app, conn)(scope, receive, send)   File "/Users/nagabhaskar.alaparthi/hackweek-ai-debugger/venv/lib/python3.13/site-packages/starlette/_exception_handler.py", line 53, in wrapped_app     raise exc   File "/Users/nagabhaskar.alaparthi/hackweek-ai-debugger/venv/lib/python3.13/site-packages/starlette/_exception_handler.py", line 42, in wrapped_app     await app(scope, receive, sender)   File "/Users/nagabhaskar.alaparthi/hackweek-ai-debugger/venv/lib/python3.13/site-packages/starlette/routing.py", line 714, in __call__     await self.middleware_stack(scope, receive, send)   File "/Users/nagabhaskar.alaparthi/hackweek-ai-debugger/venv/lib/python3.13/site-packages/starlette/routing.py", line 734, in app     await route.handle(scope, receive, send)   File "/Users/nagabhaskar.alaparthi/hackweek-ai-debugger/venv/lib/python3.13/site-packages/starlette/routing.py", line 288, in handle     await self.app(scope, receive, send)   File "/Users/nagabhaskar.alaparthi/hackweek-ai-debugger/venv/lib/python3.13/site-packages/starlette/routing.py", line 76, in app     await wrap_app_handling_exceptions(app, request)(scope, receive, send)   File "/Users/nagabhaskar.alaparthi/hackweek-ai-debugger/venv/lib/python3.13/site-packages/starlette/_exception_handler.py", line 53, in wrapped_app     raise exc   File "/Users/nagabhaskar.alaparthi/hackweek-ai-debugger/venv/lib/python3.13/site-packages/starlette/_exception_handler.py", line 42, in wrapped_app     await app(scope, receive, sender)   File "/Users/nagabhaskar.alaparthi/hackweek-ai-debugger/venv/lib/python3.13/site-packages/starlette/routing.py", line 73, in app     response = await f(request)                ^^^^^^^^^^^^^^^^   File "/Users/nagabhaskar.alaparthi/hackweek-ai-debugger/venv/lib/python3.13/site-packages/fastapi/routing.py", line 301, in app     raw_response = await run_endpoint_function(                    ^^^^^^^^^^^^^^^^^^^^^^^^^^^^     ...<3 lines>...     )     ^   File "/Users/nagabhaskar.alaparthi/hackweek-ai-debugger/venv/lib/python3.13/site-packages/fastapi/routing.py", line 214, in run_endpoint_function     return await run_in_threadpool(dependant.call, **values)            ^^^^^^^^^^^^^^^^^^^^^^^^^^^^^^^^^^^^^^^^^^^^^^^^^   File "/Users/nagabhaskar.alaparthi/hackweek-ai-debugger/venv/lib/python3.13/site-packages/starlette/concurrency.py", line 37, in run_in_threadpool     return await anyio.to_thread.run_sync(func)            ^^^^^^^^^^^^^^^^^^^^^^^^^^^^^^^^^^^^   File "/Users/nagabhaskar.alaparthi/hackweek-ai-debugger/venv/lib/python3.13/site-packages/anyio/to_thread.py", line 56, in run_sync     return await get_async_backend().run_sync_in_worker_thread(            ^^^^^^^^^^^^^^^^^^^^^^^^^^^^^^^^^^^^^^^^^^^^^^^^^^^^         func, args, abandon_on_cancel=abandon_on_cancel, limiter=limiter         ^^^^^^^^^^^^^^^^^^^^^^^^^^^^^^^^^^^^^^^^^^^^^^^^^^^^^^^^^^^^^^^^     )     ^   File "/Users/nagabhaskar.alaparthi/hackweek-ai-debugger/venv/lib/python3.13/site-packages/anyio/_backends/_asyncio.py", line 2470, in run_sync_in_worker_thread     return await future            ^^^^^^^^^^^^   File "/Users/nagabhaskar.alaparthi/hackweek-ai-debugger/venv/lib/python3.13/site-packages/anyio/_backends/_asyncio.py", line 967, in run     result = context.run(func, *args)   File "/Users/nagabhaskar.alaparthi/hackweek-ai-debugger/routers/example_router.py", line 20, in trigger_divide_by_zero_error     return ExampleService.simulate_divide_by_zero_error()            ~~~~~~~~~~~~~~~~~~~~~~~~~~~~~~~~~~~~~~~~~~~~^^   File "/Users/nagabhaskar.alaparthi/hackweek-ai-debugger/services/example_service.py", line 23, in simulate_divide_by_zero_error     raise RuntimeError("A division by zero error occurred.") from e RuntimeError: A division by zero error occurred. 
2025-04-22 12:32:31,633 - ERROR - Unhandled exception: Traceback (most recent call last):   File "/Users/nagabhaskar.alaparthi/hackweek-ai-debugger/services/example_service.py", line 21, in simulate_divide_by_zero_error     result = 1 / 0              ~~^~~ ZeroDivisionError: division by zero  The above exception was the direct cause of the following exception:  Traceback (most recent call last):   File "/Users/nagabhaskar.alaparthi/hackweek-ai-debugger/venv/lib/python3.13/site-packages/starlette/middleware/errors.py", line 165, in __call__     await self.app(scope, receive, _send)   File "/Users/nagabhaskar.alaparthi/hackweek-ai-debugger/venv/lib/python3.13/site-packages/starlette/middleware/exceptions.py", line 62, in __call__     await wrap_app_handling_exceptions(self.app, conn)(scope, receive, send)   File "/Users/nagabhaskar.alaparthi/hackweek-ai-debugger/venv/lib/python3.13/site-packages/starlette/_exception_handler.py", line 53, in wrapped_app     raise exc   File "/Users/nagabhaskar.alaparthi/hackweek-ai-debugger/venv/lib/python3.13/site-packages/starlette/_exception_handler.py", line 42, in wrapped_app     await app(scope, receive, sender)   File "/Users/nagabhaskar.alaparthi/hackweek-ai-debugger/venv/lib/python3.13/site-packages/starlette/routing.py", line 714, in __call__     await self.middleware_stack(scope, receive, send)   File "/Users/nagabhaskar.alaparthi/hackweek-ai-debugger/venv/lib/python3.13/site-packages/starlette/routing.py", line 734, in app     await route.handle(scope, receive, send)   File "/Users/nagabhaskar.alaparthi/hackweek-ai-debugger/venv/lib/python3.13/site-packages/starlette/routing.py", line 288, in handle     await self.app(scope, receive, send)   File "/Users/nagabhaskar.alaparthi/hackweek-ai-debugger/venv/lib/python3.13/site-packages/starlette/routing.py", line 76, in app     await wrap_app_handling_exceptions(app, request)(scope, receive, send)   File "/Users/nagabhaskar.alaparthi/hackweek-ai-debugger/venv/lib/python3.13/site-packages/starlette/_exception_handler.py", line 53, in wrapped_app     raise exc   File "/Users/nagabhaskar.alaparthi/hackweek-ai-debugger/venv/lib/python3.13/site-packages/starlette/_exception_handler.py", line 42, in wrapped_app     await app(scope, receive, sender)   File "/Users/nagabhaskar.alaparthi/hackweek-ai-debugger/venv/lib/python3.13/site-packages/starlette/routing.py", line 73, in app     response = await f(request)                ^^^^^^^^^^^^^^^^   File "/Users/nagabhaskar.alaparthi/hackweek-ai-debugger/venv/lib/python3.13/site-packages/fastapi/routing.py", line 301, in app     raw_response = await run_endpoint_function(                    ^^^^^^^^^^^^^^^^^^^^^^^^^^^^     ...<3 lines>...     )     ^   File "/Users/nagabhaskar.alaparthi/hackweek-ai-debugger/venv/lib/python3.13/site-packages/fastapi/routing.py", line 214, in run_endpoint_function     return await run_in_threadpool(dependant.call, **values)            ^^^^^^^^^^^^^^^^^^^^^^^^^^^^^^^^^^^^^^^^^^^^^^^^^   File "/Users/nagabhaskar.alaparthi/hackweek-ai-debugger/venv/lib/python3.13/site-packages/starlette/concurrency.py", line 37, in run_in_threadpool     return await anyio.to_thread.run_sync(func)            ^^^^^^^^^^^^^^^^^^^^^^^^^^^^^^^^^^^^   File "/Users/nagabhaskar.alaparthi/hackweek-ai-debugger/venv/lib/python3.13/site-packages/anyio/to_thread.py", line 56, in run_sync     return await get_async_backend().run_sync_in_worker_thread(            ^^^^^^^^^^^^^^^^^^^^^^^^^^^^^^^^^^^^^^^^^^^^^^^^^^^^         func, args, abandon_on_cancel=abandon_on_cancel, limiter=limiter         ^^^^^^^^^^^^^^^^^^^^^^^^^^^^^^^^^^^^^^^^^^^^^^^^^^^^^^^^^^^^^^^^     )     ^   File "/Users/nagabhaskar.alaparthi/hackweek-ai-debugger/venv/lib/python3.13/site-packages/anyio/_backends/_asyncio.py", line 2470, in run_sync_in_worker_thread     return await future            ^^^^^^^^^^^^   File "/Users/nagabhaskar.alaparthi/hackweek-ai-debugger/venv/lib/python3.13/site-packages/anyio/_backends/_asyncio.py", line 967, in run     result = context.run(func, *args)   File "/Users/nagabhaskar.alaparthi/hackweek-ai-debugger/routers/example_router.py", line 20, in trigger_divide_by_zero_error     return ExampleService.simulate_divide_by_zero_error()            ~~~~~~~~~~~~~~~~~~~~~~~~~~~~~~~~~~~~~~~~~~~~^^   File "/Users/nagabhaskar.alaparthi/hackweek-ai-debugger/services/example_service.py", line 23, in simulate_divide_by_zero_error     raise RuntimeError("A division by zero error occurred.") from e RuntimeError: A division by zero error occurred. 
2025-04-22 12:35:12,303 - ERROR - Unhandled exception: Traceback (most recent call last):   File "/Users/nagabhaskar.alaparthi/hackweek-ai-debugger/services/example_service.py", line 21, in simulate_divide_by_zero_error     result = 1 / 0              ~~^~~ ZeroDivisionError: division by zero  The above exception was the direct cause of the following exception:  Traceback (most recent call last):   File "/Users/nagabhaskar.alaparthi/hackweek-ai-debugger/venv/lib/python3.13/site-packages/starlette/middleware/errors.py", line 165, in __call__     await self.app(scope, receive, _send)   File "/Users/nagabhaskar.alaparthi/hackweek-ai-debugger/venv/lib/python3.13/site-packages/starlette/middleware/exceptions.py", line 62, in __call__     await wrap_app_handling_exceptions(self.app, conn)(scope, receive, send)   File "/Users/nagabhaskar.alaparthi/hackweek-ai-debugger/venv/lib/python3.13/site-packages/starlette/_exception_handler.py", line 53, in wrapped_app     raise exc   File "/Users/nagabhaskar.alaparthi/hackweek-ai-debugger/venv/lib/python3.13/site-packages/starlette/_exception_handler.py", line 42, in wrapped_app     await app(scope, receive, sender)   File "/Users/nagabhaskar.alaparthi/hackweek-ai-debugger/venv/lib/python3.13/site-packages/starlette/routing.py", line 714, in __call__     await self.middleware_stack(scope, receive, send)   File "/Users/nagabhaskar.alaparthi/hackweek-ai-debugger/venv/lib/python3.13/site-packages/starlette/routing.py", line 734, in app     await route.handle(scope, receive, send)   File "/Users/nagabhaskar.alaparthi/hackweek-ai-debugger/venv/lib/python3.13/site-packages/starlette/routing.py", line 288, in handle     await self.app(scope, receive, send)   File "/Users/nagabhaskar.alaparthi/hackweek-ai-debugger/venv/lib/python3.13/site-packages/starlette/routing.py", line 76, in app     await wrap_app_handling_exceptions(app, request)(scope, receive, send)   File "/Users/nagabhaskar.alaparthi/hackweek-ai-debugger/venv/lib/python3.13/site-packages/starlette/_exception_handler.py", line 53, in wrapped_app     raise exc   File "/Users/nagabhaskar.alaparthi/hackweek-ai-debugger/venv/lib/python3.13/site-packages/starlette/_exception_handler.py", line 42, in wrapped_app     await app(scope, receive, sender)   File "/Users/nagabhaskar.alaparthi/hackweek-ai-debugger/venv/lib/python3.13/site-packages/starlette/routing.py", line 73, in app     response = await f(request)                ^^^^^^^^^^^^^^^^   File "/Users/nagabhaskar.alaparthi/hackweek-ai-debugger/venv/lib/python3.13/site-packages/fastapi/routing.py", line 301, in app     raw_response = await run_endpoint_function(                    ^^^^^^^^^^^^^^^^^^^^^^^^^^^^     ...<3 lines>...     )     ^   File "/Users/nagabhaskar.alaparthi/hackweek-ai-debugger/venv/lib/python3.13/site-packages/fastapi/routing.py", line 214, in run_endpoint_function     return await run_in_threadpool(dependant.call, **values)            ^^^^^^^^^^^^^^^^^^^^^^^^^^^^^^^^^^^^^^^^^^^^^^^^^   File "/Users/nagabhaskar.alaparthi/hackweek-ai-debugger/venv/lib/python3.13/site-packages/starlette/concurrency.py", line 37, in run_in_threadpool     return await anyio.to_thread.run_sync(func)            ^^^^^^^^^^^^^^^^^^^^^^^^^^^^^^^^^^^^   File "/Users/nagabhaskar.alaparthi/hackweek-ai-debugger/venv/lib/python3.13/site-packages/anyio/to_thread.py", line 56, in run_sync     return await get_async_backend().run_sync_in_worker_thread(            ^^^^^^^^^^^^^^^^^^^^^^^^^^^^^^^^^^^^^^^^^^^^^^^^^^^^         func, args, abandon_on_cancel=abandon_on_cancel, limiter=limiter         ^^^^^^^^^^^^^^^^^^^^^^^^^^^^^^^^^^^^^^^^^^^^^^^^^^^^^^^^^^^^^^^^     )     ^   File "/Users/nagabhaskar.alaparthi/hackweek-ai-debugger/venv/lib/python3.13/site-packages/anyio/_backends/_asyncio.py", line 2470, in run_sync_in_worker_thread     return await future            ^^^^^^^^^^^^   File "/Users/nagabhaskar.alaparthi/hackweek-ai-debugger/venv/lib/python3.13/site-packages/anyio/_backends/_asyncio.py", line 967, in run     result = context.run(func, *args)   File "/Users/nagabhaskar.alaparthi/hackweek-ai-debugger/routers/example_router.py", line 20, in trigger_divide_by_zero_error     return ExampleService.simulate_divide_by_zero_error()            ~~~~~~~~~~~~~~~~~~~~~~~~~~~~~~~~~~~~~~~~~~~~^^   File "/Users/nagabhaskar.alaparthi/hackweek-ai-debugger/services/example_service.py", line 23, in simulate_divide_by_zero_error     raise RuntimeError("A division by zero error occurred.") from e RuntimeError: A division by zero error occurred. 
2025-04-22 12:36:20,890 - ERROR - Unhandled exception: Traceback (most recent call last):   File "/Users/nagabhaskar.alaparthi/hackweek-ai-debugger/services/example_service.py", line 21, in simulate_divide_by_zero_error     result = 1 / 0              ~~^~~ ZeroDivisionError: division by zero  The above exception was the direct cause of the following exception:  Traceback (most recent call last):   File "/Users/nagabhaskar.alaparthi/hackweek-ai-debugger/venv/lib/python3.13/site-packages/starlette/middleware/errors.py", line 165, in __call__     await self.app(scope, receive, _send)   File "/Users/nagabhaskar.alaparthi/hackweek-ai-debugger/venv/lib/python3.13/site-packages/starlette/middleware/exceptions.py", line 62, in __call__     await wrap_app_handling_exceptions(self.app, conn)(scope, receive, send)   File "/Users/nagabhaskar.alaparthi/hackweek-ai-debugger/venv/lib/python3.13/site-packages/starlette/_exception_handler.py", line 53, in wrapped_app     raise exc   File "/Users/nagabhaskar.alaparthi/hackweek-ai-debugger/venv/lib/python3.13/site-packages/starlette/_exception_handler.py", line 42, in wrapped_app     await app(scope, receive, sender)   File "/Users/nagabhaskar.alaparthi/hackweek-ai-debugger/venv/lib/python3.13/site-packages/starlette/routing.py", line 714, in __call__     await self.middleware_stack(scope, receive, send)   File "/Users/nagabhaskar.alaparthi/hackweek-ai-debugger/venv/lib/python3.13/site-packages/starlette/routing.py", line 734, in app     await route.handle(scope, receive, send)   File "/Users/nagabhaskar.alaparthi/hackweek-ai-debugger/venv/lib/python3.13/site-packages/starlette/routing.py", line 288, in handle     await self.app(scope, receive, send)   File "/Users/nagabhaskar.alaparthi/hackweek-ai-debugger/venv/lib/python3.13/site-packages/starlette/routing.py", line 76, in app     await wrap_app_handling_exceptions(app, request)(scope, receive, send)   File "/Users/nagabhaskar.alaparthi/hackweek-ai-debugger/venv/lib/python3.13/site-packages/starlette/_exception_handler.py", line 53, in wrapped_app     raise exc   File "/Users/nagabhaskar.alaparthi/hackweek-ai-debugger/venv/lib/python3.13/site-packages/starlette/_exception_handler.py", line 42, in wrapped_app     await app(scope, receive, sender)   File "/Users/nagabhaskar.alaparthi/hackweek-ai-debugger/venv/lib/python3.13/site-packages/starlette/routing.py", line 73, in app     response = await f(request)                ^^^^^^^^^^^^^^^^   File "/Users/nagabhaskar.alaparthi/hackweek-ai-debugger/venv/lib/python3.13/site-packages/fastapi/routing.py", line 301, in app     raw_response = await run_endpoint_function(                    ^^^^^^^^^^^^^^^^^^^^^^^^^^^^     ...<3 lines>...     )     ^   File "/Users/nagabhaskar.alaparthi/hackweek-ai-debugger/venv/lib/python3.13/site-packages/fastapi/routing.py", line 214, in run_endpoint_function     return await run_in_threadpool(dependant.call, **values)            ^^^^^^^^^^^^^^^^^^^^^^^^^^^^^^^^^^^^^^^^^^^^^^^^^   File "/Users/nagabhaskar.alaparthi/hackweek-ai-debugger/venv/lib/python3.13/site-packages/starlette/concurrency.py", line 37, in run_in_threadpool     return await anyio.to_thread.run_sync(func)            ^^^^^^^^^^^^^^^^^^^^^^^^^^^^^^^^^^^^   File "/Users/nagabhaskar.alaparthi/hackweek-ai-debugger/venv/lib/python3.13/site-packages/anyio/to_thread.py", line 56, in run_sync     return await get_async_backend().run_sync_in_worker_thread(            ^^^^^^^^^^^^^^^^^^^^^^^^^^^^^^^^^^^^^^^^^^^^^^^^^^^^         func, args, abandon_on_cancel=abandon_on_cancel, limiter=limiter         ^^^^^^^^^^^^^^^^^^^^^^^^^^^^^^^^^^^^^^^^^^^^^^^^^^^^^^^^^^^^^^^^     )     ^   File "/Users/nagabhaskar.alaparthi/hackweek-ai-debugger/venv/lib/python3.13/site-packages/anyio/_backends/_asyncio.py", line 2470, in run_sync_in_worker_thread     return await future            ^^^^^^^^^^^^   File "/Users/nagabhaskar.alaparthi/hackweek-ai-debugger/venv/lib/python3.13/site-packages/anyio/_backends/_asyncio.py", line 967, in run     result = context.run(func, *args)   File "/Users/nagabhaskar.alaparthi/hackweek-ai-debugger/routers/example_router.py", line 20, in trigger_divide_by_zero_error     return ExampleService.simulate_divide_by_zero_error()            ~~~~~~~~~~~~~~~~~~~~~~~~~~~~~~~~~~~~~~~~~~~~^^   File "/Users/nagabhaskar.alaparthi/hackweek-ai-debugger/services/example_service.py", line 23, in simulate_divide_by_zero_error     raise RuntimeError("A division by zero error occurred.") from e RuntimeError: A division by zero error occurred. 
2025-04-22 12:40:12,546 - ERROR - Unhandled exception: Traceback (most recent call last):   File "/Users/nagabhaskar.alaparthi/hackweek-ai-debugger/services/example_service.py", line 21, in simulate_divide_by_zero_error     result = 1 / 0              ~~^~~ ZeroDivisionError: division by zero  The above exception was the direct cause of the following exception:  Traceback (most recent call last):   File "/Users/nagabhaskar.alaparthi/hackweek-ai-debugger/venv/lib/python3.13/site-packages/starlette/middleware/errors.py", line 165, in __call__     await self.app(scope, receive, _send)   File "/Users/nagabhaskar.alaparthi/hackweek-ai-debugger/venv/lib/python3.13/site-packages/starlette/middleware/exceptions.py", line 62, in __call__     await wrap_app_handling_exceptions(self.app, conn)(scope, receive, send)   File "/Users/nagabhaskar.alaparthi/hackweek-ai-debugger/venv/lib/python3.13/site-packages/starlette/_exception_handler.py", line 53, in wrapped_app     raise exc   File "/Users/nagabhaskar.alaparthi/hackweek-ai-debugger/venv/lib/python3.13/site-packages/starlette/_exception_handler.py", line 42, in wrapped_app     await app(scope, receive, sender)   File "/Users/nagabhaskar.alaparthi/hackweek-ai-debugger/venv/lib/python3.13/site-packages/starlette/routing.py", line 714, in __call__     await self.middleware_stack(scope, receive, send)   File "/Users/nagabhaskar.alaparthi/hackweek-ai-debugger/venv/lib/python3.13/site-packages/starlette/routing.py", line 734, in app     await route.handle(scope, receive, send)   File "/Users/nagabhaskar.alaparthi/hackweek-ai-debugger/venv/lib/python3.13/site-packages/starlette/routing.py", line 288, in handle     await self.app(scope, receive, send)   File "/Users/nagabhaskar.alaparthi/hackweek-ai-debugger/venv/lib/python3.13/site-packages/starlette/routing.py", line 76, in app     await wrap_app_handling_exceptions(app, request)(scope, receive, send)   File "/Users/nagabhaskar.alaparthi/hackweek-ai-debugger/venv/lib/python3.13/site-packages/starlette/_exception_handler.py", line 53, in wrapped_app     raise exc   File "/Users/nagabhaskar.alaparthi/hackweek-ai-debugger/venv/lib/python3.13/site-packages/starlette/_exception_handler.py", line 42, in wrapped_app     await app(scope, receive, sender)   File "/Users/nagabhaskar.alaparthi/hackweek-ai-debugger/venv/lib/python3.13/site-packages/starlette/routing.py", line 73, in app     response = await f(request)                ^^^^^^^^^^^^^^^^   File "/Users/nagabhaskar.alaparthi/hackweek-ai-debugger/venv/lib/python3.13/site-packages/fastapi/routing.py", line 301, in app     raw_response = await run_endpoint_function(                    ^^^^^^^^^^^^^^^^^^^^^^^^^^^^     ...<3 lines>...     )     ^   File "/Users/nagabhaskar.alaparthi/hackweek-ai-debugger/venv/lib/python3.13/site-packages/fastapi/routing.py", line 214, in run_endpoint_function     return await run_in_threadpool(dependant.call, **values)            ^^^^^^^^^^^^^^^^^^^^^^^^^^^^^^^^^^^^^^^^^^^^^^^^^   File "/Users/nagabhaskar.alaparthi/hackweek-ai-debugger/venv/lib/python3.13/site-packages/starlette/concurrency.py", line 37, in run_in_threadpool     return await anyio.to_thread.run_sync(func)            ^^^^^^^^^^^^^^^^^^^^^^^^^^^^^^^^^^^^   File "/Users/nagabhaskar.alaparthi/hackweek-ai-debugger/venv/lib/python3.13/site-packages/anyio/to_thread.py", line 56, in run_sync     return await get_async_backend().run_sync_in_worker_thread(            ^^^^^^^^^^^^^^^^^^^^^^^^^^^^^^^^^^^^^^^^^^^^^^^^^^^^         func, args, abandon_on_cancel=abandon_on_cancel, limiter=limiter         ^^^^^^^^^^^^^^^^^^^^^^^^^^^^^^^^^^^^^^^^^^^^^^^^^^^^^^^^^^^^^^^^     )     ^   File "/Users/nagabhaskar.alaparthi/hackweek-ai-debugger/venv/lib/python3.13/site-packages/anyio/_backends/_asyncio.py", line 2470, in run_sync_in_worker_thread     return await future            ^^^^^^^^^^^^   File "/Users/nagabhaskar.alaparthi/hackweek-ai-debugger/venv/lib/python3.13/site-packages/anyio/_backends/_asyncio.py", line 967, in run     result = context.run(func, *args)   File "/Users/nagabhaskar.alaparthi/hackweek-ai-debugger/routers/example_router.py", line 20, in trigger_divide_by_zero_error     return ExampleService.simulate_divide_by_zero_error()            ~~~~~~~~~~~~~~~~~~~~~~~~~~~~~~~~~~~~~~~~~~~~^^   File "/Users/nagabhaskar.alaparthi/hackweek-ai-debugger/services/example_service.py", line 23, in simulate_divide_by_zero_error     raise RuntimeError("A division by zero error occurred.") from e RuntimeError: A division by zero error occurred. 
2025-04-22 13:52:05,486 - ERROR - Unhandled exception: Traceback (most recent call last):   File "/Users/nagabhaskar.alaparthi/hackweek-ai-debugger/services/example_service.py", line 21, in simulate_divide_by_zero_error     result = 1 / 0              ~~^~~ ZeroDivisionError: division by zero  The above exception was the direct cause of the following exception:  Traceback (most recent call last):   File "/Users/nagabhaskar.alaparthi/hackweek-ai-debugger/venv/lib/python3.13/site-packages/starlette/middleware/errors.py", line 165, in __call__     await self.app(scope, receive, _send)   File "/Users/nagabhaskar.alaparthi/hackweek-ai-debugger/venv/lib/python3.13/site-packages/starlette/middleware/exceptions.py", line 62, in __call__     await wrap_app_handling_exceptions(self.app, conn)(scope, receive, send)   File "/Users/nagabhaskar.alaparthi/hackweek-ai-debugger/venv/lib/python3.13/site-packages/starlette/_exception_handler.py", line 53, in wrapped_app     raise exc   File "/Users/nagabhaskar.alaparthi/hackweek-ai-debugger/venv/lib/python3.13/site-packages/starlette/_exception_handler.py", line 42, in wrapped_app     await app(scope, receive, sender)   File "/Users/nagabhaskar.alaparthi/hackweek-ai-debugger/venv/lib/python3.13/site-packages/starlette/routing.py", line 714, in __call__     await self.middleware_stack(scope, receive, send)   File "/Users/nagabhaskar.alaparthi/hackweek-ai-debugger/venv/lib/python3.13/site-packages/starlette/routing.py", line 734, in app     await route.handle(scope, receive, send)   File "/Users/nagabhaskar.alaparthi/hackweek-ai-debugger/venv/lib/python3.13/site-packages/starlette/routing.py", line 288, in handle     await self.app(scope, receive, send)   File "/Users/nagabhaskar.alaparthi/hackweek-ai-debugger/venv/lib/python3.13/site-packages/starlette/routing.py", line 76, in app     await wrap_app_handling_exceptions(app, request)(scope, receive, send)   File "/Users/nagabhaskar.alaparthi/hackweek-ai-debugger/venv/lib/python3.13/site-packages/starlette/_exception_handler.py", line 53, in wrapped_app     raise exc   File "/Users/nagabhaskar.alaparthi/hackweek-ai-debugger/venv/lib/python3.13/site-packages/starlette/_exception_handler.py", line 42, in wrapped_app     await app(scope, receive, sender)   File "/Users/nagabhaskar.alaparthi/hackweek-ai-debugger/venv/lib/python3.13/site-packages/starlette/routing.py", line 73, in app     response = await f(request)                ^^^^^^^^^^^^^^^^   File "/Users/nagabhaskar.alaparthi/hackweek-ai-debugger/venv/lib/python3.13/site-packages/fastapi/routing.py", line 301, in app     raw_response = await run_endpoint_function(                    ^^^^^^^^^^^^^^^^^^^^^^^^^^^^     ...<3 lines>...     )     ^   File "/Users/nagabhaskar.alaparthi/hackweek-ai-debugger/venv/lib/python3.13/site-packages/fastapi/routing.py", line 214, in run_endpoint_function     return await run_in_threadpool(dependant.call, **values)            ^^^^^^^^^^^^^^^^^^^^^^^^^^^^^^^^^^^^^^^^^^^^^^^^^   File "/Users/nagabhaskar.alaparthi/hackweek-ai-debugger/venv/lib/python3.13/site-packages/starlette/concurrency.py", line 37, in run_in_threadpool     return await anyio.to_thread.run_sync(func)            ^^^^^^^^^^^^^^^^^^^^^^^^^^^^^^^^^^^^   File "/Users/nagabhaskar.alaparthi/hackweek-ai-debugger/venv/lib/python3.13/site-packages/anyio/to_thread.py", line 56, in run_sync     return await get_async_backend().run_sync_in_worker_thread(            ^^^^^^^^^^^^^^^^^^^^^^^^^^^^^^^^^^^^^^^^^^^^^^^^^^^^         func, args, abandon_on_cancel=abandon_on_cancel, limiter=limiter         ^^^^^^^^^^^^^^^^^^^^^^^^^^^^^^^^^^^^^^^^^^^^^^^^^^^^^^^^^^^^^^^^     )     ^   File "/Users/nagabhaskar.alaparthi/hackweek-ai-debugger/venv/lib/python3.13/site-packages/anyio/_backends/_asyncio.py", line 2470, in run_sync_in_worker_thread     return await future            ^^^^^^^^^^^^   File "/Users/nagabhaskar.alaparthi/hackweek-ai-debugger/venv/lib/python3.13/site-packages/anyio/_backends/_asyncio.py", line 967, in run     result = context.run(func, *args)   File "/Users/nagabhaskar.alaparthi/hackweek-ai-debugger/routers/example_router.py", line 20, in trigger_divide_by_zero_error     return ExampleService.simulate_divide_by_zero_error()            ~~~~~~~~~~~~~~~~~~~~~~~~~~~~~~~~~~~~~~~~~~~~^^   File "/Users/nagabhaskar.alaparthi/hackweek-ai-debugger/services/example_service.py", line 23, in simulate_divide_by_zero_error     raise RuntimeError("A division by zero error occurred.") from e RuntimeError: A division by zero error occurred. 
2025-04-22 13:53:12,657 - ERROR - Unhandled exception: Traceback (most recent call last):   File "/Users/nagabhaskar.alaparthi/hackweek-ai-debugger/services/example_service.py", line 21, in simulate_divide_by_zero_error     result = 1 / 0              ~~^~~ ZeroDivisionError: division by zero  The above exception was the direct cause of the following exception:  Traceback (most recent call last):   File "/Users/nagabhaskar.alaparthi/hackweek-ai-debugger/venv/lib/python3.13/site-packages/starlette/middleware/errors.py", line 165, in __call__     await self.app(scope, receive, _send)   File "/Users/nagabhaskar.alaparthi/hackweek-ai-debugger/venv/lib/python3.13/site-packages/starlette/middleware/exceptions.py", line 62, in __call__     await wrap_app_handling_exceptions(self.app, conn)(scope, receive, send)   File "/Users/nagabhaskar.alaparthi/hackweek-ai-debugger/venv/lib/python3.13/site-packages/starlette/_exception_handler.py", line 53, in wrapped_app     raise exc   File "/Users/nagabhaskar.alaparthi/hackweek-ai-debugger/venv/lib/python3.13/site-packages/starlette/_exception_handler.py", line 42, in wrapped_app     await app(scope, receive, sender)   File "/Users/nagabhaskar.alaparthi/hackweek-ai-debugger/venv/lib/python3.13/site-packages/starlette/routing.py", line 714, in __call__     await self.middleware_stack(scope, receive, send)   File "/Users/nagabhaskar.alaparthi/hackweek-ai-debugger/venv/lib/python3.13/site-packages/starlette/routing.py", line 734, in app     await route.handle(scope, receive, send)   File "/Users/nagabhaskar.alaparthi/hackweek-ai-debugger/venv/lib/python3.13/site-packages/starlette/routing.py", line 288, in handle     await self.app(scope, receive, send)   File "/Users/nagabhaskar.alaparthi/hackweek-ai-debugger/venv/lib/python3.13/site-packages/starlette/routing.py", line 76, in app     await wrap_app_handling_exceptions(app, request)(scope, receive, send)   File "/Users/nagabhaskar.alaparthi/hackweek-ai-debugger/venv/lib/python3.13/site-packages/starlette/_exception_handler.py", line 53, in wrapped_app     raise exc   File "/Users/nagabhaskar.alaparthi/hackweek-ai-debugger/venv/lib/python3.13/site-packages/starlette/_exception_handler.py", line 42, in wrapped_app     await app(scope, receive, sender)   File "/Users/nagabhaskar.alaparthi/hackweek-ai-debugger/venv/lib/python3.13/site-packages/starlette/routing.py", line 73, in app     response = await f(request)                ^^^^^^^^^^^^^^^^   File "/Users/nagabhaskar.alaparthi/hackweek-ai-debugger/venv/lib/python3.13/site-packages/fastapi/routing.py", line 301, in app     raw_response = await run_endpoint_function(                    ^^^^^^^^^^^^^^^^^^^^^^^^^^^^     ...<3 lines>...     )     ^   File "/Users/nagabhaskar.alaparthi/hackweek-ai-debugger/venv/lib/python3.13/site-packages/fastapi/routing.py", line 214, in run_endpoint_function     return await run_in_threadpool(dependant.call, **values)            ^^^^^^^^^^^^^^^^^^^^^^^^^^^^^^^^^^^^^^^^^^^^^^^^^   File "/Users/nagabhaskar.alaparthi/hackweek-ai-debugger/venv/lib/python3.13/site-packages/starlette/concurrency.py", line 37, in run_in_threadpool     return await anyio.to_thread.run_sync(func)            ^^^^^^^^^^^^^^^^^^^^^^^^^^^^^^^^^^^^   File "/Users/nagabhaskar.alaparthi/hackweek-ai-debugger/venv/lib/python3.13/site-packages/anyio/to_thread.py", line 56, in run_sync     return await get_async_backend().run_sync_in_worker_thread(            ^^^^^^^^^^^^^^^^^^^^^^^^^^^^^^^^^^^^^^^^^^^^^^^^^^^^         func, args, abandon_on_cancel=abandon_on_cancel, limiter=limiter         ^^^^^^^^^^^^^^^^^^^^^^^^^^^^^^^^^^^^^^^^^^^^^^^^^^^^^^^^^^^^^^^^     )     ^   File "/Users/nagabhaskar.alaparthi/hackweek-ai-debugger/venv/lib/python3.13/site-packages/anyio/_backends/_asyncio.py", line 2470, in run_sync_in_worker_thread     return await future            ^^^^^^^^^^^^   File "/Users/nagabhaskar.alaparthi/hackweek-ai-debugger/venv/lib/python3.13/site-packages/anyio/_backends/_asyncio.py", line 967, in run     result = context.run(func, *args)   File "/Users/nagabhaskar.alaparthi/hackweek-ai-debugger/routers/example_router.py", line 20, in trigger_divide_by_zero_error     return ExampleService.simulate_divide_by_zero_error()            ~~~~~~~~~~~~~~~~~~~~~~~~~~~~~~~~~~~~~~~~~~~~^^   File "/Users/nagabhaskar.alaparthi/hackweek-ai-debugger/services/example_service.py", line 23, in simulate_divide_by_zero_error     raise RuntimeError("A division by zero error occurred.") from e RuntimeError: A division by zero error occurred. 
2025-04-22 13:53:31,742 - ERROR - Unhandled exception: Traceback (most recent call last):   File "/Users/nagabhaskar.alaparthi/hackweek-ai-debugger/services/example_service.py", line 21, in simulate_divide_by_zero_error     result = 1 / 0              ~~^~~ ZeroDivisionError: division by zero  The above exception was the direct cause of the following exception:  Traceback (most recent call last):   File "/Users/nagabhaskar.alaparthi/hackweek-ai-debugger/venv/lib/python3.13/site-packages/starlette/middleware/errors.py", line 165, in __call__     await self.app(scope, receive, _send)   File "/Users/nagabhaskar.alaparthi/hackweek-ai-debugger/venv/lib/python3.13/site-packages/starlette/middleware/exceptions.py", line 62, in __call__     await wrap_app_handling_exceptions(self.app, conn)(scope, receive, send)   File "/Users/nagabhaskar.alaparthi/hackweek-ai-debugger/venv/lib/python3.13/site-packages/starlette/_exception_handler.py", line 53, in wrapped_app     raise exc   File "/Users/nagabhaskar.alaparthi/hackweek-ai-debugger/venv/lib/python3.13/site-packages/starlette/_exception_handler.py", line 42, in wrapped_app     await app(scope, receive, sender)   File "/Users/nagabhaskar.alaparthi/hackweek-ai-debugger/venv/lib/python3.13/site-packages/starlette/routing.py", line 714, in __call__     await self.middleware_stack(scope, receive, send)   File "/Users/nagabhaskar.alaparthi/hackweek-ai-debugger/venv/lib/python3.13/site-packages/starlette/routing.py", line 734, in app     await route.handle(scope, receive, send)   File "/Users/nagabhaskar.alaparthi/hackweek-ai-debugger/venv/lib/python3.13/site-packages/starlette/routing.py", line 288, in handle     await self.app(scope, receive, send)   File "/Users/nagabhaskar.alaparthi/hackweek-ai-debugger/venv/lib/python3.13/site-packages/starlette/routing.py", line 76, in app     await wrap_app_handling_exceptions(app, request)(scope, receive, send)   File "/Users/nagabhaskar.alaparthi/hackweek-ai-debugger/venv/lib/python3.13/site-packages/starlette/_exception_handler.py", line 53, in wrapped_app     raise exc   File "/Users/nagabhaskar.alaparthi/hackweek-ai-debugger/venv/lib/python3.13/site-packages/starlette/_exception_handler.py", line 42, in wrapped_app     await app(scope, receive, sender)   File "/Users/nagabhaskar.alaparthi/hackweek-ai-debugger/venv/lib/python3.13/site-packages/starlette/routing.py", line 73, in app     response = await f(request)                ^^^^^^^^^^^^^^^^   File "/Users/nagabhaskar.alaparthi/hackweek-ai-debugger/venv/lib/python3.13/site-packages/fastapi/routing.py", line 301, in app     raw_response = await run_endpoint_function(                    ^^^^^^^^^^^^^^^^^^^^^^^^^^^^     ...<3 lines>...     )     ^   File "/Users/nagabhaskar.alaparthi/hackweek-ai-debugger/venv/lib/python3.13/site-packages/fastapi/routing.py", line 214, in run_endpoint_function     return await run_in_threadpool(dependant.call, **values)            ^^^^^^^^^^^^^^^^^^^^^^^^^^^^^^^^^^^^^^^^^^^^^^^^^   File "/Users/nagabhaskar.alaparthi/hackweek-ai-debugger/venv/lib/python3.13/site-packages/starlette/concurrency.py", line 37, in run_in_threadpool     return await anyio.to_thread.run_sync(func)            ^^^^^^^^^^^^^^^^^^^^^^^^^^^^^^^^^^^^   File "/Users/nagabhaskar.alaparthi/hackweek-ai-debugger/venv/lib/python3.13/site-packages/anyio/to_thread.py", line 56, in run_sync     return await get_async_backend().run_sync_in_worker_thread(            ^^^^^^^^^^^^^^^^^^^^^^^^^^^^^^^^^^^^^^^^^^^^^^^^^^^^         func, args, abandon_on_cancel=abandon_on_cancel, limiter=limiter         ^^^^^^^^^^^^^^^^^^^^^^^^^^^^^^^^^^^^^^^^^^^^^^^^^^^^^^^^^^^^^^^^     )     ^   File "/Users/nagabhaskar.alaparthi/hackweek-ai-debugger/venv/lib/python3.13/site-packages/anyio/_backends/_asyncio.py", line 2470, in run_sync_in_worker_thread     return await future            ^^^^^^^^^^^^   File "/Users/nagabhaskar.alaparthi/hackweek-ai-debugger/venv/lib/python3.13/site-packages/anyio/_backends/_asyncio.py", line 967, in run     result = context.run(func, *args)   File "/Users/nagabhaskar.alaparthi/hackweek-ai-debugger/routers/example_router.py", line 20, in trigger_divide_by_zero_error     return ExampleService.simulate_divide_by_zero_error()            ~~~~~~~~~~~~~~~~~~~~~~~~~~~~~~~~~~~~~~~~~~~~^^   File "/Users/nagabhaskar.alaparthi/hackweek-ai-debugger/services/example_service.py", line 23, in simulate_divide_by_zero_error     raise RuntimeError("A division by zero error occurred.") from e RuntimeError: A division by zero error occurred. 
2025-04-22 14:30:21,831 - ERROR - Unhandled exception: Traceback (most recent call last):   File "/Users/nagabhaskar.alaparthi/hackweek-ai-debugger/services/example_service.py", line 21, in simulate_divide_by_zero_error     result = 1 / 0              ~~^~~ ZeroDivisionError: division by zero  The above exception was the direct cause of the following exception:  Traceback (most recent call last):   File "/Users/nagabhaskar.alaparthi/hackweek-ai-debugger/venv/lib/python3.13/site-packages/starlette/middleware/errors.py", line 165, in __call__     await self.app(scope, receive, _send)   File "/Users/nagabhaskar.alaparthi/hackweek-ai-debugger/venv/lib/python3.13/site-packages/starlette/middleware/exceptions.py", line 62, in __call__     await wrap_app_handling_exceptions(self.app, conn)(scope, receive, send)   File "/Users/nagabhaskar.alaparthi/hackweek-ai-debugger/venv/lib/python3.13/site-packages/starlette/_exception_handler.py", line 53, in wrapped_app     raise exc   File "/Users/nagabhaskar.alaparthi/hackweek-ai-debugger/venv/lib/python3.13/site-packages/starlette/_exception_handler.py", line 42, in wrapped_app     await app(scope, receive, sender)   File "/Users/nagabhaskar.alaparthi/hackweek-ai-debugger/venv/lib/python3.13/site-packages/starlette/routing.py", line 714, in __call__     await self.middleware_stack(scope, receive, send)   File "/Users/nagabhaskar.alaparthi/hackweek-ai-debugger/venv/lib/python3.13/site-packages/starlette/routing.py", line 734, in app     await route.handle(scope, receive, send)   File "/Users/nagabhaskar.alaparthi/hackweek-ai-debugger/venv/lib/python3.13/site-packages/starlette/routing.py", line 288, in handle     await self.app(scope, receive, send)   File "/Users/nagabhaskar.alaparthi/hackweek-ai-debugger/venv/lib/python3.13/site-packages/starlette/routing.py", line 76, in app     await wrap_app_handling_exceptions(app, request)(scope, receive, send)   File "/Users/nagabhaskar.alaparthi/hackweek-ai-debugger/venv/lib/python3.13/site-packages/starlette/_exception_handler.py", line 53, in wrapped_app     raise exc   File "/Users/nagabhaskar.alaparthi/hackweek-ai-debugger/venv/lib/python3.13/site-packages/starlette/_exception_handler.py", line 42, in wrapped_app     await app(scope, receive, sender)   File "/Users/nagabhaskar.alaparthi/hackweek-ai-debugger/venv/lib/python3.13/site-packages/starlette/routing.py", line 73, in app     response = await f(request)                ^^^^^^^^^^^^^^^^   File "/Users/nagabhaskar.alaparthi/hackweek-ai-debugger/venv/lib/python3.13/site-packages/fastapi/routing.py", line 301, in app     raw_response = await run_endpoint_function(                    ^^^^^^^^^^^^^^^^^^^^^^^^^^^^     ...<3 lines>...     )     ^   File "/Users/nagabhaskar.alaparthi/hackweek-ai-debugger/venv/lib/python3.13/site-packages/fastapi/routing.py", line 214, in run_endpoint_function     return await run_in_threadpool(dependant.call, **values)            ^^^^^^^^^^^^^^^^^^^^^^^^^^^^^^^^^^^^^^^^^^^^^^^^^   File "/Users/nagabhaskar.alaparthi/hackweek-ai-debugger/venv/lib/python3.13/site-packages/starlette/concurrency.py", line 37, in run_in_threadpool     return await anyio.to_thread.run_sync(func)            ^^^^^^^^^^^^^^^^^^^^^^^^^^^^^^^^^^^^   File "/Users/nagabhaskar.alaparthi/hackweek-ai-debugger/venv/lib/python3.13/site-packages/anyio/to_thread.py", line 56, in run_sync     return await get_async_backend().run_sync_in_worker_thread(            ^^^^^^^^^^^^^^^^^^^^^^^^^^^^^^^^^^^^^^^^^^^^^^^^^^^^         func, args, abandon_on_cancel=abandon_on_cancel, limiter=limiter         ^^^^^^^^^^^^^^^^^^^^^^^^^^^^^^^^^^^^^^^^^^^^^^^^^^^^^^^^^^^^^^^^     )     ^   File "/Users/nagabhaskar.alaparthi/hackweek-ai-debugger/venv/lib/python3.13/site-packages/anyio/_backends/_asyncio.py", line 2470, in run_sync_in_worker_thread     return await future            ^^^^^^^^^^^^   File "/Users/nagabhaskar.alaparthi/hackweek-ai-debugger/venv/lib/python3.13/site-packages/anyio/_backends/_asyncio.py", line 967, in run     result = context.run(func, *args)   File "/Users/nagabhaskar.alaparthi/hackweek-ai-debugger/routers/example_router.py", line 20, in trigger_divide_by_zero_error     return ExampleService.simulate_divide_by_zero_error()            ~~~~~~~~~~~~~~~~~~~~~~~~~~~~~~~~~~~~~~~~~~~~^^   File "/Users/nagabhaskar.alaparthi/hackweek-ai-debugger/services/example_service.py", line 23, in simulate_divide_by_zero_error     raise RuntimeError("A division by zero error occurred.") from e RuntimeError: A division by zero error occurred. 
2025-04-22 14:36:25,291 - ERROR - Unhandled exception: Traceback (most recent call last):   File "/Users/nagabhaskar.alaparthi/hackweek-ai-debugger/services/example_service.py", line 21, in simulate_divide_by_zero_error     result = 1 / 0              ~~^~~ ZeroDivisionError: division by zero  The above exception was the direct cause of the following exception:  Traceback (most recent call last):   File "/Users/nagabhaskar.alaparthi/hackweek-ai-debugger/venv/lib/python3.13/site-packages/starlette/middleware/errors.py", line 165, in __call__     await self.app(scope, receive, _send)   File "/Users/nagabhaskar.alaparthi/hackweek-ai-debugger/venv/lib/python3.13/site-packages/starlette/middleware/exceptions.py", line 62, in __call__     await wrap_app_handling_exceptions(self.app, conn)(scope, receive, send)   File "/Users/nagabhaskar.alaparthi/hackweek-ai-debugger/venv/lib/python3.13/site-packages/starlette/_exception_handler.py", line 53, in wrapped_app     raise exc   File "/Users/nagabhaskar.alaparthi/hackweek-ai-debugger/venv/lib/python3.13/site-packages/starlette/_exception_handler.py", line 42, in wrapped_app     await app(scope, receive, sender)   File "/Users/nagabhaskar.alaparthi/hackweek-ai-debugger/venv/lib/python3.13/site-packages/starlette/routing.py", line 714, in __call__     await self.middleware_stack(scope, receive, send)   File "/Users/nagabhaskar.alaparthi/hackweek-ai-debugger/venv/lib/python3.13/site-packages/starlette/routing.py", line 734, in app     await route.handle(scope, receive, send)   File "/Users/nagabhaskar.alaparthi/hackweek-ai-debugger/venv/lib/python3.13/site-packages/starlette/routing.py", line 288, in handle     await self.app(scope, receive, send)   File "/Users/nagabhaskar.alaparthi/hackweek-ai-debugger/venv/lib/python3.13/site-packages/starlette/routing.py", line 76, in app     await wrap_app_handling_exceptions(app, request)(scope, receive, send)   File "/Users/nagabhaskar.alaparthi/hackweek-ai-debugger/venv/lib/python3.13/site-packages/starlette/_exception_handler.py", line 53, in wrapped_app     raise exc   File "/Users/nagabhaskar.alaparthi/hackweek-ai-debugger/venv/lib/python3.13/site-packages/starlette/_exception_handler.py", line 42, in wrapped_app     await app(scope, receive, sender)   File "/Users/nagabhaskar.alaparthi/hackweek-ai-debugger/venv/lib/python3.13/site-packages/starlette/routing.py", line 73, in app     response = await f(request)                ^^^^^^^^^^^^^^^^   File "/Users/nagabhaskar.alaparthi/hackweek-ai-debugger/venv/lib/python3.13/site-packages/fastapi/routing.py", line 301, in app     raw_response = await run_endpoint_function(                    ^^^^^^^^^^^^^^^^^^^^^^^^^^^^     ...<3 lines>...     )     ^   File "/Users/nagabhaskar.alaparthi/hackweek-ai-debugger/venv/lib/python3.13/site-packages/fastapi/routing.py", line 214, in run_endpoint_function     return await run_in_threadpool(dependant.call, **values)            ^^^^^^^^^^^^^^^^^^^^^^^^^^^^^^^^^^^^^^^^^^^^^^^^^   File "/Users/nagabhaskar.alaparthi/hackweek-ai-debugger/venv/lib/python3.13/site-packages/starlette/concurrency.py", line 37, in run_in_threadpool     return await anyio.to_thread.run_sync(func)            ^^^^^^^^^^^^^^^^^^^^^^^^^^^^^^^^^^^^   File "/Users/nagabhaskar.alaparthi/hackweek-ai-debugger/venv/lib/python3.13/site-packages/anyio/to_thread.py", line 56, in run_sync     return await get_async_backend().run_sync_in_worker_thread(            ^^^^^^^^^^^^^^^^^^^^^^^^^^^^^^^^^^^^^^^^^^^^^^^^^^^^         func, args, abandon_on_cancel=abandon_on_cancel, limiter=limiter         ^^^^^^^^^^^^^^^^^^^^^^^^^^^^^^^^^^^^^^^^^^^^^^^^^^^^^^^^^^^^^^^^     )     ^   File "/Users/nagabhaskar.alaparthi/hackweek-ai-debugger/venv/lib/python3.13/site-packages/anyio/_backends/_asyncio.py", line 2470, in run_sync_in_worker_thread     return await future            ^^^^^^^^^^^^   File "/Users/nagabhaskar.alaparthi/hackweek-ai-debugger/venv/lib/python3.13/site-packages/anyio/_backends/_asyncio.py", line 967, in run     result = context.run(func, *args)   File "/Users/nagabhaskar.alaparthi/hackweek-ai-debugger/routers/example_router.py", line 20, in trigger_divide_by_zero_error     return ExampleService.simulate_divide_by_zero_error()            ~~~~~~~~~~~~~~~~~~~~~~~~~~~~~~~~~~~~~~~~~~~~^^   File "/Users/nagabhaskar.alaparthi/hackweek-ai-debugger/services/example_service.py", line 23, in simulate_divide_by_zero_error     raise RuntimeError("A division by zero error occurred.") from e RuntimeError: A division by zero error occurred. 
2025-04-22 14:48:26,840 - ERROR - Unhandled exception: Traceback (most recent call last):   File "/Users/nagabhaskar.alaparthi/hackweek-ai-debugger/services/example_service.py", line 21, in simulate_divide_by_zero_error     result = 1 / 0              ~~^~~ ZeroDivisionError: division by zero  The above exception was the direct cause of the following exception:  Traceback (most recent call last):   File "/Users/nagabhaskar.alaparthi/hackweek-ai-debugger/venv/lib/python3.13/site-packages/starlette/middleware/errors.py", line 165, in __call__     await self.app(scope, receive, _send)   File "/Users/nagabhaskar.alaparthi/hackweek-ai-debugger/venv/lib/python3.13/site-packages/starlette/middleware/exceptions.py", line 62, in __call__     await wrap_app_handling_exceptions(self.app, conn)(scope, receive, send)   File "/Users/nagabhaskar.alaparthi/hackweek-ai-debugger/venv/lib/python3.13/site-packages/starlette/_exception_handler.py", line 53, in wrapped_app     raise exc   File "/Users/nagabhaskar.alaparthi/hackweek-ai-debugger/venv/lib/python3.13/site-packages/starlette/_exception_handler.py", line 42, in wrapped_app     await app(scope, receive, sender)   File "/Users/nagabhaskar.alaparthi/hackweek-ai-debugger/venv/lib/python3.13/site-packages/starlette/routing.py", line 714, in __call__     await self.middleware_stack(scope, receive, send)   File "/Users/nagabhaskar.alaparthi/hackweek-ai-debugger/venv/lib/python3.13/site-packages/starlette/routing.py", line 734, in app     await route.handle(scope, receive, send)   File "/Users/nagabhaskar.alaparthi/hackweek-ai-debugger/venv/lib/python3.13/site-packages/starlette/routing.py", line 288, in handle     await self.app(scope, receive, send)   File "/Users/nagabhaskar.alaparthi/hackweek-ai-debugger/venv/lib/python3.13/site-packages/starlette/routing.py", line 76, in app     await wrap_app_handling_exceptions(app, request)(scope, receive, send)   File "/Users/nagabhaskar.alaparthi/hackweek-ai-debugger/venv/lib/python3.13/site-packages/starlette/_exception_handler.py", line 53, in wrapped_app     raise exc   File "/Users/nagabhaskar.alaparthi/hackweek-ai-debugger/venv/lib/python3.13/site-packages/starlette/_exception_handler.py", line 42, in wrapped_app     await app(scope, receive, sender)   File "/Users/nagabhaskar.alaparthi/hackweek-ai-debugger/venv/lib/python3.13/site-packages/starlette/routing.py", line 73, in app     response = await f(request)                ^^^^^^^^^^^^^^^^   File "/Users/nagabhaskar.alaparthi/hackweek-ai-debugger/venv/lib/python3.13/site-packages/fastapi/routing.py", line 301, in app     raw_response = await run_endpoint_function(                    ^^^^^^^^^^^^^^^^^^^^^^^^^^^^     ...<3 lines>...     )     ^   File "/Users/nagabhaskar.alaparthi/hackweek-ai-debugger/venv/lib/python3.13/site-packages/fastapi/routing.py", line 214, in run_endpoint_function     return await run_in_threadpool(dependant.call, **values)            ^^^^^^^^^^^^^^^^^^^^^^^^^^^^^^^^^^^^^^^^^^^^^^^^^   File "/Users/nagabhaskar.alaparthi/hackweek-ai-debugger/venv/lib/python3.13/site-packages/starlette/concurrency.py", line 37, in run_in_threadpool     return await anyio.to_thread.run_sync(func)            ^^^^^^^^^^^^^^^^^^^^^^^^^^^^^^^^^^^^   File "/Users/nagabhaskar.alaparthi/hackweek-ai-debugger/venv/lib/python3.13/site-packages/anyio/to_thread.py", line 56, in run_sync     return await get_async_backend().run_sync_in_worker_thread(            ^^^^^^^^^^^^^^^^^^^^^^^^^^^^^^^^^^^^^^^^^^^^^^^^^^^^         func, args, abandon_on_cancel=abandon_on_cancel, limiter=limiter         ^^^^^^^^^^^^^^^^^^^^^^^^^^^^^^^^^^^^^^^^^^^^^^^^^^^^^^^^^^^^^^^^     )     ^   File "/Users/nagabhaskar.alaparthi/hackweek-ai-debugger/venv/lib/python3.13/site-packages/anyio/_backends/_asyncio.py", line 2470, in run_sync_in_worker_thread     return await future            ^^^^^^^^^^^^   File "/Users/nagabhaskar.alaparthi/hackweek-ai-debugger/venv/lib/python3.13/site-packages/anyio/_backends/_asyncio.py", line 967, in run     result = context.run(func, *args)   File "/Users/nagabhaskar.alaparthi/hackweek-ai-debugger/routers/example_router.py", line 20, in trigger_divide_by_zero_error     return ExampleService.simulate_divide_by_zero_error()            ~~~~~~~~~~~~~~~~~~~~~~~~~~~~~~~~~~~~~~~~~~~~^^   File "/Users/nagabhaskar.alaparthi/hackweek-ai-debugger/services/example_service.py", line 23, in simulate_divide_by_zero_error     raise RuntimeError("A division by zero error occurred.") from e RuntimeError: A division by zero error occurred. 
2025-04-22 14:55:48,171 - ERROR - Unhandled exception: Traceback (most recent call last):   File "/Users/nagabhaskar.alaparthi/hackweek-ai-debugger/venv/lib/python3.13/site-packages/starlette/middleware/errors.py", line 165, in __call__     await self.app(scope, receive, _send)   File "/Users/nagabhaskar.alaparthi/hackweek-ai-debugger/venv/lib/python3.13/site-packages/starlette/middleware/exceptions.py", line 62, in __call__     await wrap_app_handling_exceptions(self.app, conn)(scope, receive, send)   File "/Users/nagabhaskar.alaparthi/hackweek-ai-debugger/venv/lib/python3.13/site-packages/starlette/_exception_handler.py", line 53, in wrapped_app     raise exc   File "/Users/nagabhaskar.alaparthi/hackweek-ai-debugger/venv/lib/python3.13/site-packages/starlette/_exception_handler.py", line 42, in wrapped_app     await app(scope, receive, sender)   File "/Users/nagabhaskar.alaparthi/hackweek-ai-debugger/venv/lib/python3.13/site-packages/starlette/routing.py", line 714, in __call__     await self.middleware_stack(scope, receive, send)   File "/Users/nagabhaskar.alaparthi/hackweek-ai-debugger/venv/lib/python3.13/site-packages/starlette/routing.py", line 734, in app     await route.handle(scope, receive, send)   File "/Users/nagabhaskar.alaparthi/hackweek-ai-debugger/venv/lib/python3.13/site-packages/starlette/routing.py", line 288, in handle     await self.app(scope, receive, send)   File "/Users/nagabhaskar.alaparthi/hackweek-ai-debugger/venv/lib/python3.13/site-packages/starlette/routing.py", line 76, in app     await wrap_app_handling_exceptions(app, request)(scope, receive, send)   File "/Users/nagabhaskar.alaparthi/hackweek-ai-debugger/venv/lib/python3.13/site-packages/starlette/_exception_handler.py", line 53, in wrapped_app     raise exc   File "/Users/nagabhaskar.alaparthi/hackweek-ai-debugger/venv/lib/python3.13/site-packages/starlette/_exception_handler.py", line 42, in wrapped_app     await app(scope, receive, sender)   File "/Users/nagabhaskar.alaparthi/hackweek-ai-debugger/venv/lib/python3.13/site-packages/starlette/routing.py", line 73, in app     response = await f(request)                ^^^^^^^^^^^^^^^^   File "/Users/nagabhaskar.alaparthi/hackweek-ai-debugger/venv/lib/python3.13/site-packages/fastapi/routing.py", line 301, in app     raw_response = await run_endpoint_function(                    ^^^^^^^^^^^^^^^^^^^^^^^^^^^^     ...<3 lines>...     )     ^   File "/Users/nagabhaskar.alaparthi/hackweek-ai-debugger/venv/lib/python3.13/site-packages/fastapi/routing.py", line 214, in run_endpoint_function     return await run_in_threadpool(dependant.call, **values)            ^^^^^^^^^^^^^^^^^^^^^^^^^^^^^^^^^^^^^^^^^^^^^^^^^   File "/Users/nagabhaskar.alaparthi/hackweek-ai-debugger/venv/lib/python3.13/site-packages/starlette/concurrency.py", line 37, in run_in_threadpool     return await anyio.to_thread.run_sync(func)            ^^^^^^^^^^^^^^^^^^^^^^^^^^^^^^^^^^^^   File "/Users/nagabhaskar.alaparthi/hackweek-ai-debugger/venv/lib/python3.13/site-packages/anyio/to_thread.py", line 56, in run_sync     return await get_async_backend().run_sync_in_worker_thread(            ^^^^^^^^^^^^^^^^^^^^^^^^^^^^^^^^^^^^^^^^^^^^^^^^^^^^         func, args, abandon_on_cancel=abandon_on_cancel, limiter=limiter         ^^^^^^^^^^^^^^^^^^^^^^^^^^^^^^^^^^^^^^^^^^^^^^^^^^^^^^^^^^^^^^^^     )     ^   File "/Users/nagabhaskar.alaparthi/hackweek-ai-debugger/venv/lib/python3.13/site-packages/anyio/_backends/_asyncio.py", line 2470, in run_sync_in_worker_thread     return await future            ^^^^^^^^^^^^   File "/Users/nagabhaskar.alaparthi/hackweek-ai-debugger/venv/lib/python3.13/site-packages/anyio/_backends/_asyncio.py", line 967, in run     result = context.run(func, *args)   File "/Users/nagabhaskar.alaparthi/hackweek-ai-debugger/routers/example_router.py", line 28, in calculate_expression     return ExampleService.calculate_expression(payload)            ~~~~~~~~~~~~~~~~~~~~~~~~~~~~~~~~~~~^^^^^^^^^   File "/Users/nagabhaskar.alaparthi/hackweek-ai-debugger/services/example_service.py", line 38, in calculate_expression     result = x / y + y / z + z / x                              ~~^~~ ZeroDivisionError: division by zero 
2025-04-22 15:04:19,109 - ERROR - Unhandled exception: Traceback (most recent call last):   File "/Users/nagabhaskar.alaparthi/hackweek-ai-debugger/venv/lib/python3.13/site-packages/starlette/middleware/errors.py", line 165, in __call__     await self.app(scope, receive, _send)   File "/Users/nagabhaskar.alaparthi/hackweek-ai-debugger/venv/lib/python3.13/site-packages/starlette/middleware/exceptions.py", line 62, in __call__     await wrap_app_handling_exceptions(self.app, conn)(scope, receive, send)   File "/Users/nagabhaskar.alaparthi/hackweek-ai-debugger/venv/lib/python3.13/site-packages/starlette/_exception_handler.py", line 53, in wrapped_app     raise exc   File "/Users/nagabhaskar.alaparthi/hackweek-ai-debugger/venv/lib/python3.13/site-packages/starlette/_exception_handler.py", line 42, in wrapped_app     await app(scope, receive, sender)   File "/Users/nagabhaskar.alaparthi/hackweek-ai-debugger/venv/lib/python3.13/site-packages/starlette/routing.py", line 714, in __call__     await self.middleware_stack(scope, receive, send)   File "/Users/nagabhaskar.alaparthi/hackweek-ai-debugger/venv/lib/python3.13/site-packages/starlette/routing.py", line 734, in app     await route.handle(scope, receive, send)   File "/Users/nagabhaskar.alaparthi/hackweek-ai-debugger/venv/lib/python3.13/site-packages/starlette/routing.py", line 288, in handle     await self.app(scope, receive, send)   File "/Users/nagabhaskar.alaparthi/hackweek-ai-debugger/venv/lib/python3.13/site-packages/starlette/routing.py", line 76, in app     await wrap_app_handling_exceptions(app, request)(scope, receive, send)   File "/Users/nagabhaskar.alaparthi/hackweek-ai-debugger/venv/lib/python3.13/site-packages/starlette/_exception_handler.py", line 53, in wrapped_app     raise exc   File "/Users/nagabhaskar.alaparthi/hackweek-ai-debugger/venv/lib/python3.13/site-packages/starlette/_exception_handler.py", line 42, in wrapped_app     await app(scope, receive, sender)   File "/Users/nagabhaskar.alaparthi/hackweek-ai-debugger/venv/lib/python3.13/site-packages/starlette/routing.py", line 73, in app     response = await f(request)                ^^^^^^^^^^^^^^^^   File "/Users/nagabhaskar.alaparthi/hackweek-ai-debugger/venv/lib/python3.13/site-packages/fastapi/routing.py", line 301, in app     raw_response = await run_endpoint_function(                    ^^^^^^^^^^^^^^^^^^^^^^^^^^^^     ...<3 lines>...     )     ^   File "/Users/nagabhaskar.alaparthi/hackweek-ai-debugger/venv/lib/python3.13/site-packages/fastapi/routing.py", line 214, in run_endpoint_function     return await run_in_threadpool(dependant.call, **values)            ^^^^^^^^^^^^^^^^^^^^^^^^^^^^^^^^^^^^^^^^^^^^^^^^^   File "/Users/nagabhaskar.alaparthi/hackweek-ai-debugger/venv/lib/python3.13/site-packages/starlette/concurrency.py", line 37, in run_in_threadpool     return await anyio.to_thread.run_sync(func)            ^^^^^^^^^^^^^^^^^^^^^^^^^^^^^^^^^^^^   File "/Users/nagabhaskar.alaparthi/hackweek-ai-debugger/venv/lib/python3.13/site-packages/anyio/to_thread.py", line 56, in run_sync     return await get_async_backend().run_sync_in_worker_thread(            ^^^^^^^^^^^^^^^^^^^^^^^^^^^^^^^^^^^^^^^^^^^^^^^^^^^^         func, args, abandon_on_cancel=abandon_on_cancel, limiter=limiter         ^^^^^^^^^^^^^^^^^^^^^^^^^^^^^^^^^^^^^^^^^^^^^^^^^^^^^^^^^^^^^^^^     )     ^   File "/Users/nagabhaskar.alaparthi/hackweek-ai-debugger/venv/lib/python3.13/site-packages/anyio/_backends/_asyncio.py", line 2470, in run_sync_in_worker_thread     return await future            ^^^^^^^^^^^^   File "/Users/nagabhaskar.alaparthi/hackweek-ai-debugger/venv/lib/python3.13/site-packages/anyio/_backends/_asyncio.py", line 967, in run     result = context.run(func, *args)   File "/Users/nagabhaskar.alaparthi/hackweek-ai-debugger/routers/example_router.py", line 28, in calculate_expression     return ExampleService.calculate_expression(payload)            ~~~~~~~~~~~~~~~~~~~~~~~~~~~~~~~~~~~^^^^^^^^^   File "/Users/nagabhaskar.alaparthi/hackweek-ai-debugger/services/example_service.py", line 38, in calculate_expression     result = x / y + y / z + z / x                              ~~^~~ ZeroDivisionError: division by zero 
2025-04-22 15:07:46,233 - ERROR - Unhandled exception: Traceback (most recent call last):   File "/Users/nagabhaskar.alaparthi/hackweek-ai-debugger/venv/lib/python3.13/site-packages/starlette/middleware/errors.py", line 165, in __call__     await self.app(scope, receive, _send)   File "/Users/nagabhaskar.alaparthi/hackweek-ai-debugger/venv/lib/python3.13/site-packages/starlette/middleware/exceptions.py", line 62, in __call__     await wrap_app_handling_exceptions(self.app, conn)(scope, receive, send)   File "/Users/nagabhaskar.alaparthi/hackweek-ai-debugger/venv/lib/python3.13/site-packages/starlette/_exception_handler.py", line 53, in wrapped_app     raise exc   File "/Users/nagabhaskar.alaparthi/hackweek-ai-debugger/venv/lib/python3.13/site-packages/starlette/_exception_handler.py", line 42, in wrapped_app     await app(scope, receive, sender)   File "/Users/nagabhaskar.alaparthi/hackweek-ai-debugger/venv/lib/python3.13/site-packages/starlette/routing.py", line 714, in __call__     await self.middleware_stack(scope, receive, send)   File "/Users/nagabhaskar.alaparthi/hackweek-ai-debugger/venv/lib/python3.13/site-packages/starlette/routing.py", line 734, in app     await route.handle(scope, receive, send)   File "/Users/nagabhaskar.alaparthi/hackweek-ai-debugger/venv/lib/python3.13/site-packages/starlette/routing.py", line 288, in handle     await self.app(scope, receive, send)   File "/Users/nagabhaskar.alaparthi/hackweek-ai-debugger/venv/lib/python3.13/site-packages/starlette/routing.py", line 76, in app     await wrap_app_handling_exceptions(app, request)(scope, receive, send)   File "/Users/nagabhaskar.alaparthi/hackweek-ai-debugger/venv/lib/python3.13/site-packages/starlette/_exception_handler.py", line 53, in wrapped_app     raise exc   File "/Users/nagabhaskar.alaparthi/hackweek-ai-debugger/venv/lib/python3.13/site-packages/starlette/_exception_handler.py", line 42, in wrapped_app     await app(scope, receive, sender)   File "/Users/nagabhaskar.alaparthi/hackweek-ai-debugger/venv/lib/python3.13/site-packages/starlette/routing.py", line 73, in app     response = await f(request)                ^^^^^^^^^^^^^^^^   File "/Users/nagabhaskar.alaparthi/hackweek-ai-debugger/venv/lib/python3.13/site-packages/fastapi/routing.py", line 301, in app     raw_response = await run_endpoint_function(                    ^^^^^^^^^^^^^^^^^^^^^^^^^^^^     ...<3 lines>...     )     ^   File "/Users/nagabhaskar.alaparthi/hackweek-ai-debugger/venv/lib/python3.13/site-packages/fastapi/routing.py", line 214, in run_endpoint_function     return await run_in_threadpool(dependant.call, **values)            ^^^^^^^^^^^^^^^^^^^^^^^^^^^^^^^^^^^^^^^^^^^^^^^^^   File "/Users/nagabhaskar.alaparthi/hackweek-ai-debugger/venv/lib/python3.13/site-packages/starlette/concurrency.py", line 37, in run_in_threadpool     return await anyio.to_thread.run_sync(func)            ^^^^^^^^^^^^^^^^^^^^^^^^^^^^^^^^^^^^   File "/Users/nagabhaskar.alaparthi/hackweek-ai-debugger/venv/lib/python3.13/site-packages/anyio/to_thread.py", line 56, in run_sync     return await get_async_backend().run_sync_in_worker_thread(            ^^^^^^^^^^^^^^^^^^^^^^^^^^^^^^^^^^^^^^^^^^^^^^^^^^^^         func, args, abandon_on_cancel=abandon_on_cancel, limiter=limiter         ^^^^^^^^^^^^^^^^^^^^^^^^^^^^^^^^^^^^^^^^^^^^^^^^^^^^^^^^^^^^^^^^     )     ^   File "/Users/nagabhaskar.alaparthi/hackweek-ai-debugger/venv/lib/python3.13/site-packages/anyio/_backends/_asyncio.py", line 2470, in run_sync_in_worker_thread     return await future            ^^^^^^^^^^^^   File "/Users/nagabhaskar.alaparthi/hackweek-ai-debugger/venv/lib/python3.13/site-packages/anyio/_backends/_asyncio.py", line 967, in run     result = context.run(func, *args)   File "/Users/nagabhaskar.alaparthi/hackweek-ai-debugger/routers/example_router.py", line 28, in calculate_expression     return ExampleService.calculate_expression(payload)            ~~~~~~~~~~~~~~~~~~~~~~~~~~~~~~~~~~~^^^^^^^^^   File "/Users/nagabhaskar.alaparthi/hackweek-ai-debugger/services/example_service.py", line 38, in calculate_expression     result = x / y + y / z + z / x                              ~~^~~ ZeroDivisionError: division by zero 
2025-04-22 15:08:42,507 - ERROR - Unhandled exception: Traceback (most recent call last):   File "/Users/nagabhaskar.alaparthi/hackweek-ai-debugger/venv/lib/python3.13/site-packages/starlette/middleware/errors.py", line 165, in __call__     await self.app(scope, receive, _send)   File "/Users/nagabhaskar.alaparthi/hackweek-ai-debugger/venv/lib/python3.13/site-packages/starlette/middleware/exceptions.py", line 62, in __call__     await wrap_app_handling_exceptions(self.app, conn)(scope, receive, send)   File "/Users/nagabhaskar.alaparthi/hackweek-ai-debugger/venv/lib/python3.13/site-packages/starlette/_exception_handler.py", line 53, in wrapped_app     raise exc   File "/Users/nagabhaskar.alaparthi/hackweek-ai-debugger/venv/lib/python3.13/site-packages/starlette/_exception_handler.py", line 42, in wrapped_app     await app(scope, receive, sender)   File "/Users/nagabhaskar.alaparthi/hackweek-ai-debugger/venv/lib/python3.13/site-packages/starlette/routing.py", line 714, in __call__     await self.middleware_stack(scope, receive, send)   File "/Users/nagabhaskar.alaparthi/hackweek-ai-debugger/venv/lib/python3.13/site-packages/starlette/routing.py", line 734, in app     await route.handle(scope, receive, send)   File "/Users/nagabhaskar.alaparthi/hackweek-ai-debugger/venv/lib/python3.13/site-packages/starlette/routing.py", line 288, in handle     await self.app(scope, receive, send)   File "/Users/nagabhaskar.alaparthi/hackweek-ai-debugger/venv/lib/python3.13/site-packages/starlette/routing.py", line 76, in app     await wrap_app_handling_exceptions(app, request)(scope, receive, send)   File "/Users/nagabhaskar.alaparthi/hackweek-ai-debugger/venv/lib/python3.13/site-packages/starlette/_exception_handler.py", line 53, in wrapped_app     raise exc   File "/Users/nagabhaskar.alaparthi/hackweek-ai-debugger/venv/lib/python3.13/site-packages/starlette/_exception_handler.py", line 42, in wrapped_app     await app(scope, receive, sender)   File "/Users/nagabhaskar.alaparthi/hackweek-ai-debugger/venv/lib/python3.13/site-packages/starlette/routing.py", line 73, in app     response = await f(request)                ^^^^^^^^^^^^^^^^   File "/Users/nagabhaskar.alaparthi/hackweek-ai-debugger/venv/lib/python3.13/site-packages/fastapi/routing.py", line 301, in app     raw_response = await run_endpoint_function(                    ^^^^^^^^^^^^^^^^^^^^^^^^^^^^     ...<3 lines>...     )     ^   File "/Users/nagabhaskar.alaparthi/hackweek-ai-debugger/venv/lib/python3.13/site-packages/fastapi/routing.py", line 214, in run_endpoint_function     return await run_in_threadpool(dependant.call, **values)            ^^^^^^^^^^^^^^^^^^^^^^^^^^^^^^^^^^^^^^^^^^^^^^^^^   File "/Users/nagabhaskar.alaparthi/hackweek-ai-debugger/venv/lib/python3.13/site-packages/starlette/concurrency.py", line 37, in run_in_threadpool     return await anyio.to_thread.run_sync(func)            ^^^^^^^^^^^^^^^^^^^^^^^^^^^^^^^^^^^^   File "/Users/nagabhaskar.alaparthi/hackweek-ai-debugger/venv/lib/python3.13/site-packages/anyio/to_thread.py", line 56, in run_sync     return await get_async_backend().run_sync_in_worker_thread(            ^^^^^^^^^^^^^^^^^^^^^^^^^^^^^^^^^^^^^^^^^^^^^^^^^^^^         func, args, abandon_on_cancel=abandon_on_cancel, limiter=limiter         ^^^^^^^^^^^^^^^^^^^^^^^^^^^^^^^^^^^^^^^^^^^^^^^^^^^^^^^^^^^^^^^^     )     ^   File "/Users/nagabhaskar.alaparthi/hackweek-ai-debugger/venv/lib/python3.13/site-packages/anyio/_backends/_asyncio.py", line 2470, in run_sync_in_worker_thread     return await future            ^^^^^^^^^^^^   File "/Users/nagabhaskar.alaparthi/hackweek-ai-debugger/venv/lib/python3.13/site-packages/anyio/_backends/_asyncio.py", line 967, in run     result = context.run(func, *args)   File "/Users/nagabhaskar.alaparthi/hackweek-ai-debugger/routers/example_router.py", line 28, in calculate_expression     return ExampleService.calculate_expression(payload)            ~~~~~~~~~~~~~~~~~~~~~~~~~~~~~~~~~~~^^^^^^^^^   File "/Users/nagabhaskar.alaparthi/hackweek-ai-debugger/services/example_service.py", line 19, in calculate_expression     text = payload["text"]            ~~~~~~~^^^^^^^^ KeyError: 'text' 
