2025-04-21 12:26:22,933 - ERROR - Unhandled exception: Traceback (most recent call last):   File "/Users/nagabhaskar.alaparthi/hackweek-ai-debugger/services/example_service.py", line 21, in simulate_divide_by_zero_error     result = 1 / 0              ~~^~~ ZeroDivisionError: division by zero  The above exception was the direct cause of the following exception:  Traceback (most recent call last):   File "/Users/nagabhaskar.alaparthi/hackweek-ai-debugger/venv/lib/python3.13/site-packages/starlette/middleware/errors.py", line 165, in __call__     await self.app(scope, receive, _send)   File "/Users/nagabhaskar.alaparthi/hackweek-ai-debugger/venv/lib/python3.13/site-packages/starlette/middleware/exceptions.py", line 62, in __call__     await wrap_app_handling_exceptions(self.app, conn)(scope, receive, send)   File "/Users/nagabhaskar.alaparthi/hackweek-ai-debugger/venv/lib/python3.13/site-packages/starlette/_exception_handler.py", line 53, in wrapped_app     raise exc   File "/Users/nagabhaskar.alaparthi/hackweek-ai-debugger/venv/lib/python3.13/site-packages/starlette/_exception_handler.py", line 42, in wrapped_app     await app(scope, receive, sender)   File "/Users/nagabhaskar.alaparthi/hackweek-ai-debugger/venv/lib/python3.13/site-packages/starlette/routing.py", line 714, in __call__     await self.middleware_stack(scope, receive, send)   File "/Users/nagabhaskar.alaparthi/hackweek-ai-debugger/venv/lib/python3.13/site-packages/starlette/routing.py", line 734, in app     await route.handle(scope, receive, send)   File "/Users/nagabhaskar.alaparthi/hackweek-ai-debugger/venv/lib/python3.13/site-packages/starlette/routing.py", line 288, in handle     await self.app(scope, receive, send)   File "/Users/nagabhaskar.alaparthi/hackweek-ai-debugger/venv/lib/python3.13/site-packages/starlette/routing.py", line 76, in app     await wrap_app_handling_exceptions(app, request)(scope, receive, send)   File "/Users/nagabhaskar.alaparthi/hackweek-ai-debugger/venv/lib/python3.13/site-packages/starlette/_exception_handler.py", line 53, in wrapped_app     raise exc   File "/Users/nagabhaskar.alaparthi/hackweek-ai-debugger/venv/lib/python3.13/site-packages/starlette/_exception_handler.py", line 42, in wrapped_app     await app(scope, receive, sender)   File "/Users/nagabhaskar.alaparthi/hackweek-ai-debugger/venv/lib/python3.13/site-packages/starlette/routing.py", line 73, in app     response = await f(request)                ^^^^^^^^^^^^^^^^   File "/Users/nagabhaskar.alaparthi/hackweek-ai-debugger/venv/lib/python3.13/site-packages/fastapi/routing.py", line 301, in app     raw_response = await run_endpoint_function(                    ^^^^^^^^^^^^^^^^^^^^^^^^^^^^     ...<3 lines>...     )     ^   File "/Users/nagabhaskar.alaparthi/hackweek-ai-debugger/venv/lib/python3.13/site-packages/fastapi/routing.py", line 214, in run_endpoint_function     return await run_in_threadpool(dependant.call, **values)            ^^^^^^^^^^^^^^^^^^^^^^^^^^^^^^^^^^^^^^^^^^^^^^^^^   File "/Users/nagabhaskar.alaparthi/hackweek-ai-debugger/venv/lib/python3.13/site-packages/starlette/concurrency.py", line 37, in run_in_threadpool     return await anyio.to_thread.run_sync(func)            ^^^^^^^^^^^^^^^^^^^^^^^^^^^^^^^^^^^^   File "/Users/nagabhaskar.alaparthi/hackweek-ai-debugger/venv/lib/python3.13/site-packages/anyio/to_thread.py", line 56, in run_sync     return await get_async_backend().run_sync_in_worker_thread(            ^^^^^^^^^^^^^^^^^^^^^^^^^^^^^^^^^^^^^^^^^^^^^^^^^^^^         func, args, abandon_on_cancel=abandon_on_cancel, limiter=limiter         ^^^^^^^^^^^^^^^^^^^^^^^^^^^^^^^^^^^^^^^^^^^^^^^^^^^^^^^^^^^^^^^^     )     ^   File "/Users/nagabhaskar.alaparthi/hackweek-ai-debugger/venv/lib/python3.13/site-packages/anyio/_backends/_asyncio.py", line 2470, in run_sync_in_worker_thread     return await future            ^^^^^^^^^^^^   File "/Users/nagabhaskar.alaparthi/hackweek-ai-debugger/venv/lib/python3.13/site-packages/anyio/_backends/_asyncio.py", line 967, in run     result = context.run(func, *args)   File "/Users/nagabhaskar.alaparthi/hackweek-ai-debugger/routers/example_router.py", line 20, in trigger_divide_by_zero_error     return ExampleService.simulate_divide_by_zero_error()            ~~~~~~~~~~~~~~~~~~~~~~~~~~~~~~~~~~~~~~~~~~~~^^   File "/Users/nagabhaskar.alaparthi/hackweek-ai-debugger/services/example_service.py", line 23, in simulate_divide_by_zero_error     raise RuntimeError("A division by zero error occurred.") from e RuntimeError: A division by zero error occurred. 
2025-04-21 12:27:41,985 - ERROR - Unhandled exception: Traceback (most recent call last):   File "/Users/nagabhaskar.alaparthi/hackweek-ai-debugger/services/example_service.py", line 21, in simulate_divide_by_zero_error     result = 1 / 0              ~~^~~ ZeroDivisionError: division by zero  The above exception was the direct cause of the following exception:  Traceback (most recent call last):   File "/Users/nagabhaskar.alaparthi/hackweek-ai-debugger/venv/lib/python3.13/site-packages/starlette/middleware/errors.py", line 165, in __call__     await self.app(scope, receive, _send)   File "/Users/nagabhaskar.alaparthi/hackweek-ai-debugger/venv/lib/python3.13/site-packages/starlette/middleware/exceptions.py", line 62, in __call__     await wrap_app_handling_exceptions(self.app, conn)(scope, receive, send)   File "/Users/nagabhaskar.alaparthi/hackweek-ai-debugger/venv/lib/python3.13/site-packages/starlette/_exception_handler.py", line 53, in wrapped_app     raise exc   File "/Users/nagabhaskar.alaparthi/hackweek-ai-debugger/venv/lib/python3.13/site-packages/starlette/_exception_handler.py", line 42, in wrapped_app     await app(scope, receive, sender)   File "/Users/nagabhaskar.alaparthi/hackweek-ai-debugger/venv/lib/python3.13/site-packages/starlette/routing.py", line 714, in __call__     await self.middleware_stack(scope, receive, send)   File "/Users/nagabhaskar.alaparthi/hackweek-ai-debugger/venv/lib/python3.13/site-packages/starlette/routing.py", line 734, in app     await route.handle(scope, receive, send)   File "/Users/nagabhaskar.alaparthi/hackweek-ai-debugger/venv/lib/python3.13/site-packages/starlette/routing.py", line 288, in handle     await self.app(scope, receive, send)   File "/Users/nagabhaskar.alaparthi/hackweek-ai-debugger/venv/lib/python3.13/site-packages/starlette/routing.py", line 76, in app     await wrap_app_handling_exceptions(app, request)(scope, receive, send)   File "/Users/nagabhaskar.alaparthi/hackweek-ai-debugger/venv/lib/python3.13/site-packages/starlette/_exception_handler.py", line 53, in wrapped_app     raise exc   File "/Users/nagabhaskar.alaparthi/hackweek-ai-debugger/venv/lib/python3.13/site-packages/starlette/_exception_handler.py", line 42, in wrapped_app     await app(scope, receive, sender)   File "/Users/nagabhaskar.alaparthi/hackweek-ai-debugger/venv/lib/python3.13/site-packages/starlette/routing.py", line 73, in app     response = await f(request)                ^^^^^^^^^^^^^^^^   File "/Users/nagabhaskar.alaparthi/hackweek-ai-debugger/venv/lib/python3.13/site-packages/fastapi/routing.py", line 301, in app     raw_response = await run_endpoint_function(                    ^^^^^^^^^^^^^^^^^^^^^^^^^^^^     ...<3 lines>...     )     ^   File "/Users/nagabhaskar.alaparthi/hackweek-ai-debugger/venv/lib/python3.13/site-packages/fastapi/routing.py", line 214, in run_endpoint_function     return await run_in_threadpool(dependant.call, **values)            ^^^^^^^^^^^^^^^^^^^^^^^^^^^^^^^^^^^^^^^^^^^^^^^^^   File "/Users/nagabhaskar.alaparthi/hackweek-ai-debugger/venv/lib/python3.13/site-packages/starlette/concurrency.py", line 37, in run_in_threadpool     return await anyio.to_thread.run_sync(func)            ^^^^^^^^^^^^^^^^^^^^^^^^^^^^^^^^^^^^   File "/Users/nagabhaskar.alaparthi/hackweek-ai-debugger/venv/lib/python3.13/site-packages/anyio/to_thread.py", line 56, in run_sync     return await get_async_backend().run_sync_in_worker_thread(            ^^^^^^^^^^^^^^^^^^^^^^^^^^^^^^^^^^^^^^^^^^^^^^^^^^^^         func, args, abandon_on_cancel=abandon_on_cancel, limiter=limiter         ^^^^^^^^^^^^^^^^^^^^^^^^^^^^^^^^^^^^^^^^^^^^^^^^^^^^^^^^^^^^^^^^     )     ^   File "/Users/nagabhaskar.alaparthi/hackweek-ai-debugger/venv/lib/python3.13/site-packages/anyio/_backends/_asyncio.py", line 2470, in run_sync_in_worker_thread     return await future            ^^^^^^^^^^^^   File "/Users/nagabhaskar.alaparthi/hackweek-ai-debugger/venv/lib/python3.13/site-packages/anyio/_backends/_asyncio.py", line 967, in run     result = context.run(func, *args)   File "/Users/nagabhaskar.alaparthi/hackweek-ai-debugger/routers/example_router.py", line 20, in trigger_divide_by_zero_error     return ExampleService.simulate_divide_by_zero_error()            ~~~~~~~~~~~~~~~~~~~~~~~~~~~~~~~~~~~~~~~~~~~~^^   File "/Users/nagabhaskar.alaparthi/hackweek-ai-debugger/services/example_service.py", line 23, in simulate_divide_by_zero_error     raise RuntimeError("A division by zero error occurred.") from e RuntimeError: A division by zero error occurred. 
2025-04-21 12:32:35,876 - ERROR - Unhandled exception: Traceback (most recent call last):   File "/Users/nagabhaskar.alaparthi/hackweek-ai-debugger/services/example_service.py", line 21, in simulate_divide_by_zero_error     result = 1 / 0              ~~^~~ ZeroDivisionError: division by zero  The above exception was the direct cause of the following exception:  Traceback (most recent call last):   File "/Users/nagabhaskar.alaparthi/hackweek-ai-debugger/venv/lib/python3.13/site-packages/starlette/middleware/errors.py", line 165, in __call__     await self.app(scope, receive, _send)   File "/Users/nagabhaskar.alaparthi/hackweek-ai-debugger/venv/lib/python3.13/site-packages/starlette/middleware/exceptions.py", line 62, in __call__     await wrap_app_handling_exceptions(self.app, conn)(scope, receive, send)   File "/Users/nagabhaskar.alaparthi/hackweek-ai-debugger/venv/lib/python3.13/site-packages/starlette/_exception_handler.py", line 53, in wrapped_app     raise exc   File "/Users/nagabhaskar.alaparthi/hackweek-ai-debugger/venv/lib/python3.13/site-packages/starlette/_exception_handler.py", line 42, in wrapped_app     await app(scope, receive, sender)   File "/Users/nagabhaskar.alaparthi/hackweek-ai-debugger/venv/lib/python3.13/site-packages/starlette/routing.py", line 714, in __call__     await self.middleware_stack(scope, receive, send)   File "/Users/nagabhaskar.alaparthi/hackweek-ai-debugger/venv/lib/python3.13/site-packages/starlette/routing.py", line 734, in app     await route.handle(scope, receive, send)   File "/Users/nagabhaskar.alaparthi/hackweek-ai-debugger/venv/lib/python3.13/site-packages/starlette/routing.py", line 288, in handle     await self.app(scope, receive, send)   File "/Users/nagabhaskar.alaparthi/hackweek-ai-debugger/venv/lib/python3.13/site-packages/starlette/routing.py", line 76, in app     await wrap_app_handling_exceptions(app, request)(scope, receive, send)   File "/Users/nagabhaskar.alaparthi/hackweek-ai-debugger/venv/lib/python3.13/site-packages/starlette/_exception_handler.py", line 53, in wrapped_app     raise exc   File "/Users/nagabhaskar.alaparthi/hackweek-ai-debugger/venv/lib/python3.13/site-packages/starlette/_exception_handler.py", line 42, in wrapped_app     await app(scope, receive, sender)   File "/Users/nagabhaskar.alaparthi/hackweek-ai-debugger/venv/lib/python3.13/site-packages/starlette/routing.py", line 73, in app     response = await f(request)                ^^^^^^^^^^^^^^^^   File "/Users/nagabhaskar.alaparthi/hackweek-ai-debugger/venv/lib/python3.13/site-packages/fastapi/routing.py", line 301, in app     raw_response = await run_endpoint_function(                    ^^^^^^^^^^^^^^^^^^^^^^^^^^^^     ...<3 lines>...     )     ^   File "/Users/nagabhaskar.alaparthi/hackweek-ai-debugger/venv/lib/python3.13/site-packages/fastapi/routing.py", line 214, in run_endpoint_function     return await run_in_threadpool(dependant.call, **values)            ^^^^^^^^^^^^^^^^^^^^^^^^^^^^^^^^^^^^^^^^^^^^^^^^^   File "/Users/nagabhaskar.alaparthi/hackweek-ai-debugger/venv/lib/python3.13/site-packages/starlette/concurrency.py", line 37, in run_in_threadpool     return await anyio.to_thread.run_sync(func)            ^^^^^^^^^^^^^^^^^^^^^^^^^^^^^^^^^^^^   File "/Users/nagabhaskar.alaparthi/hackweek-ai-debugger/venv/lib/python3.13/site-packages/anyio/to_thread.py", line 56, in run_sync     return await get_async_backend().run_sync_in_worker_thread(            ^^^^^^^^^^^^^^^^^^^^^^^^^^^^^^^^^^^^^^^^^^^^^^^^^^^^         func, args, abandon_on_cancel=abandon_on_cancel, limiter=limiter         ^^^^^^^^^^^^^^^^^^^^^^^^^^^^^^^^^^^^^^^^^^^^^^^^^^^^^^^^^^^^^^^^     )     ^   File "/Users/nagabhaskar.alaparthi/hackweek-ai-debugger/venv/lib/python3.13/site-packages/anyio/_backends/_asyncio.py", line 2470, in run_sync_in_worker_thread     return await future            ^^^^^^^^^^^^   File "/Users/nagabhaskar.alaparthi/hackweek-ai-debugger/venv/lib/python3.13/site-packages/anyio/_backends/_asyncio.py", line 967, in run     result = context.run(func, *args)   File "/Users/nagabhaskar.alaparthi/hackweek-ai-debugger/routers/example_router.py", line 20, in trigger_divide_by_zero_error     return ExampleService.simulate_divide_by_zero_error()            ~~~~~~~~~~~~~~~~~~~~~~~~~~~~~~~~~~~~~~~~~~~~^^   File "/Users/nagabhaskar.alaparthi/hackweek-ai-debugger/services/example_service.py", line 23, in simulate_divide_by_zero_error     raise RuntimeError("A division by zero error occurred.") from e RuntimeError: A division by zero error occurred. 
2025-04-21 12:33:39,397 - ERROR - Unhandled exception: Traceback (most recent call last):   File "/Users/nagabhaskar.alaparthi/hackweek-ai-debugger/services/example_service.py", line 21, in simulate_divide_by_zero_error     result = 1 / 0              ~~^~~ ZeroDivisionError: division by zero  The above exception was the direct cause of the following exception:  Traceback (most recent call last):   File "/Users/nagabhaskar.alaparthi/hackweek-ai-debugger/venv/lib/python3.13/site-packages/starlette/middleware/errors.py", line 165, in __call__     await self.app(scope, receive, _send)   File "/Users/nagabhaskar.alaparthi/hackweek-ai-debugger/venv/lib/python3.13/site-packages/starlette/middleware/exceptions.py", line 62, in __call__     await wrap_app_handling_exceptions(self.app, conn)(scope, receive, send)   File "/Users/nagabhaskar.alaparthi/hackweek-ai-debugger/venv/lib/python3.13/site-packages/starlette/_exception_handler.py", line 53, in wrapped_app     raise exc   File "/Users/nagabhaskar.alaparthi/hackweek-ai-debugger/venv/lib/python3.13/site-packages/starlette/_exception_handler.py", line 42, in wrapped_app     await app(scope, receive, sender)   File "/Users/nagabhaskar.alaparthi/hackweek-ai-debugger/venv/lib/python3.13/site-packages/starlette/routing.py", line 714, in __call__     await self.middleware_stack(scope, receive, send)   File "/Users/nagabhaskar.alaparthi/hackweek-ai-debugger/venv/lib/python3.13/site-packages/starlette/routing.py", line 734, in app     await route.handle(scope, receive, send)   File "/Users/nagabhaskar.alaparthi/hackweek-ai-debugger/venv/lib/python3.13/site-packages/starlette/routing.py", line 288, in handle     await self.app(scope, receive, send)   File "/Users/nagabhaskar.alaparthi/hackweek-ai-debugger/venv/lib/python3.13/site-packages/starlette/routing.py", line 76, in app     await wrap_app_handling_exceptions(app, request)(scope, receive, send)   File "/Users/nagabhaskar.alaparthi/hackweek-ai-debugger/venv/lib/python3.13/site-packages/starlette/_exception_handler.py", line 53, in wrapped_app     raise exc   File "/Users/nagabhaskar.alaparthi/hackweek-ai-debugger/venv/lib/python3.13/site-packages/starlette/_exception_handler.py", line 42, in wrapped_app     await app(scope, receive, sender)   File "/Users/nagabhaskar.alaparthi/hackweek-ai-debugger/venv/lib/python3.13/site-packages/starlette/routing.py", line 73, in app     response = await f(request)                ^^^^^^^^^^^^^^^^   File "/Users/nagabhaskar.alaparthi/hackweek-ai-debugger/venv/lib/python3.13/site-packages/fastapi/routing.py", line 301, in app     raw_response = await run_endpoint_function(                    ^^^^^^^^^^^^^^^^^^^^^^^^^^^^     ...<3 lines>...     )     ^   File "/Users/nagabhaskar.alaparthi/hackweek-ai-debugger/venv/lib/python3.13/site-packages/fastapi/routing.py", line 214, in run_endpoint_function     return await run_in_threadpool(dependant.call, **values)            ^^^^^^^^^^^^^^^^^^^^^^^^^^^^^^^^^^^^^^^^^^^^^^^^^   File "/Users/nagabhaskar.alaparthi/hackweek-ai-debugger/venv/lib/python3.13/site-packages/starlette/concurrency.py", line 37, in run_in_threadpool     return await anyio.to_thread.run_sync(func)            ^^^^^^^^^^^^^^^^^^^^^^^^^^^^^^^^^^^^   File "/Users/nagabhaskar.alaparthi/hackweek-ai-debugger/venv/lib/python3.13/site-packages/anyio/to_thread.py", line 56, in run_sync     return await get_async_backend().run_sync_in_worker_thread(            ^^^^^^^^^^^^^^^^^^^^^^^^^^^^^^^^^^^^^^^^^^^^^^^^^^^^         func, args, abandon_on_cancel=abandon_on_cancel, limiter=limiter         ^^^^^^^^^^^^^^^^^^^^^^^^^^^^^^^^^^^^^^^^^^^^^^^^^^^^^^^^^^^^^^^^     )     ^   File "/Users/nagabhaskar.alaparthi/hackweek-ai-debugger/venv/lib/python3.13/site-packages/anyio/_backends/_asyncio.py", line 2470, in run_sync_in_worker_thread     return await future            ^^^^^^^^^^^^   File "/Users/nagabhaskar.alaparthi/hackweek-ai-debugger/venv/lib/python3.13/site-packages/anyio/_backends/_asyncio.py", line 967, in run     result = context.run(func, *args)   File "/Users/nagabhaskar.alaparthi/hackweek-ai-debugger/routers/example_router.py", line 20, in trigger_divide_by_zero_error     return ExampleService.simulate_divide_by_zero_error()            ~~~~~~~~~~~~~~~~~~~~~~~~~~~~~~~~~~~~~~~~~~~~^^   File "/Users/nagabhaskar.alaparthi/hackweek-ai-debugger/services/example_service.py", line 23, in simulate_divide_by_zero_error     raise RuntimeError("A division by zero error occurred.") from e RuntimeError: A division by zero error occurred. 
2025-04-21 12:34:43,742 - ERROR - Unhandled exception: Traceback (most recent call last):   File "/Users/nagabhaskar.alaparthi/hackweek-ai-debugger/services/example_service.py", line 21, in simulate_divide_by_zero_error     result = 1 / 0              ~~^~~ ZeroDivisionError: division by zero  The above exception was the direct cause of the following exception:  Traceback (most recent call last):   File "/Users/nagabhaskar.alaparthi/hackweek-ai-debugger/venv/lib/python3.13/site-packages/starlette/middleware/errors.py", line 165, in __call__     await self.app(scope, receive, _send)   File "/Users/nagabhaskar.alaparthi/hackweek-ai-debugger/venv/lib/python3.13/site-packages/starlette/middleware/exceptions.py", line 62, in __call__     await wrap_app_handling_exceptions(self.app, conn)(scope, receive, send)   File "/Users/nagabhaskar.alaparthi/hackweek-ai-debugger/venv/lib/python3.13/site-packages/starlette/_exception_handler.py", line 53, in wrapped_app     raise exc   File "/Users/nagabhaskar.alaparthi/hackweek-ai-debugger/venv/lib/python3.13/site-packages/starlette/_exception_handler.py", line 42, in wrapped_app     await app(scope, receive, sender)   File "/Users/nagabhaskar.alaparthi/hackweek-ai-debugger/venv/lib/python3.13/site-packages/starlette/routing.py", line 714, in __call__     await self.middleware_stack(scope, receive, send)   File "/Users/nagabhaskar.alaparthi/hackweek-ai-debugger/venv/lib/python3.13/site-packages/starlette/routing.py", line 734, in app     await route.handle(scope, receive, send)   File "/Users/nagabhaskar.alaparthi/hackweek-ai-debugger/venv/lib/python3.13/site-packages/starlette/routing.py", line 288, in handle     await self.app(scope, receive, send)   File "/Users/nagabhaskar.alaparthi/hackweek-ai-debugger/venv/lib/python3.13/site-packages/starlette/routing.py", line 76, in app     await wrap_app_handling_exceptions(app, request)(scope, receive, send)   File "/Users/nagabhaskar.alaparthi/hackweek-ai-debugger/venv/lib/python3.13/site-packages/starlette/_exception_handler.py", line 53, in wrapped_app     raise exc   File "/Users/nagabhaskar.alaparthi/hackweek-ai-debugger/venv/lib/python3.13/site-packages/starlette/_exception_handler.py", line 42, in wrapped_app     await app(scope, receive, sender)   File "/Users/nagabhaskar.alaparthi/hackweek-ai-debugger/venv/lib/python3.13/site-packages/starlette/routing.py", line 73, in app     response = await f(request)                ^^^^^^^^^^^^^^^^   File "/Users/nagabhaskar.alaparthi/hackweek-ai-debugger/venv/lib/python3.13/site-packages/fastapi/routing.py", line 301, in app     raw_response = await run_endpoint_function(                    ^^^^^^^^^^^^^^^^^^^^^^^^^^^^     ...<3 lines>...     )     ^   File "/Users/nagabhaskar.alaparthi/hackweek-ai-debugger/venv/lib/python3.13/site-packages/fastapi/routing.py", line 214, in run_endpoint_function     return await run_in_threadpool(dependant.call, **values)            ^^^^^^^^^^^^^^^^^^^^^^^^^^^^^^^^^^^^^^^^^^^^^^^^^   File "/Users/nagabhaskar.alaparthi/hackweek-ai-debugger/venv/lib/python3.13/site-packages/starlette/concurrency.py", line 37, in run_in_threadpool     return await anyio.to_thread.run_sync(func)            ^^^^^^^^^^^^^^^^^^^^^^^^^^^^^^^^^^^^   File "/Users/nagabhaskar.alaparthi/hackweek-ai-debugger/venv/lib/python3.13/site-packages/anyio/to_thread.py", line 56, in run_sync     return await get_async_backend().run_sync_in_worker_thread(            ^^^^^^^^^^^^^^^^^^^^^^^^^^^^^^^^^^^^^^^^^^^^^^^^^^^^         func, args, abandon_on_cancel=abandon_on_cancel, limiter=limiter         ^^^^^^^^^^^^^^^^^^^^^^^^^^^^^^^^^^^^^^^^^^^^^^^^^^^^^^^^^^^^^^^^     )     ^   File "/Users/nagabhaskar.alaparthi/hackweek-ai-debugger/venv/lib/python3.13/site-packages/anyio/_backends/_asyncio.py", line 2470, in run_sync_in_worker_thread     return await future            ^^^^^^^^^^^^   File "/Users/nagabhaskar.alaparthi/hackweek-ai-debugger/venv/lib/python3.13/site-packages/anyio/_backends/_asyncio.py", line 967, in run     result = context.run(func, *args)   File "/Users/nagabhaskar.alaparthi/hackweek-ai-debugger/routers/example_router.py", line 20, in trigger_divide_by_zero_error     return ExampleService.simulate_divide_by_zero_error()            ~~~~~~~~~~~~~~~~~~~~~~~~~~~~~~~~~~~~~~~~~~~~^^   File "/Users/nagabhaskar.alaparthi/hackweek-ai-debugger/services/example_service.py", line 23, in simulate_divide_by_zero_error     raise RuntimeError("A division by zero error occurred.") from e RuntimeError: A division by zero error occurred. 
2025-04-21 12:42:12,155 - ERROR - Unhandled exception: Traceback (most recent call last):   File "/Users/nagabhaskar.alaparthi/hackweek-ai-debugger/services/example_service.py", line 21, in simulate_divide_by_zero_error     result = 1 / 0              ~~^~~ ZeroDivisionError: division by zero  The above exception was the direct cause of the following exception:  Traceback (most recent call last):   File "/Users/nagabhaskar.alaparthi/hackweek-ai-debugger/venv/lib/python3.13/site-packages/starlette/middleware/errors.py", line 165, in __call__     await self.app(scope, receive, _send)   File "/Users/nagabhaskar.alaparthi/hackweek-ai-debugger/venv/lib/python3.13/site-packages/starlette/middleware/exceptions.py", line 62, in __call__     await wrap_app_handling_exceptions(self.app, conn)(scope, receive, send)   File "/Users/nagabhaskar.alaparthi/hackweek-ai-debugger/venv/lib/python3.13/site-packages/starlette/_exception_handler.py", line 53, in wrapped_app     raise exc   File "/Users/nagabhaskar.alaparthi/hackweek-ai-debugger/venv/lib/python3.13/site-packages/starlette/_exception_handler.py", line 42, in wrapped_app     await app(scope, receive, sender)   File "/Users/nagabhaskar.alaparthi/hackweek-ai-debugger/venv/lib/python3.13/site-packages/starlette/routing.py", line 714, in __call__     await self.middleware_stack(scope, receive, send)   File "/Users/nagabhaskar.alaparthi/hackweek-ai-debugger/venv/lib/python3.13/site-packages/starlette/routing.py", line 734, in app     await route.handle(scope, receive, send)   File "/Users/nagabhaskar.alaparthi/hackweek-ai-debugger/venv/lib/python3.13/site-packages/starlette/routing.py", line 288, in handle     await self.app(scope, receive, send)   File "/Users/nagabhaskar.alaparthi/hackweek-ai-debugger/venv/lib/python3.13/site-packages/starlette/routing.py", line 76, in app     await wrap_app_handling_exceptions(app, request)(scope, receive, send)   File "/Users/nagabhaskar.alaparthi/hackweek-ai-debugger/venv/lib/python3.13/site-packages/starlette/_exception_handler.py", line 53, in wrapped_app     raise exc   File "/Users/nagabhaskar.alaparthi/hackweek-ai-debugger/venv/lib/python3.13/site-packages/starlette/_exception_handler.py", line 42, in wrapped_app     await app(scope, receive, sender)   File "/Users/nagabhaskar.alaparthi/hackweek-ai-debugger/venv/lib/python3.13/site-packages/starlette/routing.py", line 73, in app     response = await f(request)                ^^^^^^^^^^^^^^^^   File "/Users/nagabhaskar.alaparthi/hackweek-ai-debugger/venv/lib/python3.13/site-packages/fastapi/routing.py", line 301, in app     raw_response = await run_endpoint_function(                    ^^^^^^^^^^^^^^^^^^^^^^^^^^^^     ...<3 lines>...     )     ^   File "/Users/nagabhaskar.alaparthi/hackweek-ai-debugger/venv/lib/python3.13/site-packages/fastapi/routing.py", line 214, in run_endpoint_function     return await run_in_threadpool(dependant.call, **values)            ^^^^^^^^^^^^^^^^^^^^^^^^^^^^^^^^^^^^^^^^^^^^^^^^^   File "/Users/nagabhaskar.alaparthi/hackweek-ai-debugger/venv/lib/python3.13/site-packages/starlette/concurrency.py", line 37, in run_in_threadpool     return await anyio.to_thread.run_sync(func)            ^^^^^^^^^^^^^^^^^^^^^^^^^^^^^^^^^^^^   File "/Users/nagabhaskar.alaparthi/hackweek-ai-debugger/venv/lib/python3.13/site-packages/anyio/to_thread.py", line 56, in run_sync     return await get_async_backend().run_sync_in_worker_thread(            ^^^^^^^^^^^^^^^^^^^^^^^^^^^^^^^^^^^^^^^^^^^^^^^^^^^^         func, args, abandon_on_cancel=abandon_on_cancel, limiter=limiter         ^^^^^^^^^^^^^^^^^^^^^^^^^^^^^^^^^^^^^^^^^^^^^^^^^^^^^^^^^^^^^^^^     )     ^   File "/Users/nagabhaskar.alaparthi/hackweek-ai-debugger/venv/lib/python3.13/site-packages/anyio/_backends/_asyncio.py", line 2470, in run_sync_in_worker_thread     return await future            ^^^^^^^^^^^^   File "/Users/nagabhaskar.alaparthi/hackweek-ai-debugger/venv/lib/python3.13/site-packages/anyio/_backends/_asyncio.py", line 967, in run     result = context.run(func, *args)   File "/Users/nagabhaskar.alaparthi/hackweek-ai-debugger/routers/example_router.py", line 20, in trigger_divide_by_zero_error     return ExampleService.simulate_divide_by_zero_error()            ~~~~~~~~~~~~~~~~~~~~~~~~~~~~~~~~~~~~~~~~~~~~^^   File "/Users/nagabhaskar.alaparthi/hackweek-ai-debugger/services/example_service.py", line 23, in simulate_divide_by_zero_error     raise RuntimeError("A division by zero error occurred.") from e RuntimeError: A division by zero error occurred. 
2025-04-21 12:42:13,530 - ERROR - Unhandled exception: Traceback (most recent call last):   File "/Users/nagabhaskar.alaparthi/hackweek-ai-debugger/services/example_service.py", line 21, in simulate_divide_by_zero_error     result = 1 / 0              ~~^~~ ZeroDivisionError: division by zero  The above exception was the direct cause of the following exception:  Traceback (most recent call last):   File "/Users/nagabhaskar.alaparthi/hackweek-ai-debugger/venv/lib/python3.13/site-packages/starlette/middleware/errors.py", line 165, in __call__     await self.app(scope, receive, _send)   File "/Users/nagabhaskar.alaparthi/hackweek-ai-debugger/venv/lib/python3.13/site-packages/starlette/middleware/exceptions.py", line 62, in __call__     await wrap_app_handling_exceptions(self.app, conn)(scope, receive, send)   File "/Users/nagabhaskar.alaparthi/hackweek-ai-debugger/venv/lib/python3.13/site-packages/starlette/_exception_handler.py", line 53, in wrapped_app     raise exc   File "/Users/nagabhaskar.alaparthi/hackweek-ai-debugger/venv/lib/python3.13/site-packages/starlette/_exception_handler.py", line 42, in wrapped_app     await app(scope, receive, sender)   File "/Users/nagabhaskar.alaparthi/hackweek-ai-debugger/venv/lib/python3.13/site-packages/starlette/routing.py", line 714, in __call__     await self.middleware_stack(scope, receive, send)   File "/Users/nagabhaskar.alaparthi/hackweek-ai-debugger/venv/lib/python3.13/site-packages/starlette/routing.py", line 734, in app     await route.handle(scope, receive, send)   File "/Users/nagabhaskar.alaparthi/hackweek-ai-debugger/venv/lib/python3.13/site-packages/starlette/routing.py", line 288, in handle     await self.app(scope, receive, send)   File "/Users/nagabhaskar.alaparthi/hackweek-ai-debugger/venv/lib/python3.13/site-packages/starlette/routing.py", line 76, in app     await wrap_app_handling_exceptions(app, request)(scope, receive, send)   File "/Users/nagabhaskar.alaparthi/hackweek-ai-debugger/venv/lib/python3.13/site-packages/starlette/_exception_handler.py", line 53, in wrapped_app     raise exc   File "/Users/nagabhaskar.alaparthi/hackweek-ai-debugger/venv/lib/python3.13/site-packages/starlette/_exception_handler.py", line 42, in wrapped_app     await app(scope, receive, sender)   File "/Users/nagabhaskar.alaparthi/hackweek-ai-debugger/venv/lib/python3.13/site-packages/starlette/routing.py", line 73, in app     response = await f(request)                ^^^^^^^^^^^^^^^^   File "/Users/nagabhaskar.alaparthi/hackweek-ai-debugger/venv/lib/python3.13/site-packages/fastapi/routing.py", line 301, in app     raw_response = await run_endpoint_function(                    ^^^^^^^^^^^^^^^^^^^^^^^^^^^^     ...<3 lines>...     )     ^   File "/Users/nagabhaskar.alaparthi/hackweek-ai-debugger/venv/lib/python3.13/site-packages/fastapi/routing.py", line 214, in run_endpoint_function     return await run_in_threadpool(dependant.call, **values)            ^^^^^^^^^^^^^^^^^^^^^^^^^^^^^^^^^^^^^^^^^^^^^^^^^   File "/Users/nagabhaskar.alaparthi/hackweek-ai-debugger/venv/lib/python3.13/site-packages/starlette/concurrency.py", line 37, in run_in_threadpool     return await anyio.to_thread.run_sync(func)            ^^^^^^^^^^^^^^^^^^^^^^^^^^^^^^^^^^^^   File "/Users/nagabhaskar.alaparthi/hackweek-ai-debugger/venv/lib/python3.13/site-packages/anyio/to_thread.py", line 56, in run_sync     return await get_async_backend().run_sync_in_worker_thread(            ^^^^^^^^^^^^^^^^^^^^^^^^^^^^^^^^^^^^^^^^^^^^^^^^^^^^         func, args, abandon_on_cancel=abandon_on_cancel, limiter=limiter         ^^^^^^^^^^^^^^^^^^^^^^^^^^^^^^^^^^^^^^^^^^^^^^^^^^^^^^^^^^^^^^^^     )     ^   File "/Users/nagabhaskar.alaparthi/hackweek-ai-debugger/venv/lib/python3.13/site-packages/anyio/_backends/_asyncio.py", line 2470, in run_sync_in_worker_thread     return await future            ^^^^^^^^^^^^   File "/Users/nagabhaskar.alaparthi/hackweek-ai-debugger/venv/lib/python3.13/site-packages/anyio/_backends/_asyncio.py", line 967, in run     result = context.run(func, *args)   File "/Users/nagabhaskar.alaparthi/hackweek-ai-debugger/routers/example_router.py", line 20, in trigger_divide_by_zero_error     return ExampleService.simulate_divide_by_zero_error()            ~~~~~~~~~~~~~~~~~~~~~~~~~~~~~~~~~~~~~~~~~~~~^^   File "/Users/nagabhaskar.alaparthi/hackweek-ai-debugger/services/example_service.py", line 23, in simulate_divide_by_zero_error     raise RuntimeError("A division by zero error occurred.") from e RuntimeError: A division by zero error occurred. 
2025-04-21 12:45:07,659 - ERROR - Unhandled exception: Traceback (most recent call last):   File "/Users/nagabhaskar.alaparthi/hackweek-ai-debugger/services/example_service.py", line 21, in simulate_divide_by_zero_error     result = 1 / 0              ~~^~~ ZeroDivisionError: division by zero  The above exception was the direct cause of the following exception:  Traceback (most recent call last):   File "/Users/nagabhaskar.alaparthi/hackweek-ai-debugger/venv/lib/python3.13/site-packages/starlette/middleware/errors.py", line 165, in __call__     await self.app(scope, receive, _send)   File "/Users/nagabhaskar.alaparthi/hackweek-ai-debugger/venv/lib/python3.13/site-packages/starlette/middleware/exceptions.py", line 62, in __call__     await wrap_app_handling_exceptions(self.app, conn)(scope, receive, send)   File "/Users/nagabhaskar.alaparthi/hackweek-ai-debugger/venv/lib/python3.13/site-packages/starlette/_exception_handler.py", line 53, in wrapped_app     raise exc   File "/Users/nagabhaskar.alaparthi/hackweek-ai-debugger/venv/lib/python3.13/site-packages/starlette/_exception_handler.py", line 42, in wrapped_app     await app(scope, receive, sender)   File "/Users/nagabhaskar.alaparthi/hackweek-ai-debugger/venv/lib/python3.13/site-packages/starlette/routing.py", line 714, in __call__     await self.middleware_stack(scope, receive, send)   File "/Users/nagabhaskar.alaparthi/hackweek-ai-debugger/venv/lib/python3.13/site-packages/starlette/routing.py", line 734, in app     await route.handle(scope, receive, send)   File "/Users/nagabhaskar.alaparthi/hackweek-ai-debugger/venv/lib/python3.13/site-packages/starlette/routing.py", line 288, in handle     await self.app(scope, receive, send)   File "/Users/nagabhaskar.alaparthi/hackweek-ai-debugger/venv/lib/python3.13/site-packages/starlette/routing.py", line 76, in app     await wrap_app_handling_exceptions(app, request)(scope, receive, send)   File "/Users/nagabhaskar.alaparthi/hackweek-ai-debugger/venv/lib/python3.13/site-packages/starlette/_exception_handler.py", line 53, in wrapped_app     raise exc   File "/Users/nagabhaskar.alaparthi/hackweek-ai-debugger/venv/lib/python3.13/site-packages/starlette/_exception_handler.py", line 42, in wrapped_app     await app(scope, receive, sender)   File "/Users/nagabhaskar.alaparthi/hackweek-ai-debugger/venv/lib/python3.13/site-packages/starlette/routing.py", line 73, in app     response = await f(request)                ^^^^^^^^^^^^^^^^   File "/Users/nagabhaskar.alaparthi/hackweek-ai-debugger/venv/lib/python3.13/site-packages/fastapi/routing.py", line 301, in app     raw_response = await run_endpoint_function(                    ^^^^^^^^^^^^^^^^^^^^^^^^^^^^     ...<3 lines>...     )     ^   File "/Users/nagabhaskar.alaparthi/hackweek-ai-debugger/venv/lib/python3.13/site-packages/fastapi/routing.py", line 214, in run_endpoint_function     return await run_in_threadpool(dependant.call, **values)            ^^^^^^^^^^^^^^^^^^^^^^^^^^^^^^^^^^^^^^^^^^^^^^^^^   File "/Users/nagabhaskar.alaparthi/hackweek-ai-debugger/venv/lib/python3.13/site-packages/starlette/concurrency.py", line 37, in run_in_threadpool     return await anyio.to_thread.run_sync(func)            ^^^^^^^^^^^^^^^^^^^^^^^^^^^^^^^^^^^^   File "/Users/nagabhaskar.alaparthi/hackweek-ai-debugger/venv/lib/python3.13/site-packages/anyio/to_thread.py", line 56, in run_sync     return await get_async_backend().run_sync_in_worker_thread(            ^^^^^^^^^^^^^^^^^^^^^^^^^^^^^^^^^^^^^^^^^^^^^^^^^^^^         func, args, abandon_on_cancel=abandon_on_cancel, limiter=limiter         ^^^^^^^^^^^^^^^^^^^^^^^^^^^^^^^^^^^^^^^^^^^^^^^^^^^^^^^^^^^^^^^^     )     ^   File "/Users/nagabhaskar.alaparthi/hackweek-ai-debugger/venv/lib/python3.13/site-packages/anyio/_backends/_asyncio.py", line 2470, in run_sync_in_worker_thread     return await future            ^^^^^^^^^^^^   File "/Users/nagabhaskar.alaparthi/hackweek-ai-debugger/venv/lib/python3.13/site-packages/anyio/_backends/_asyncio.py", line 967, in run     result = context.run(func, *args)   File "/Users/nagabhaskar.alaparthi/hackweek-ai-debugger/routers/example_router.py", line 20, in trigger_divide_by_zero_error     return ExampleService.simulate_divide_by_zero_error()            ~~~~~~~~~~~~~~~~~~~~~~~~~~~~~~~~~~~~~~~~~~~~^^   File "/Users/nagabhaskar.alaparthi/hackweek-ai-debugger/services/example_service.py", line 23, in simulate_divide_by_zero_error     raise RuntimeError("A division by zero error occurred.") from e RuntimeError: A division by zero error occurred. 
2025-04-21 12:46:27,101 - ERROR - Unhandled exception: Traceback (most recent call last):   File "/Users/nagabhaskar.alaparthi/hackweek-ai-debugger/services/example_service.py", line 21, in simulate_divide_by_zero_error     result = 1 / 0              ~~^~~ ZeroDivisionError: division by zero  The above exception was the direct cause of the following exception:  Traceback (most recent call last):   File "/Users/nagabhaskar.alaparthi/hackweek-ai-debugger/venv/lib/python3.13/site-packages/starlette/middleware/errors.py", line 165, in __call__     await self.app(scope, receive, _send)   File "/Users/nagabhaskar.alaparthi/hackweek-ai-debugger/venv/lib/python3.13/site-packages/starlette/middleware/exceptions.py", line 62, in __call__     await wrap_app_handling_exceptions(self.app, conn)(scope, receive, send)   File "/Users/nagabhaskar.alaparthi/hackweek-ai-debugger/venv/lib/python3.13/site-packages/starlette/_exception_handler.py", line 53, in wrapped_app     raise exc   File "/Users/nagabhaskar.alaparthi/hackweek-ai-debugger/venv/lib/python3.13/site-packages/starlette/_exception_handler.py", line 42, in wrapped_app     await app(scope, receive, sender)   File "/Users/nagabhaskar.alaparthi/hackweek-ai-debugger/venv/lib/python3.13/site-packages/starlette/routing.py", line 714, in __call__     await self.middleware_stack(scope, receive, send)   File "/Users/nagabhaskar.alaparthi/hackweek-ai-debugger/venv/lib/python3.13/site-packages/starlette/routing.py", line 734, in app     await route.handle(scope, receive, send)   File "/Users/nagabhaskar.alaparthi/hackweek-ai-debugger/venv/lib/python3.13/site-packages/starlette/routing.py", line 288, in handle     await self.app(scope, receive, send)   File "/Users/nagabhaskar.alaparthi/hackweek-ai-debugger/venv/lib/python3.13/site-packages/starlette/routing.py", line 76, in app     await wrap_app_handling_exceptions(app, request)(scope, receive, send)   File "/Users/nagabhaskar.alaparthi/hackweek-ai-debugger/venv/lib/python3.13/site-packages/starlette/_exception_handler.py", line 53, in wrapped_app     raise exc   File "/Users/nagabhaskar.alaparthi/hackweek-ai-debugger/venv/lib/python3.13/site-packages/starlette/_exception_handler.py", line 42, in wrapped_app     await app(scope, receive, sender)   File "/Users/nagabhaskar.alaparthi/hackweek-ai-debugger/venv/lib/python3.13/site-packages/starlette/routing.py", line 73, in app     response = await f(request)                ^^^^^^^^^^^^^^^^   File "/Users/nagabhaskar.alaparthi/hackweek-ai-debugger/venv/lib/python3.13/site-packages/fastapi/routing.py", line 301, in app     raw_response = await run_endpoint_function(                    ^^^^^^^^^^^^^^^^^^^^^^^^^^^^     ...<3 lines>...     )     ^   File "/Users/nagabhaskar.alaparthi/hackweek-ai-debugger/venv/lib/python3.13/site-packages/fastapi/routing.py", line 214, in run_endpoint_function     return await run_in_threadpool(dependant.call, **values)            ^^^^^^^^^^^^^^^^^^^^^^^^^^^^^^^^^^^^^^^^^^^^^^^^^   File "/Users/nagabhaskar.alaparthi/hackweek-ai-debugger/venv/lib/python3.13/site-packages/starlette/concurrency.py", line 37, in run_in_threadpool     return await anyio.to_thread.run_sync(func)            ^^^^^^^^^^^^^^^^^^^^^^^^^^^^^^^^^^^^   File "/Users/nagabhaskar.alaparthi/hackweek-ai-debugger/venv/lib/python3.13/site-packages/anyio/to_thread.py", line 56, in run_sync     return await get_async_backend().run_sync_in_worker_thread(            ^^^^^^^^^^^^^^^^^^^^^^^^^^^^^^^^^^^^^^^^^^^^^^^^^^^^         func, args, abandon_on_cancel=abandon_on_cancel, limiter=limiter         ^^^^^^^^^^^^^^^^^^^^^^^^^^^^^^^^^^^^^^^^^^^^^^^^^^^^^^^^^^^^^^^^     )     ^   File "/Users/nagabhaskar.alaparthi/hackweek-ai-debugger/venv/lib/python3.13/site-packages/anyio/_backends/_asyncio.py", line 2470, in run_sync_in_worker_thread     return await future            ^^^^^^^^^^^^   File "/Users/nagabhaskar.alaparthi/hackweek-ai-debugger/venv/lib/python3.13/site-packages/anyio/_backends/_asyncio.py", line 967, in run     result = context.run(func, *args)   File "/Users/nagabhaskar.alaparthi/hackweek-ai-debugger/routers/example_router.py", line 20, in trigger_divide_by_zero_error     return ExampleService.simulate_divide_by_zero_error()            ~~~~~~~~~~~~~~~~~~~~~~~~~~~~~~~~~~~~~~~~~~~~^^   File "/Users/nagabhaskar.alaparthi/hackweek-ai-debugger/services/example_service.py", line 23, in simulate_divide_by_zero_error     raise RuntimeError("A division by zero error occurred.") from e RuntimeError: A division by zero error occurred. 
2025-04-21 12:56:43,634 - ERROR - Unhandled exception: Traceback (most recent call last):   File "/Users/nagabhaskar.alaparthi/hackweek-ai-debugger/services/example_service.py", line 21, in simulate_divide_by_zero_error     result = 1 / 0              ~~^~~ ZeroDivisionError: division by zero  The above exception was the direct cause of the following exception:  Traceback (most recent call last):   File "/Users/nagabhaskar.alaparthi/hackweek-ai-debugger/venv/lib/python3.13/site-packages/starlette/middleware/errors.py", line 165, in __call__     await self.app(scope, receive, _send)   File "/Users/nagabhaskar.alaparthi/hackweek-ai-debugger/venv/lib/python3.13/site-packages/starlette/middleware/exceptions.py", line 62, in __call__     await wrap_app_handling_exceptions(self.app, conn)(scope, receive, send)   File "/Users/nagabhaskar.alaparthi/hackweek-ai-debugger/venv/lib/python3.13/site-packages/starlette/_exception_handler.py", line 53, in wrapped_app     raise exc   File "/Users/nagabhaskar.alaparthi/hackweek-ai-debugger/venv/lib/python3.13/site-packages/starlette/_exception_handler.py", line 42, in wrapped_app     await app(scope, receive, sender)   File "/Users/nagabhaskar.alaparthi/hackweek-ai-debugger/venv/lib/python3.13/site-packages/starlette/routing.py", line 714, in __call__     await self.middleware_stack(scope, receive, send)   File "/Users/nagabhaskar.alaparthi/hackweek-ai-debugger/venv/lib/python3.13/site-packages/starlette/routing.py", line 734, in app     await route.handle(scope, receive, send)   File "/Users/nagabhaskar.alaparthi/hackweek-ai-debugger/venv/lib/python3.13/site-packages/starlette/routing.py", line 288, in handle     await self.app(scope, receive, send)   File "/Users/nagabhaskar.alaparthi/hackweek-ai-debugger/venv/lib/python3.13/site-packages/starlette/routing.py", line 76, in app     await wrap_app_handling_exceptions(app, request)(scope, receive, send)   File "/Users/nagabhaskar.alaparthi/hackweek-ai-debugger/venv/lib/python3.13/site-packages/starlette/_exception_handler.py", line 53, in wrapped_app     raise exc   File "/Users/nagabhaskar.alaparthi/hackweek-ai-debugger/venv/lib/python3.13/site-packages/starlette/_exception_handler.py", line 42, in wrapped_app     await app(scope, receive, sender)   File "/Users/nagabhaskar.alaparthi/hackweek-ai-debugger/venv/lib/python3.13/site-packages/starlette/routing.py", line 73, in app     response = await f(request)                ^^^^^^^^^^^^^^^^   File "/Users/nagabhaskar.alaparthi/hackweek-ai-debugger/venv/lib/python3.13/site-packages/fastapi/routing.py", line 301, in app     raw_response = await run_endpoint_function(                    ^^^^^^^^^^^^^^^^^^^^^^^^^^^^     ...<3 lines>...     )     ^   File "/Users/nagabhaskar.alaparthi/hackweek-ai-debugger/venv/lib/python3.13/site-packages/fastapi/routing.py", line 214, in run_endpoint_function     return await run_in_threadpool(dependant.call, **values)            ^^^^^^^^^^^^^^^^^^^^^^^^^^^^^^^^^^^^^^^^^^^^^^^^^   File "/Users/nagabhaskar.alaparthi/hackweek-ai-debugger/venv/lib/python3.13/site-packages/starlette/concurrency.py", line 37, in run_in_threadpool     return await anyio.to_thread.run_sync(func)            ^^^^^^^^^^^^^^^^^^^^^^^^^^^^^^^^^^^^   File "/Users/nagabhaskar.alaparthi/hackweek-ai-debugger/venv/lib/python3.13/site-packages/anyio/to_thread.py", line 56, in run_sync     return await get_async_backend().run_sync_in_worker_thread(            ^^^^^^^^^^^^^^^^^^^^^^^^^^^^^^^^^^^^^^^^^^^^^^^^^^^^         func, args, abandon_on_cancel=abandon_on_cancel, limiter=limiter         ^^^^^^^^^^^^^^^^^^^^^^^^^^^^^^^^^^^^^^^^^^^^^^^^^^^^^^^^^^^^^^^^     )     ^   File "/Users/nagabhaskar.alaparthi/hackweek-ai-debugger/venv/lib/python3.13/site-packages/anyio/_backends/_asyncio.py", line 2470, in run_sync_in_worker_thread     return await future            ^^^^^^^^^^^^   File "/Users/nagabhaskar.alaparthi/hackweek-ai-debugger/venv/lib/python3.13/site-packages/anyio/_backends/_asyncio.py", line 967, in run     result = context.run(func, *args)   File "/Users/nagabhaskar.alaparthi/hackweek-ai-debugger/routers/example_router.py", line 20, in trigger_divide_by_zero_error     return ExampleService.simulate_divide_by_zero_error()            ~~~~~~~~~~~~~~~~~~~~~~~~~~~~~~~~~~~~~~~~~~~~^^   File "/Users/nagabhaskar.alaparthi/hackweek-ai-debugger/services/example_service.py", line 23, in simulate_divide_by_zero_error     raise RuntimeError("A division by zero error occurred.") from e RuntimeError: A division by zero error occurred. 
2025-04-21 12:58:27,751 - ERROR - Unhandled exception: Traceback (most recent call last):   File "/Users/nagabhaskar.alaparthi/hackweek-ai-debugger/services/example_service.py", line 21, in simulate_divide_by_zero_error     result = 1 / 0              ~~^~~ ZeroDivisionError: division by zero  The above exception was the direct cause of the following exception:  Traceback (most recent call last):   File "/Users/nagabhaskar.alaparthi/hackweek-ai-debugger/venv/lib/python3.13/site-packages/starlette/middleware/errors.py", line 165, in __call__     await self.app(scope, receive, _send)   File "/Users/nagabhaskar.alaparthi/hackweek-ai-debugger/venv/lib/python3.13/site-packages/starlette/middleware/exceptions.py", line 62, in __call__     await wrap_app_handling_exceptions(self.app, conn)(scope, receive, send)   File "/Users/nagabhaskar.alaparthi/hackweek-ai-debugger/venv/lib/python3.13/site-packages/starlette/_exception_handler.py", line 53, in wrapped_app     raise exc   File "/Users/nagabhaskar.alaparthi/hackweek-ai-debugger/venv/lib/python3.13/site-packages/starlette/_exception_handler.py", line 42, in wrapped_app     await app(scope, receive, sender)   File "/Users/nagabhaskar.alaparthi/hackweek-ai-debugger/venv/lib/python3.13/site-packages/starlette/routing.py", line 714, in __call__     await self.middleware_stack(scope, receive, send)   File "/Users/nagabhaskar.alaparthi/hackweek-ai-debugger/venv/lib/python3.13/site-packages/starlette/routing.py", line 734, in app     await route.handle(scope, receive, send)   File "/Users/nagabhaskar.alaparthi/hackweek-ai-debugger/venv/lib/python3.13/site-packages/starlette/routing.py", line 288, in handle     await self.app(scope, receive, send)   File "/Users/nagabhaskar.alaparthi/hackweek-ai-debugger/venv/lib/python3.13/site-packages/starlette/routing.py", line 76, in app     await wrap_app_handling_exceptions(app, request)(scope, receive, send)   File "/Users/nagabhaskar.alaparthi/hackweek-ai-debugger/venv/lib/python3.13/site-packages/starlette/_exception_handler.py", line 53, in wrapped_app     raise exc   File "/Users/nagabhaskar.alaparthi/hackweek-ai-debugger/venv/lib/python3.13/site-packages/starlette/_exception_handler.py", line 42, in wrapped_app     await app(scope, receive, sender)   File "/Users/nagabhaskar.alaparthi/hackweek-ai-debugger/venv/lib/python3.13/site-packages/starlette/routing.py", line 73, in app     response = await f(request)                ^^^^^^^^^^^^^^^^   File "/Users/nagabhaskar.alaparthi/hackweek-ai-debugger/venv/lib/python3.13/site-packages/fastapi/routing.py", line 301, in app     raw_response = await run_endpoint_function(                    ^^^^^^^^^^^^^^^^^^^^^^^^^^^^     ...<3 lines>...     )     ^   File "/Users/nagabhaskar.alaparthi/hackweek-ai-debugger/venv/lib/python3.13/site-packages/fastapi/routing.py", line 214, in run_endpoint_function     return await run_in_threadpool(dependant.call, **values)            ^^^^^^^^^^^^^^^^^^^^^^^^^^^^^^^^^^^^^^^^^^^^^^^^^   File "/Users/nagabhaskar.alaparthi/hackweek-ai-debugger/venv/lib/python3.13/site-packages/starlette/concurrency.py", line 37, in run_in_threadpool     return await anyio.to_thread.run_sync(func)            ^^^^^^^^^^^^^^^^^^^^^^^^^^^^^^^^^^^^   File "/Users/nagabhaskar.alaparthi/hackweek-ai-debugger/venv/lib/python3.13/site-packages/anyio/to_thread.py", line 56, in run_sync     return await get_async_backend().run_sync_in_worker_thread(            ^^^^^^^^^^^^^^^^^^^^^^^^^^^^^^^^^^^^^^^^^^^^^^^^^^^^         func, args, abandon_on_cancel=abandon_on_cancel, limiter=limiter         ^^^^^^^^^^^^^^^^^^^^^^^^^^^^^^^^^^^^^^^^^^^^^^^^^^^^^^^^^^^^^^^^     )     ^   File "/Users/nagabhaskar.alaparthi/hackweek-ai-debugger/venv/lib/python3.13/site-packages/anyio/_backends/_asyncio.py", line 2470, in run_sync_in_worker_thread     return await future            ^^^^^^^^^^^^   File "/Users/nagabhaskar.alaparthi/hackweek-ai-debugger/venv/lib/python3.13/site-packages/anyio/_backends/_asyncio.py", line 967, in run     result = context.run(func, *args)   File "/Users/nagabhaskar.alaparthi/hackweek-ai-debugger/routers/example_router.py", line 20, in trigger_divide_by_zero_error     return ExampleService.simulate_divide_by_zero_error()            ~~~~~~~~~~~~~~~~~~~~~~~~~~~~~~~~~~~~~~~~~~~~^^   File "/Users/nagabhaskar.alaparthi/hackweek-ai-debugger/services/example_service.py", line 23, in simulate_divide_by_zero_error     raise RuntimeError("A division by zero error occurred.") from e RuntimeError: A division by zero error occurred. 
2025-04-21 12:59:14,866 - ERROR - Unhandled exception: Traceback (most recent call last):   File "/Users/nagabhaskar.alaparthi/hackweek-ai-debugger/services/example_service.py", line 21, in simulate_divide_by_zero_error     result = 1 / 0              ~~^~~ ZeroDivisionError: division by zero  The above exception was the direct cause of the following exception:  Traceback (most recent call last):   File "/Users/nagabhaskar.alaparthi/hackweek-ai-debugger/venv/lib/python3.13/site-packages/starlette/middleware/errors.py", line 165, in __call__     await self.app(scope, receive, _send)   File "/Users/nagabhaskar.alaparthi/hackweek-ai-debugger/venv/lib/python3.13/site-packages/starlette/middleware/exceptions.py", line 62, in __call__     await wrap_app_handling_exceptions(self.app, conn)(scope, receive, send)   File "/Users/nagabhaskar.alaparthi/hackweek-ai-debugger/venv/lib/python3.13/site-packages/starlette/_exception_handler.py", line 53, in wrapped_app     raise exc   File "/Users/nagabhaskar.alaparthi/hackweek-ai-debugger/venv/lib/python3.13/site-packages/starlette/_exception_handler.py", line 42, in wrapped_app     await app(scope, receive, sender)   File "/Users/nagabhaskar.alaparthi/hackweek-ai-debugger/venv/lib/python3.13/site-packages/starlette/routing.py", line 714, in __call__     await self.middleware_stack(scope, receive, send)   File "/Users/nagabhaskar.alaparthi/hackweek-ai-debugger/venv/lib/python3.13/site-packages/starlette/routing.py", line 734, in app     await route.handle(scope, receive, send)   File "/Users/nagabhaskar.alaparthi/hackweek-ai-debugger/venv/lib/python3.13/site-packages/starlette/routing.py", line 288, in handle     await self.app(scope, receive, send)   File "/Users/nagabhaskar.alaparthi/hackweek-ai-debugger/venv/lib/python3.13/site-packages/starlette/routing.py", line 76, in app     await wrap_app_handling_exceptions(app, request)(scope, receive, send)   File "/Users/nagabhaskar.alaparthi/hackweek-ai-debugger/venv/lib/python3.13/site-packages/starlette/_exception_handler.py", line 53, in wrapped_app     raise exc   File "/Users/nagabhaskar.alaparthi/hackweek-ai-debugger/venv/lib/python3.13/site-packages/starlette/_exception_handler.py", line 42, in wrapped_app     await app(scope, receive, sender)   File "/Users/nagabhaskar.alaparthi/hackweek-ai-debugger/venv/lib/python3.13/site-packages/starlette/routing.py", line 73, in app     response = await f(request)                ^^^^^^^^^^^^^^^^   File "/Users/nagabhaskar.alaparthi/hackweek-ai-debugger/venv/lib/python3.13/site-packages/fastapi/routing.py", line 301, in app     raw_response = await run_endpoint_function(                    ^^^^^^^^^^^^^^^^^^^^^^^^^^^^     ...<3 lines>...     )     ^   File "/Users/nagabhaskar.alaparthi/hackweek-ai-debugger/venv/lib/python3.13/site-packages/fastapi/routing.py", line 214, in run_endpoint_function     return await run_in_threadpool(dependant.call, **values)            ^^^^^^^^^^^^^^^^^^^^^^^^^^^^^^^^^^^^^^^^^^^^^^^^^   File "/Users/nagabhaskar.alaparthi/hackweek-ai-debugger/venv/lib/python3.13/site-packages/starlette/concurrency.py", line 37, in run_in_threadpool     return await anyio.to_thread.run_sync(func)            ^^^^^^^^^^^^^^^^^^^^^^^^^^^^^^^^^^^^   File "/Users/nagabhaskar.alaparthi/hackweek-ai-debugger/venv/lib/python3.13/site-packages/anyio/to_thread.py", line 56, in run_sync     return await get_async_backend().run_sync_in_worker_thread(            ^^^^^^^^^^^^^^^^^^^^^^^^^^^^^^^^^^^^^^^^^^^^^^^^^^^^         func, args, abandon_on_cancel=abandon_on_cancel, limiter=limiter         ^^^^^^^^^^^^^^^^^^^^^^^^^^^^^^^^^^^^^^^^^^^^^^^^^^^^^^^^^^^^^^^^     )     ^   File "/Users/nagabhaskar.alaparthi/hackweek-ai-debugger/venv/lib/python3.13/site-packages/anyio/_backends/_asyncio.py", line 2470, in run_sync_in_worker_thread     return await future            ^^^^^^^^^^^^   File "/Users/nagabhaskar.alaparthi/hackweek-ai-debugger/venv/lib/python3.13/site-packages/anyio/_backends/_asyncio.py", line 967, in run     result = context.run(func, *args)   File "/Users/nagabhaskar.alaparthi/hackweek-ai-debugger/routers/example_router.py", line 20, in trigger_divide_by_zero_error     return ExampleService.simulate_divide_by_zero_error()            ~~~~~~~~~~~~~~~~~~~~~~~~~~~~~~~~~~~~~~~~~~~~^^   File "/Users/nagabhaskar.alaparthi/hackweek-ai-debugger/services/example_service.py", line 23, in simulate_divide_by_zero_error     raise RuntimeError("A division by zero error occurred.") from e RuntimeError: A division by zero error occurred. 
