2025-04-21 12:26:02,015 - INFO - Starting log monitoring for file: application.log
2025-04-21 12:27:33,863 - INFO - Starting log monitoring for file: application.log
2025-04-21 12:27:42,908 - INFO - Error detected: 2025-04-21 12:27:41,985 - ERROR - Unhandled exception: Traceback (most recent call last):   File "/Users/nagabhaskar.alaparthi/hackweek-ai-debugger/services/example_service.py", line 21, in simulate_divide_by_zero_error     result = 1 / 0              ~~^~~ ZeroDivisionError: division by zero  The above exception was the direct cause of the following exception:  Traceback (most recent call last):   File "/Users/nagabhaskar.alaparthi/hackweek-ai-debugger/venv/lib/python3.13/site-packages/starlette/middleware/errors.py", line 165, in __call__     await self.app(scope, receive, _send)   File "/Users/nagabhaskar.alaparthi/hackweek-ai-debugger/venv/lib/python3.13/site-packages/starlette/middleware/exceptions.py", line 62, in __call__     await wrap_app_handling_exceptions(self.app, conn)(scope, receive, send)   File "/Users/nagabhaskar.alaparthi/hackweek-ai-debugger/venv/lib/python3.13/site-packages/starlette/_exception_handler.py", line 53, in wrapped_app     raise exc   File "/Users/nagabhaskar.alaparthi/hackweek-ai-debugger/venv/lib/python3.13/site-packages/starlette/_exception_handler.py", line 42, in wrapped_app     await app(scope, receive, sender)   File "/Users/nagabhaskar.alaparthi/hackweek-ai-debugger/venv/lib/python3.13/site-packages/starlette/routing.py", line 714, in __call__     await self.middleware_stack(scope, receive, send)   File "/Users/nagabhaskar.alaparthi/hackweek-ai-debugger/venv/lib/python3.13/site-packages/starlette/routing.py", line 734, in app     await route.handle(scope, receive, send)   File "/Users/nagabhaskar.alaparthi/hackweek-ai-debugger/venv/lib/python3.13/site-packages/starlette/routing.py", line 288, in handle     await self.app(scope, receive, send)   File "/Users/nagabhaskar.alaparthi/hackweek-ai-debugger/venv/lib/python3.13/site-packages/starlette/routing.py", line 76, in app     await wrap_app_handling_exceptions(app, request)(scope, receive, send)   File "/Users/nagabhaskar.alaparthi/hackweek-ai-debugger/venv/lib/python3.13/site-packages/starlette/_exception_handler.py", line 53, in wrapped_app     raise exc   File "/Users/nagabhaskar.alaparthi/hackweek-ai-debugger/venv/lib/python3.13/site-packages/starlette/_exception_handler.py", line 42, in wrapped_app     await app(scope, receive, sender)   File "/Users/nagabhaskar.alaparthi/hackweek-ai-debugger/venv/lib/python3.13/site-packages/starlette/routing.py", line 73, in app     response = await f(request)                ^^^^^^^^^^^^^^^^   File "/Users/nagabhaskar.alaparthi/hackweek-ai-debugger/venv/lib/python3.13/site-packages/fastapi/routing.py", line 301, in app     raw_response = await run_endpoint_function(                    ^^^^^^^^^^^^^^^^^^^^^^^^^^^^     ...<3 lines>...     )     ^   File "/Users/nagabhaskar.alaparthi/hackweek-ai-debugger/venv/lib/python3.13/site-packages/fastapi/routing.py", line 214, in run_endpoint_function     return await run_in_threadpool(dependant.call, **values)            ^^^^^^^^^^^^^^^^^^^^^^^^^^^^^^^^^^^^^^^^^^^^^^^^^   File "/Users/nagabhaskar.alaparthi/hackweek-ai-debugger/venv/lib/python3.13/site-packages/starlette/concurrency.py", line 37, in run_in_threadpool     return await anyio.to_thread.run_sync(func)            ^^^^^^^^^^^^^^^^^^^^^^^^^^^^^^^^^^^^   File "/Users/nagabhaskar.alaparthi/hackweek-ai-debugger/venv/lib/python3.13/site-packages/anyio/to_thread.py", line 56, in run_sync     return await get_async_backend().run_sync_in_worker_thread(            ^^^^^^^^^^^^^^^^^^^^^^^^^^^^^^^^^^^^^^^^^^^^^^^^^^^^         func, args, abandon_on_cancel=abandon_on_cancel, limiter=limiter         ^^^^^^^^^^^^^^^^^^^^^^^^^^^^^^^^^^^^^^^^^^^^^^^^^^^^^^^^^^^^^^^^     )     ^   File "/Users/nagabhaskar.alaparthi/hackweek-ai-debugger/venv/lib/python3.13/site-packages/anyio/_backends/_asyncio.py", line 2470, in run_sync_in_worker_thread     return await future            ^^^^^^^^^^^^   File "/Users/nagabhaskar.alaparthi/hackweek-ai-debugger/venv/lib/python3.13/site-packages/anyio/_backends/_asyncio.py", line 967, in run     result = context.run(func, *args)   File "/Users/nagabhaskar.alaparthi/hackweek-ai-debugger/routers/example_router.py", line 20, in trigger_divide_by_zero_error     return ExampleService.simulate_divide_by_zero_error()            ~~~~~~~~~~~~~~~~~~~~~~~~~~~~~~~~~~~~~~~~~~~~^^   File "/Users/nagabhaskar.alaparthi/hackweek-ai-debugger/services/example_service.py", line 23, in simulate_divide_by_zero_error     raise RuntimeError("A division by zero error occurred.") from e RuntimeError: A division by zero error occurred.
2025-04-21 12:27:42,908 - INFO - Debugging error: 2025-04-21 12:27:41,985 - ERROR - Unhandled exception: Traceback (most recent call last):   File "/Users/nagabhaskar.alaparthi/hackweek-ai-debugger/services/example_service.py", line 21, in simulate_divide_by_zero_error     result = 1 / 0              ~~^~~ ZeroDivisionError: division by zero  The above exception was the direct cause of the following exception:  Traceback (most recent call last):   File "/Users/nagabhaskar.alaparthi/hackweek-ai-debugger/venv/lib/python3.13/site-packages/starlette/middleware/errors.py", line 165, in __call__     await self.app(scope, receive, _send)   File "/Users/nagabhaskar.alaparthi/hackweek-ai-debugger/venv/lib/python3.13/site-packages/starlette/middleware/exceptions.py", line 62, in __call__     await wrap_app_handling_exceptions(self.app, conn)(scope, receive, send)   File "/Users/nagabhaskar.alaparthi/hackweek-ai-debugger/venv/lib/python3.13/site-packages/starlette/_exception_handler.py", line 53, in wrapped_app     raise exc   File "/Users/nagabhaskar.alaparthi/hackweek-ai-debugger/venv/lib/python3.13/site-packages/starlette/_exception_handler.py", line 42, in wrapped_app     await app(scope, receive, sender)   File "/Users/nagabhaskar.alaparthi/hackweek-ai-debugger/venv/lib/python3.13/site-packages/starlette/routing.py", line 714, in __call__     await self.middleware_stack(scope, receive, send)   File "/Users/nagabhaskar.alaparthi/hackweek-ai-debugger/venv/lib/python3.13/site-packages/starlette/routing.py", line 734, in app     await route.handle(scope, receive, send)   File "/Users/nagabhaskar.alaparthi/hackweek-ai-debugger/venv/lib/python3.13/site-packages/starlette/routing.py", line 288, in handle     await self.app(scope, receive, send)   File "/Users/nagabhaskar.alaparthi/hackweek-ai-debugger/venv/lib/python3.13/site-packages/starlette/routing.py", line 76, in app     await wrap_app_handling_exceptions(app, request)(scope, receive, send)   File "/Users/nagabhaskar.alaparthi/hackweek-ai-debugger/venv/lib/python3.13/site-packages/starlette/_exception_handler.py", line 53, in wrapped_app     raise exc   File "/Users/nagabhaskar.alaparthi/hackweek-ai-debugger/venv/lib/python3.13/site-packages/starlette/_exception_handler.py", line 42, in wrapped_app     await app(scope, receive, sender)   File "/Users/nagabhaskar.alaparthi/hackweek-ai-debugger/venv/lib/python3.13/site-packages/starlette/routing.py", line 73, in app     response = await f(request)                ^^^^^^^^^^^^^^^^   File "/Users/nagabhaskar.alaparthi/hackweek-ai-debugger/venv/lib/python3.13/site-packages/fastapi/routing.py", line 301, in app     raw_response = await run_endpoint_function(                    ^^^^^^^^^^^^^^^^^^^^^^^^^^^^     ...<3 lines>...     )     ^   File "/Users/nagabhaskar.alaparthi/hackweek-ai-debugger/venv/lib/python3.13/site-packages/fastapi/routing.py", line 214, in run_endpoint_function     return await run_in_threadpool(dependant.call, **values)            ^^^^^^^^^^^^^^^^^^^^^^^^^^^^^^^^^^^^^^^^^^^^^^^^^   File "/Users/nagabhaskar.alaparthi/hackweek-ai-debugger/venv/lib/python3.13/site-packages/starlette/concurrency.py", line 37, in run_in_threadpool     return await anyio.to_thread.run_sync(func)            ^^^^^^^^^^^^^^^^^^^^^^^^^^^^^^^^^^^^   File "/Users/nagabhaskar.alaparthi/hackweek-ai-debugger/venv/lib/python3.13/site-packages/anyio/to_thread.py", line 56, in run_sync     return await get_async_backend().run_sync_in_worker_thread(            ^^^^^^^^^^^^^^^^^^^^^^^^^^^^^^^^^^^^^^^^^^^^^^^^^^^^         func, args, abandon_on_cancel=abandon_on_cancel, limiter=limiter         ^^^^^^^^^^^^^^^^^^^^^^^^^^^^^^^^^^^^^^^^^^^^^^^^^^^^^^^^^^^^^^^^     )     ^   File "/Users/nagabhaskar.alaparthi/hackweek-ai-debugger/venv/lib/python3.13/site-packages/anyio/_backends/_asyncio.py", line 2470, in run_sync_in_worker_thread     return await future            ^^^^^^^^^^^^   File "/Users/nagabhaskar.alaparthi/hackweek-ai-debugger/venv/lib/python3.13/site-packages/anyio/_backends/_asyncio.py", line 967, in run     result = context.run(func, *args)   File "/Users/nagabhaskar.alaparthi/hackweek-ai-debugger/routers/example_router.py", line 20, in trigger_divide_by_zero_error     return ExampleService.simulate_divide_by_zero_error()            ~~~~~~~~~~~~~~~~~~~~~~~~~~~~~~~~~~~~~~~~~~~~^^   File "/Users/nagabhaskar.alaparthi/hackweek-ai-debugger/services/example_service.py", line 23, in simulate_divide_by_zero_error     raise RuntimeError("A division by zero error occurred.") from e RuntimeError: A division by zero error occurred.
2025-04-21 12:27:42,908 - INFO - Notifying Slack about error: 2025-04-21 12:27:41,985 - ERROR - Unhandled exception: Traceback (most recent call last):   File "/Users/nagabhaskar.alaparthi/hackweek-ai-debugger/services/example_service.py", line 21, in simulate_divide_by_zero_error     result = 1 / 0              ~~^~~ ZeroDivisionError: division by zero  The above exception was the direct cause of the following exception:  Traceback (most recent call last):   File "/Users/nagabhaskar.alaparthi/hackweek-ai-debugger/venv/lib/python3.13/site-packages/starlette/middleware/errors.py", line 165, in __call__     await self.app(scope, receive, _send)   File "/Users/nagabhaskar.alaparthi/hackweek-ai-debugger/venv/lib/python3.13/site-packages/starlette/middleware/exceptions.py", line 62, in __call__     await wrap_app_handling_exceptions(self.app, conn)(scope, receive, send)   File "/Users/nagabhaskar.alaparthi/hackweek-ai-debugger/venv/lib/python3.13/site-packages/starlette/_exception_handler.py", line 53, in wrapped_app     raise exc   File "/Users/nagabhaskar.alaparthi/hackweek-ai-debugger/venv/lib/python3.13/site-packages/starlette/_exception_handler.py", line 42, in wrapped_app     await app(scope, receive, sender)   File "/Users/nagabhaskar.alaparthi/hackweek-ai-debugger/venv/lib/python3.13/site-packages/starlette/routing.py", line 714, in __call__     await self.middleware_stack(scope, receive, send)   File "/Users/nagabhaskar.alaparthi/hackweek-ai-debugger/venv/lib/python3.13/site-packages/starlette/routing.py", line 734, in app     await route.handle(scope, receive, send)   File "/Users/nagabhaskar.alaparthi/hackweek-ai-debugger/venv/lib/python3.13/site-packages/starlette/routing.py", line 288, in handle     await self.app(scope, receive, send)   File "/Users/nagabhaskar.alaparthi/hackweek-ai-debugger/venv/lib/python3.13/site-packages/starlette/routing.py", line 76, in app     await wrap_app_handling_exceptions(app, request)(scope, receive, send)   File "/Users/nagabhaskar.alaparthi/hackweek-ai-debugger/venv/lib/python3.13/site-packages/starlette/_exception_handler.py", line 53, in wrapped_app     raise exc   File "/Users/nagabhaskar.alaparthi/hackweek-ai-debugger/venv/lib/python3.13/site-packages/starlette/_exception_handler.py", line 42, in wrapped_app     await app(scope, receive, sender)   File "/Users/nagabhaskar.alaparthi/hackweek-ai-debugger/venv/lib/python3.13/site-packages/starlette/routing.py", line 73, in app     response = await f(request)                ^^^^^^^^^^^^^^^^   File "/Users/nagabhaskar.alaparthi/hackweek-ai-debugger/venv/lib/python3.13/site-packages/fastapi/routing.py", line 301, in app     raw_response = await run_endpoint_function(                    ^^^^^^^^^^^^^^^^^^^^^^^^^^^^     ...<3 lines>...     )     ^   File "/Users/nagabhaskar.alaparthi/hackweek-ai-debugger/venv/lib/python3.13/site-packages/fastapi/routing.py", line 214, in run_endpoint_function     return await run_in_threadpool(dependant.call, **values)            ^^^^^^^^^^^^^^^^^^^^^^^^^^^^^^^^^^^^^^^^^^^^^^^^^   File "/Users/nagabhaskar.alaparthi/hackweek-ai-debugger/venv/lib/python3.13/site-packages/starlette/concurrency.py", line 37, in run_in_threadpool     return await anyio.to_thread.run_sync(func)            ^^^^^^^^^^^^^^^^^^^^^^^^^^^^^^^^^^^^   File "/Users/nagabhaskar.alaparthi/hackweek-ai-debugger/venv/lib/python3.13/site-packages/anyio/to_thread.py", line 56, in run_sync     return await get_async_backend().run_sync_in_worker_thread(            ^^^^^^^^^^^^^^^^^^^^^^^^^^^^^^^^^^^^^^^^^^^^^^^^^^^^         func, args, abandon_on_cancel=abandon_on_cancel, limiter=limiter         ^^^^^^^^^^^^^^^^^^^^^^^^^^^^^^^^^^^^^^^^^^^^^^^^^^^^^^^^^^^^^^^^     )     ^   File "/Users/nagabhaskar.alaparthi/hackweek-ai-debugger/venv/lib/python3.13/site-packages/anyio/_backends/_asyncio.py", line 2470, in run_sync_in_worker_thread     return await future            ^^^^^^^^^^^^   File "/Users/nagabhaskar.alaparthi/hackweek-ai-debugger/venv/lib/python3.13/site-packages/anyio/_backends/_asyncio.py", line 967, in run     result = context.run(func, *args)   File "/Users/nagabhaskar.alaparthi/hackweek-ai-debugger/routers/example_router.py", line 20, in trigger_divide_by_zero_error     return ExampleService.simulate_divide_by_zero_error()            ~~~~~~~~~~~~~~~~~~~~~~~~~~~~~~~~~~~~~~~~~~~~^^   File "/Users/nagabhaskar.alaparthi/hackweek-ai-debugger/services/example_service.py", line 23, in simulate_divide_by_zero_error     raise RuntimeError("A division by zero error occurred.") from e RuntimeError: A division by zero error occurred.
2025-04-21 12:32:33,024 - INFO - Starting log monitoring for file: application.log
2025-04-21 12:32:36,041 - INFO - Error detected: 2025-04-21 12:32:35,876 - ERROR - Unhandled exception: Traceback (most recent call last):   File "/Users/nagabhaskar.alaparthi/hackweek-ai-debugger/services/example_service.py", line 21, in simulate_divide_by_zero_error     result = 1 / 0              ~~^~~ ZeroDivisionError: division by zero  The above exception was the direct cause of the following exception:  Traceback (most recent call last):   File "/Users/nagabhaskar.alaparthi/hackweek-ai-debugger/venv/lib/python3.13/site-packages/starlette/middleware/errors.py", line 165, in __call__     await self.app(scope, receive, _send)   File "/Users/nagabhaskar.alaparthi/hackweek-ai-debugger/venv/lib/python3.13/site-packages/starlette/middleware/exceptions.py", line 62, in __call__     await wrap_app_handling_exceptions(self.app, conn)(scope, receive, send)   File "/Users/nagabhaskar.alaparthi/hackweek-ai-debugger/venv/lib/python3.13/site-packages/starlette/_exception_handler.py", line 53, in wrapped_app     raise exc   File "/Users/nagabhaskar.alaparthi/hackweek-ai-debugger/venv/lib/python3.13/site-packages/starlette/_exception_handler.py", line 42, in wrapped_app     await app(scope, receive, sender)   File "/Users/nagabhaskar.alaparthi/hackweek-ai-debugger/venv/lib/python3.13/site-packages/starlette/routing.py", line 714, in __call__     await self.middleware_stack(scope, receive, send)   File "/Users/nagabhaskar.alaparthi/hackweek-ai-debugger/venv/lib/python3.13/site-packages/starlette/routing.py", line 734, in app     await route.handle(scope, receive, send)   File "/Users/nagabhaskar.alaparthi/hackweek-ai-debugger/venv/lib/python3.13/site-packages/starlette/routing.py", line 288, in handle     await self.app(scope, receive, send)   File "/Users/nagabhaskar.alaparthi/hackweek-ai-debugger/venv/lib/python3.13/site-packages/starlette/routing.py", line 76, in app     await wrap_app_handling_exceptions(app, request)(scope, receive, send)   File "/Users/nagabhaskar.alaparthi/hackweek-ai-debugger/venv/lib/python3.13/site-packages/starlette/_exception_handler.py", line 53, in wrapped_app     raise exc   File "/Users/nagabhaskar.alaparthi/hackweek-ai-debugger/venv/lib/python3.13/site-packages/starlette/_exception_handler.py", line 42, in wrapped_app     await app(scope, receive, sender)   File "/Users/nagabhaskar.alaparthi/hackweek-ai-debugger/venv/lib/python3.13/site-packages/starlette/routing.py", line 73, in app     response = await f(request)                ^^^^^^^^^^^^^^^^   File "/Users/nagabhaskar.alaparthi/hackweek-ai-debugger/venv/lib/python3.13/site-packages/fastapi/routing.py", line 301, in app     raw_response = await run_endpoint_function(                    ^^^^^^^^^^^^^^^^^^^^^^^^^^^^     ...<3 lines>...     )     ^   File "/Users/nagabhaskar.alaparthi/hackweek-ai-debugger/venv/lib/python3.13/site-packages/fastapi/routing.py", line 214, in run_endpoint_function     return await run_in_threadpool(dependant.call, **values)            ^^^^^^^^^^^^^^^^^^^^^^^^^^^^^^^^^^^^^^^^^^^^^^^^^   File "/Users/nagabhaskar.alaparthi/hackweek-ai-debugger/venv/lib/python3.13/site-packages/starlette/concurrency.py", line 37, in run_in_threadpool     return await anyio.to_thread.run_sync(func)            ^^^^^^^^^^^^^^^^^^^^^^^^^^^^^^^^^^^^   File "/Users/nagabhaskar.alaparthi/hackweek-ai-debugger/venv/lib/python3.13/site-packages/anyio/to_thread.py", line 56, in run_sync     return await get_async_backend().run_sync_in_worker_thread(            ^^^^^^^^^^^^^^^^^^^^^^^^^^^^^^^^^^^^^^^^^^^^^^^^^^^^         func, args, abandon_on_cancel=abandon_on_cancel, limiter=limiter         ^^^^^^^^^^^^^^^^^^^^^^^^^^^^^^^^^^^^^^^^^^^^^^^^^^^^^^^^^^^^^^^^     )     ^   File "/Users/nagabhaskar.alaparthi/hackweek-ai-debugger/venv/lib/python3.13/site-packages/anyio/_backends/_asyncio.py", line 2470, in run_sync_in_worker_thread     return await future            ^^^^^^^^^^^^   File "/Users/nagabhaskar.alaparthi/hackweek-ai-debugger/venv/lib/python3.13/site-packages/anyio/_backends/_asyncio.py", line 967, in run     result = context.run(func, *args)   File "/Users/nagabhaskar.alaparthi/hackweek-ai-debugger/routers/example_router.py", line 20, in trigger_divide_by_zero_error     return ExampleService.simulate_divide_by_zero_error()            ~~~~~~~~~~~~~~~~~~~~~~~~~~~~~~~~~~~~~~~~~~~~^^   File "/Users/nagabhaskar.alaparthi/hackweek-ai-debugger/services/example_service.py", line 23, in simulate_divide_by_zero_error     raise RuntimeError("A division by zero error occurred.") from e RuntimeError: A division by zero error occurred.
2025-04-21 12:32:36,044 - INFO - Extracted method code: 
            result = 1 / 0
        except ZeroDivisionError as e:
            raise RuntimeError("A division by zero error occurred.") from e

    @staticmethod

2025-04-21 12:32:36,044 - INFO - Notifying Slack about error: 2025-04-21 12:32:35,876 - ERROR - Unhandled exception: Traceback (most recent call last):   File "/Users/nagabhaskar.alaparthi/hackweek-ai-debugger/services/example_service.py", line 21, in simulate_divide_by_zero_error     result = 1 / 0              ~~^~~ ZeroDivisionError: division by zero  The above exception was the direct cause of the following exception:  Traceback (most recent call last):   File "/Users/nagabhaskar.alaparthi/hackweek-ai-debugger/venv/lib/python3.13/site-packages/starlette/middleware/errors.py", line 165, in __call__     await self.app(scope, receive, _send)   File "/Users/nagabhaskar.alaparthi/hackweek-ai-debugger/venv/lib/python3.13/site-packages/starlette/middleware/exceptions.py", line 62, in __call__     await wrap_app_handling_exceptions(self.app, conn)(scope, receive, send)   File "/Users/nagabhaskar.alaparthi/hackweek-ai-debugger/venv/lib/python3.13/site-packages/starlette/_exception_handler.py", line 53, in wrapped_app     raise exc   File "/Users/nagabhaskar.alaparthi/hackweek-ai-debugger/venv/lib/python3.13/site-packages/starlette/_exception_handler.py", line 42, in wrapped_app     await app(scope, receive, sender)   File "/Users/nagabhaskar.alaparthi/hackweek-ai-debugger/venv/lib/python3.13/site-packages/starlette/routing.py", line 714, in __call__     await self.middleware_stack(scope, receive, send)   File "/Users/nagabhaskar.alaparthi/hackweek-ai-debugger/venv/lib/python3.13/site-packages/starlette/routing.py", line 734, in app     await route.handle(scope, receive, send)   File "/Users/nagabhaskar.alaparthi/hackweek-ai-debugger/venv/lib/python3.13/site-packages/starlette/routing.py", line 288, in handle     await self.app(scope, receive, send)   File "/Users/nagabhaskar.alaparthi/hackweek-ai-debugger/venv/lib/python3.13/site-packages/starlette/routing.py", line 76, in app     await wrap_app_handling_exceptions(app, request)(scope, receive, send)   File "/Users/nagabhaskar.alaparthi/hackweek-ai-debugger/venv/lib/python3.13/site-packages/starlette/_exception_handler.py", line 53, in wrapped_app     raise exc   File "/Users/nagabhaskar.alaparthi/hackweek-ai-debugger/venv/lib/python3.13/site-packages/starlette/_exception_handler.py", line 42, in wrapped_app     await app(scope, receive, sender)   File "/Users/nagabhaskar.alaparthi/hackweek-ai-debugger/venv/lib/python3.13/site-packages/starlette/routing.py", line 73, in app     response = await f(request)                ^^^^^^^^^^^^^^^^   File "/Users/nagabhaskar.alaparthi/hackweek-ai-debugger/venv/lib/python3.13/site-packages/fastapi/routing.py", line 301, in app     raw_response = await run_endpoint_function(                    ^^^^^^^^^^^^^^^^^^^^^^^^^^^^     ...<3 lines>...     )     ^   File "/Users/nagabhaskar.alaparthi/hackweek-ai-debugger/venv/lib/python3.13/site-packages/fastapi/routing.py", line 214, in run_endpoint_function     return await run_in_threadpool(dependant.call, **values)            ^^^^^^^^^^^^^^^^^^^^^^^^^^^^^^^^^^^^^^^^^^^^^^^^^   File "/Users/nagabhaskar.alaparthi/hackweek-ai-debugger/venv/lib/python3.13/site-packages/starlette/concurrency.py", line 37, in run_in_threadpool     return await anyio.to_thread.run_sync(func)            ^^^^^^^^^^^^^^^^^^^^^^^^^^^^^^^^^^^^   File "/Users/nagabhaskar.alaparthi/hackweek-ai-debugger/venv/lib/python3.13/site-packages/anyio/to_thread.py", line 56, in run_sync     return await get_async_backend().run_sync_in_worker_thread(            ^^^^^^^^^^^^^^^^^^^^^^^^^^^^^^^^^^^^^^^^^^^^^^^^^^^^         func, args, abandon_on_cancel=abandon_on_cancel, limiter=limiter         ^^^^^^^^^^^^^^^^^^^^^^^^^^^^^^^^^^^^^^^^^^^^^^^^^^^^^^^^^^^^^^^^     )     ^   File "/Users/nagabhaskar.alaparthi/hackweek-ai-debugger/venv/lib/python3.13/site-packages/anyio/_backends/_asyncio.py", line 2470, in run_sync_in_worker_thread     return await future            ^^^^^^^^^^^^   File "/Users/nagabhaskar.alaparthi/hackweek-ai-debugger/venv/lib/python3.13/site-packages/anyio/_backends/_asyncio.py", line 967, in run     result = context.run(func, *args)   File "/Users/nagabhaskar.alaparthi/hackweek-ai-debugger/routers/example_router.py", line 20, in trigger_divide_by_zero_error     return ExampleService.simulate_divide_by_zero_error()            ~~~~~~~~~~~~~~~~~~~~~~~~~~~~~~~~~~~~~~~~~~~~^^   File "/Users/nagabhaskar.alaparthi/hackweek-ai-debugger/services/example_service.py", line 23, in simulate_divide_by_zero_error     raise RuntimeError("A division by zero error occurred.") from e RuntimeError: A division by zero error occurred. 

2025-04-21 12:33:15,998 - INFO - Starting log monitoring for file: application.log
2025-04-21 12:33:40,097 - INFO - Error detected: 2025-04-21 12:33:39,397 - ERROR - Unhandled exception: Traceback (most recent call last):   File "/Users/nagabhaskar.alaparthi/hackweek-ai-debugger/services/example_service.py", line 21, in simulate_divide_by_zero_error     result = 1 / 0              ~~^~~ ZeroDivisionError: division by zero  The above exception was the direct cause of the following exception:  Traceback (most recent call last):   File "/Users/nagabhaskar.alaparthi/hackweek-ai-debugger/venv/lib/python3.13/site-packages/starlette/middleware/errors.py", line 165, in __call__     await self.app(scope, receive, _send)   File "/Users/nagabhaskar.alaparthi/hackweek-ai-debugger/venv/lib/python3.13/site-packages/starlette/middleware/exceptions.py", line 62, in __call__     await wrap_app_handling_exceptions(self.app, conn)(scope, receive, send)   File "/Users/nagabhaskar.alaparthi/hackweek-ai-debugger/venv/lib/python3.13/site-packages/starlette/_exception_handler.py", line 53, in wrapped_app     raise exc   File "/Users/nagabhaskar.alaparthi/hackweek-ai-debugger/venv/lib/python3.13/site-packages/starlette/_exception_handler.py", line 42, in wrapped_app     await app(scope, receive, sender)   File "/Users/nagabhaskar.alaparthi/hackweek-ai-debugger/venv/lib/python3.13/site-packages/starlette/routing.py", line 714, in __call__     await self.middleware_stack(scope, receive, send)   File "/Users/nagabhaskar.alaparthi/hackweek-ai-debugger/venv/lib/python3.13/site-packages/starlette/routing.py", line 734, in app     await route.handle(scope, receive, send)   File "/Users/nagabhaskar.alaparthi/hackweek-ai-debugger/venv/lib/python3.13/site-packages/starlette/routing.py", line 288, in handle     await self.app(scope, receive, send)   File "/Users/nagabhaskar.alaparthi/hackweek-ai-debugger/venv/lib/python3.13/site-packages/starlette/routing.py", line 76, in app     await wrap_app_handling_exceptions(app, request)(scope, receive, send)   File "/Users/nagabhaskar.alaparthi/hackweek-ai-debugger/venv/lib/python3.13/site-packages/starlette/_exception_handler.py", line 53, in wrapped_app     raise exc   File "/Users/nagabhaskar.alaparthi/hackweek-ai-debugger/venv/lib/python3.13/site-packages/starlette/_exception_handler.py", line 42, in wrapped_app     await app(scope, receive, sender)   File "/Users/nagabhaskar.alaparthi/hackweek-ai-debugger/venv/lib/python3.13/site-packages/starlette/routing.py", line 73, in app     response = await f(request)                ^^^^^^^^^^^^^^^^   File "/Users/nagabhaskar.alaparthi/hackweek-ai-debugger/venv/lib/python3.13/site-packages/fastapi/routing.py", line 301, in app     raw_response = await run_endpoint_function(                    ^^^^^^^^^^^^^^^^^^^^^^^^^^^^     ...<3 lines>...     )     ^   File "/Users/nagabhaskar.alaparthi/hackweek-ai-debugger/venv/lib/python3.13/site-packages/fastapi/routing.py", line 214, in run_endpoint_function     return await run_in_threadpool(dependant.call, **values)            ^^^^^^^^^^^^^^^^^^^^^^^^^^^^^^^^^^^^^^^^^^^^^^^^^   File "/Users/nagabhaskar.alaparthi/hackweek-ai-debugger/venv/lib/python3.13/site-packages/starlette/concurrency.py", line 37, in run_in_threadpool     return await anyio.to_thread.run_sync(func)            ^^^^^^^^^^^^^^^^^^^^^^^^^^^^^^^^^^^^   File "/Users/nagabhaskar.alaparthi/hackweek-ai-debugger/venv/lib/python3.13/site-packages/anyio/to_thread.py", line 56, in run_sync     return await get_async_backend().run_sync_in_worker_thread(            ^^^^^^^^^^^^^^^^^^^^^^^^^^^^^^^^^^^^^^^^^^^^^^^^^^^^         func, args, abandon_on_cancel=abandon_on_cancel, limiter=limiter         ^^^^^^^^^^^^^^^^^^^^^^^^^^^^^^^^^^^^^^^^^^^^^^^^^^^^^^^^^^^^^^^^     )     ^   File "/Users/nagabhaskar.alaparthi/hackweek-ai-debugger/venv/lib/python3.13/site-packages/anyio/_backends/_asyncio.py", line 2470, in run_sync_in_worker_thread     return await future            ^^^^^^^^^^^^   File "/Users/nagabhaskar.alaparthi/hackweek-ai-debugger/venv/lib/python3.13/site-packages/anyio/_backends/_asyncio.py", line 967, in run     result = context.run(func, *args)   File "/Users/nagabhaskar.alaparthi/hackweek-ai-debugger/routers/example_router.py", line 20, in trigger_divide_by_zero_error     return ExampleService.simulate_divide_by_zero_error()            ~~~~~~~~~~~~~~~~~~~~~~~~~~~~~~~~~~~~~~~~~~~~^^   File "/Users/nagabhaskar.alaparthi/hackweek-ai-debugger/services/example_service.py", line 23, in simulate_divide_by_zero_error     raise RuntimeError("A division by zero error occurred.") from e RuntimeError: A division by zero error occurred.
2025-04-21 12:33:40,098 - INFO - Extracted method code: 
            result = 1 / 0
        except ZeroDivisionError as e:
            raise RuntimeError("A division by zero error occurred.") from e

    @staticmethod
    def simulate_conversion_error():
        try:
            # Simulate a conversion error
            invalid_conversion = int("not_a_number")
        except ValueError as e:
            raise RuntimeError("A conversion error occurred.") from e

2025-04-21 12:33:40,098 - INFO - Notifying Slack about error: 2025-04-21 12:33:39,397 - ERROR - Unhandled exception: Traceback (most recent call last):   File "/Users/nagabhaskar.alaparthi/hackweek-ai-debugger/services/example_service.py", line 21, in simulate_divide_by_zero_error     result = 1 / 0              ~~^~~ ZeroDivisionError: division by zero  The above exception was the direct cause of the following exception:  Traceback (most recent call last):   File "/Users/nagabhaskar.alaparthi/hackweek-ai-debugger/venv/lib/python3.13/site-packages/starlette/middleware/errors.py", line 165, in __call__     await self.app(scope, receive, _send)   File "/Users/nagabhaskar.alaparthi/hackweek-ai-debugger/venv/lib/python3.13/site-packages/starlette/middleware/exceptions.py", line 62, in __call__     await wrap_app_handling_exceptions(self.app, conn)(scope, receive, send)   File "/Users/nagabhaskar.alaparthi/hackweek-ai-debugger/venv/lib/python3.13/site-packages/starlette/_exception_handler.py", line 53, in wrapped_app     raise exc   File "/Users/nagabhaskar.alaparthi/hackweek-ai-debugger/venv/lib/python3.13/site-packages/starlette/_exception_handler.py", line 42, in wrapped_app     await app(scope, receive, sender)   File "/Users/nagabhaskar.alaparthi/hackweek-ai-debugger/venv/lib/python3.13/site-packages/starlette/routing.py", line 714, in __call__     await self.middleware_stack(scope, receive, send)   File "/Users/nagabhaskar.alaparthi/hackweek-ai-debugger/venv/lib/python3.13/site-packages/starlette/routing.py", line 734, in app     await route.handle(scope, receive, send)   File "/Users/nagabhaskar.alaparthi/hackweek-ai-debugger/venv/lib/python3.13/site-packages/starlette/routing.py", line 288, in handle     await self.app(scope, receive, send)   File "/Users/nagabhaskar.alaparthi/hackweek-ai-debugger/venv/lib/python3.13/site-packages/starlette/routing.py", line 76, in app     await wrap_app_handling_exceptions(app, request)(scope, receive, send)   File "/Users/nagabhaskar.alaparthi/hackweek-ai-debugger/venv/lib/python3.13/site-packages/starlette/_exception_handler.py", line 53, in wrapped_app     raise exc   File "/Users/nagabhaskar.alaparthi/hackweek-ai-debugger/venv/lib/python3.13/site-packages/starlette/_exception_handler.py", line 42, in wrapped_app     await app(scope, receive, sender)   File "/Users/nagabhaskar.alaparthi/hackweek-ai-debugger/venv/lib/python3.13/site-packages/starlette/routing.py", line 73, in app     response = await f(request)                ^^^^^^^^^^^^^^^^   File "/Users/nagabhaskar.alaparthi/hackweek-ai-debugger/venv/lib/python3.13/site-packages/fastapi/routing.py", line 301, in app     raw_response = await run_endpoint_function(                    ^^^^^^^^^^^^^^^^^^^^^^^^^^^^     ...<3 lines>...     )     ^   File "/Users/nagabhaskar.alaparthi/hackweek-ai-debugger/venv/lib/python3.13/site-packages/fastapi/routing.py", line 214, in run_endpoint_function     return await run_in_threadpool(dependant.call, **values)            ^^^^^^^^^^^^^^^^^^^^^^^^^^^^^^^^^^^^^^^^^^^^^^^^^   File "/Users/nagabhaskar.alaparthi/hackweek-ai-debugger/venv/lib/python3.13/site-packages/starlette/concurrency.py", line 37, in run_in_threadpool     return await anyio.to_thread.run_sync(func)            ^^^^^^^^^^^^^^^^^^^^^^^^^^^^^^^^^^^^   File "/Users/nagabhaskar.alaparthi/hackweek-ai-debugger/venv/lib/python3.13/site-packages/anyio/to_thread.py", line 56, in run_sync     return await get_async_backend().run_sync_in_worker_thread(            ^^^^^^^^^^^^^^^^^^^^^^^^^^^^^^^^^^^^^^^^^^^^^^^^^^^^         func, args, abandon_on_cancel=abandon_on_cancel, limiter=limiter         ^^^^^^^^^^^^^^^^^^^^^^^^^^^^^^^^^^^^^^^^^^^^^^^^^^^^^^^^^^^^^^^^     )     ^   File "/Users/nagabhaskar.alaparthi/hackweek-ai-debugger/venv/lib/python3.13/site-packages/anyio/_backends/_asyncio.py", line 2470, in run_sync_in_worker_thread     return await future            ^^^^^^^^^^^^   File "/Users/nagabhaskar.alaparthi/hackweek-ai-debugger/venv/lib/python3.13/site-packages/anyio/_backends/_asyncio.py", line 967, in run     result = context.run(func, *args)   File "/Users/nagabhaskar.alaparthi/hackweek-ai-debugger/routers/example_router.py", line 20, in trigger_divide_by_zero_error     return ExampleService.simulate_divide_by_zero_error()            ~~~~~~~~~~~~~~~~~~~~~~~~~~~~~~~~~~~~~~~~~~~~^^   File "/Users/nagabhaskar.alaparthi/hackweek-ai-debugger/services/example_service.py", line 23, in simulate_divide_by_zero_error     raise RuntimeError("A division by zero error occurred.") from e RuntimeError: A division by zero error occurred. 

2025-04-21 12:34:40,913 - INFO - Starting log monitoring for file: application.log
2025-04-21 12:34:43,926 - INFO - Error detected: 2025-04-21 12:34:43,742 - ERROR - Unhandled exception: Traceback (most recent call last):   File "/Users/nagabhaskar.alaparthi/hackweek-ai-debugger/services/example_service.py", line 21, in simulate_divide_by_zero_error     result = 1 / 0              ~~^~~ ZeroDivisionError: division by zero  The above exception was the direct cause of the following exception:  Traceback (most recent call last):   File "/Users/nagabhaskar.alaparthi/hackweek-ai-debugger/venv/lib/python3.13/site-packages/starlette/middleware/errors.py", line 165, in __call__     await self.app(scope, receive, _send)   File "/Users/nagabhaskar.alaparthi/hackweek-ai-debugger/venv/lib/python3.13/site-packages/starlette/middleware/exceptions.py", line 62, in __call__     await wrap_app_handling_exceptions(self.app, conn)(scope, receive, send)   File "/Users/nagabhaskar.alaparthi/hackweek-ai-debugger/venv/lib/python3.13/site-packages/starlette/_exception_handler.py", line 53, in wrapped_app     raise exc   File "/Users/nagabhaskar.alaparthi/hackweek-ai-debugger/venv/lib/python3.13/site-packages/starlette/_exception_handler.py", line 42, in wrapped_app     await app(scope, receive, sender)   File "/Users/nagabhaskar.alaparthi/hackweek-ai-debugger/venv/lib/python3.13/site-packages/starlette/routing.py", line 714, in __call__     await self.middleware_stack(scope, receive, send)   File "/Users/nagabhaskar.alaparthi/hackweek-ai-debugger/venv/lib/python3.13/site-packages/starlette/routing.py", line 734, in app     await route.handle(scope, receive, send)   File "/Users/nagabhaskar.alaparthi/hackweek-ai-debugger/venv/lib/python3.13/site-packages/starlette/routing.py", line 288, in handle     await self.app(scope, receive, send)   File "/Users/nagabhaskar.alaparthi/hackweek-ai-debugger/venv/lib/python3.13/site-packages/starlette/routing.py", line 76, in app     await wrap_app_handling_exceptions(app, request)(scope, receive, send)   File "/Users/nagabhaskar.alaparthi/hackweek-ai-debugger/venv/lib/python3.13/site-packages/starlette/_exception_handler.py", line 53, in wrapped_app     raise exc   File "/Users/nagabhaskar.alaparthi/hackweek-ai-debugger/venv/lib/python3.13/site-packages/starlette/_exception_handler.py", line 42, in wrapped_app     await app(scope, receive, sender)   File "/Users/nagabhaskar.alaparthi/hackweek-ai-debugger/venv/lib/python3.13/site-packages/starlette/routing.py", line 73, in app     response = await f(request)                ^^^^^^^^^^^^^^^^   File "/Users/nagabhaskar.alaparthi/hackweek-ai-debugger/venv/lib/python3.13/site-packages/fastapi/routing.py", line 301, in app     raw_response = await run_endpoint_function(                    ^^^^^^^^^^^^^^^^^^^^^^^^^^^^     ...<3 lines>...     )     ^   File "/Users/nagabhaskar.alaparthi/hackweek-ai-debugger/venv/lib/python3.13/site-packages/fastapi/routing.py", line 214, in run_endpoint_function     return await run_in_threadpool(dependant.call, **values)            ^^^^^^^^^^^^^^^^^^^^^^^^^^^^^^^^^^^^^^^^^^^^^^^^^   File "/Users/nagabhaskar.alaparthi/hackweek-ai-debugger/venv/lib/python3.13/site-packages/starlette/concurrency.py", line 37, in run_in_threadpool     return await anyio.to_thread.run_sync(func)            ^^^^^^^^^^^^^^^^^^^^^^^^^^^^^^^^^^^^   File "/Users/nagabhaskar.alaparthi/hackweek-ai-debugger/venv/lib/python3.13/site-packages/anyio/to_thread.py", line 56, in run_sync     return await get_async_backend().run_sync_in_worker_thread(            ^^^^^^^^^^^^^^^^^^^^^^^^^^^^^^^^^^^^^^^^^^^^^^^^^^^^         func, args, abandon_on_cancel=abandon_on_cancel, limiter=limiter         ^^^^^^^^^^^^^^^^^^^^^^^^^^^^^^^^^^^^^^^^^^^^^^^^^^^^^^^^^^^^^^^^     )     ^   File "/Users/nagabhaskar.alaparthi/hackweek-ai-debugger/venv/lib/python3.13/site-packages/anyio/_backends/_asyncio.py", line 2470, in run_sync_in_worker_thread     return await future            ^^^^^^^^^^^^   File "/Users/nagabhaskar.alaparthi/hackweek-ai-debugger/venv/lib/python3.13/site-packages/anyio/_backends/_asyncio.py", line 967, in run     result = context.run(func, *args)   File "/Users/nagabhaskar.alaparthi/hackweek-ai-debugger/routers/example_router.py", line 20, in trigger_divide_by_zero_error     return ExampleService.simulate_divide_by_zero_error()            ~~~~~~~~~~~~~~~~~~~~~~~~~~~~~~~~~~~~~~~~~~~~^^   File "/Users/nagabhaskar.alaparthi/hackweek-ai-debugger/services/example_service.py", line 23, in simulate_divide_by_zero_error     raise RuntimeError("A division by zero error occurred.") from e RuntimeError: A division by zero error occurred.
2025-04-21 12:34:43,927 - INFO - Extracted method code: 
    @staticmethod
    def simulate_divide_by_zero_error():
        try:
            # Simulate a divide by zero error
            result = 1 / 0
        except ZeroDivisionError as e:
            raise RuntimeError("A division by zero error occurred.") from e

    @staticmethod
    def simulate_conversion_error():

2025-04-21 12:34:43,927 - INFO - Notifying Slack about error: 2025-04-21 12:34:43,742 - ERROR - Unhandled exception: Traceback (most recent call last):   File "/Users/nagabhaskar.alaparthi/hackweek-ai-debugger/services/example_service.py", line 21, in simulate_divide_by_zero_error     result = 1 / 0              ~~^~~ ZeroDivisionError: division by zero  The above exception was the direct cause of the following exception:  Traceback (most recent call last):   File "/Users/nagabhaskar.alaparthi/hackweek-ai-debugger/venv/lib/python3.13/site-packages/starlette/middleware/errors.py", line 165, in __call__     await self.app(scope, receive, _send)   File "/Users/nagabhaskar.alaparthi/hackweek-ai-debugger/venv/lib/python3.13/site-packages/starlette/middleware/exceptions.py", line 62, in __call__     await wrap_app_handling_exceptions(self.app, conn)(scope, receive, send)   File "/Users/nagabhaskar.alaparthi/hackweek-ai-debugger/venv/lib/python3.13/site-packages/starlette/_exception_handler.py", line 53, in wrapped_app     raise exc   File "/Users/nagabhaskar.alaparthi/hackweek-ai-debugger/venv/lib/python3.13/site-packages/starlette/_exception_handler.py", line 42, in wrapped_app     await app(scope, receive, sender)   File "/Users/nagabhaskar.alaparthi/hackweek-ai-debugger/venv/lib/python3.13/site-packages/starlette/routing.py", line 714, in __call__     await self.middleware_stack(scope, receive, send)   File "/Users/nagabhaskar.alaparthi/hackweek-ai-debugger/venv/lib/python3.13/site-packages/starlette/routing.py", line 734, in app     await route.handle(scope, receive, send)   File "/Users/nagabhaskar.alaparthi/hackweek-ai-debugger/venv/lib/python3.13/site-packages/starlette/routing.py", line 288, in handle     await self.app(scope, receive, send)   File "/Users/nagabhaskar.alaparthi/hackweek-ai-debugger/venv/lib/python3.13/site-packages/starlette/routing.py", line 76, in app     await wrap_app_handling_exceptions(app, request)(scope, receive, send)   File "/Users/nagabhaskar.alaparthi/hackweek-ai-debugger/venv/lib/python3.13/site-packages/starlette/_exception_handler.py", line 53, in wrapped_app     raise exc   File "/Users/nagabhaskar.alaparthi/hackweek-ai-debugger/venv/lib/python3.13/site-packages/starlette/_exception_handler.py", line 42, in wrapped_app     await app(scope, receive, sender)   File "/Users/nagabhaskar.alaparthi/hackweek-ai-debugger/venv/lib/python3.13/site-packages/starlette/routing.py", line 73, in app     response = await f(request)                ^^^^^^^^^^^^^^^^   File "/Users/nagabhaskar.alaparthi/hackweek-ai-debugger/venv/lib/python3.13/site-packages/fastapi/routing.py", line 301, in app     raw_response = await run_endpoint_function(                    ^^^^^^^^^^^^^^^^^^^^^^^^^^^^     ...<3 lines>...     )     ^   File "/Users/nagabhaskar.alaparthi/hackweek-ai-debugger/venv/lib/python3.13/site-packages/fastapi/routing.py", line 214, in run_endpoint_function     return await run_in_threadpool(dependant.call, **values)            ^^^^^^^^^^^^^^^^^^^^^^^^^^^^^^^^^^^^^^^^^^^^^^^^^   File "/Users/nagabhaskar.alaparthi/hackweek-ai-debugger/venv/lib/python3.13/site-packages/starlette/concurrency.py", line 37, in run_in_threadpool     return await anyio.to_thread.run_sync(func)            ^^^^^^^^^^^^^^^^^^^^^^^^^^^^^^^^^^^^   File "/Users/nagabhaskar.alaparthi/hackweek-ai-debugger/venv/lib/python3.13/site-packages/anyio/to_thread.py", line 56, in run_sync     return await get_async_backend().run_sync_in_worker_thread(            ^^^^^^^^^^^^^^^^^^^^^^^^^^^^^^^^^^^^^^^^^^^^^^^^^^^^         func, args, abandon_on_cancel=abandon_on_cancel, limiter=limiter         ^^^^^^^^^^^^^^^^^^^^^^^^^^^^^^^^^^^^^^^^^^^^^^^^^^^^^^^^^^^^^^^^     )     ^   File "/Users/nagabhaskar.alaparthi/hackweek-ai-debugger/venv/lib/python3.13/site-packages/anyio/_backends/_asyncio.py", line 2470, in run_sync_in_worker_thread     return await future            ^^^^^^^^^^^^   File "/Users/nagabhaskar.alaparthi/hackweek-ai-debugger/venv/lib/python3.13/site-packages/anyio/_backends/_asyncio.py", line 967, in run     result = context.run(func, *args)   File "/Users/nagabhaskar.alaparthi/hackweek-ai-debugger/routers/example_router.py", line 20, in trigger_divide_by_zero_error     return ExampleService.simulate_divide_by_zero_error()            ~~~~~~~~~~~~~~~~~~~~~~~~~~~~~~~~~~~~~~~~~~~~^^   File "/Users/nagabhaskar.alaparthi/hackweek-ai-debugger/services/example_service.py", line 23, in simulate_divide_by_zero_error     raise RuntimeError("A division by zero error occurred.") from e RuntimeError: A division by zero error occurred. 

2025-04-21 12:42:09,007 - INFO - Starting log monitoring for file: application.log
2025-04-21 12:42:13,025 - INFO - Error detected: 2025-04-21 12:42:12,155 - ERROR - Unhandled exception: Traceback (most recent call last):   File "/Users/nagabhaskar.alaparthi/hackweek-ai-debugger/services/example_service.py", line 21, in simulate_divide_by_zero_error     result = 1 / 0              ~~^~~ ZeroDivisionError: division by zero  The above exception was the direct cause of the following exception:  Traceback (most recent call last):   File "/Users/nagabhaskar.alaparthi/hackweek-ai-debugger/venv/lib/python3.13/site-packages/starlette/middleware/errors.py", line 165, in __call__     await self.app(scope, receive, _send)   File "/Users/nagabhaskar.alaparthi/hackweek-ai-debugger/venv/lib/python3.13/site-packages/starlette/middleware/exceptions.py", line 62, in __call__     await wrap_app_handling_exceptions(self.app, conn)(scope, receive, send)   File "/Users/nagabhaskar.alaparthi/hackweek-ai-debugger/venv/lib/python3.13/site-packages/starlette/_exception_handler.py", line 53, in wrapped_app     raise exc   File "/Users/nagabhaskar.alaparthi/hackweek-ai-debugger/venv/lib/python3.13/site-packages/starlette/_exception_handler.py", line 42, in wrapped_app     await app(scope, receive, sender)   File "/Users/nagabhaskar.alaparthi/hackweek-ai-debugger/venv/lib/python3.13/site-packages/starlette/routing.py", line 714, in __call__     await self.middleware_stack(scope, receive, send)   File "/Users/nagabhaskar.alaparthi/hackweek-ai-debugger/venv/lib/python3.13/site-packages/starlette/routing.py", line 734, in app     await route.handle(scope, receive, send)   File "/Users/nagabhaskar.alaparthi/hackweek-ai-debugger/venv/lib/python3.13/site-packages/starlette/routing.py", line 288, in handle     await self.app(scope, receive, send)   File "/Users/nagabhaskar.alaparthi/hackweek-ai-debugger/venv/lib/python3.13/site-packages/starlette/routing.py", line 76, in app     await wrap_app_handling_exceptions(app, request)(scope, receive, send)   File "/Users/nagabhaskar.alaparthi/hackweek-ai-debugger/venv/lib/python3.13/site-packages/starlette/_exception_handler.py", line 53, in wrapped_app     raise exc   File "/Users/nagabhaskar.alaparthi/hackweek-ai-debugger/venv/lib/python3.13/site-packages/starlette/_exception_handler.py", line 42, in wrapped_app     await app(scope, receive, sender)   File "/Users/nagabhaskar.alaparthi/hackweek-ai-debugger/venv/lib/python3.13/site-packages/starlette/routing.py", line 73, in app     response = await f(request)                ^^^^^^^^^^^^^^^^   File "/Users/nagabhaskar.alaparthi/hackweek-ai-debugger/venv/lib/python3.13/site-packages/fastapi/routing.py", line 301, in app     raw_response = await run_endpoint_function(                    ^^^^^^^^^^^^^^^^^^^^^^^^^^^^     ...<3 lines>...     )     ^   File "/Users/nagabhaskar.alaparthi/hackweek-ai-debugger/venv/lib/python3.13/site-packages/fastapi/routing.py", line 214, in run_endpoint_function     return await run_in_threadpool(dependant.call, **values)            ^^^^^^^^^^^^^^^^^^^^^^^^^^^^^^^^^^^^^^^^^^^^^^^^^   File "/Users/nagabhaskar.alaparthi/hackweek-ai-debugger/venv/lib/python3.13/site-packages/starlette/concurrency.py", line 37, in run_in_threadpool     return await anyio.to_thread.run_sync(func)            ^^^^^^^^^^^^^^^^^^^^^^^^^^^^^^^^^^^^   File "/Users/nagabhaskar.alaparthi/hackweek-ai-debugger/venv/lib/python3.13/site-packages/anyio/to_thread.py", line 56, in run_sync     return await get_async_backend().run_sync_in_worker_thread(            ^^^^^^^^^^^^^^^^^^^^^^^^^^^^^^^^^^^^^^^^^^^^^^^^^^^^         func, args, abandon_on_cancel=abandon_on_cancel, limiter=limiter         ^^^^^^^^^^^^^^^^^^^^^^^^^^^^^^^^^^^^^^^^^^^^^^^^^^^^^^^^^^^^^^^^     )     ^   File "/Users/nagabhaskar.alaparthi/hackweek-ai-debugger/venv/lib/python3.13/site-packages/anyio/_backends/_asyncio.py", line 2470, in run_sync_in_worker_thread     return await future            ^^^^^^^^^^^^   File "/Users/nagabhaskar.alaparthi/hackweek-ai-debugger/venv/lib/python3.13/site-packages/anyio/_backends/_asyncio.py", line 967, in run     result = context.run(func, *args)   File "/Users/nagabhaskar.alaparthi/hackweek-ai-debugger/routers/example_router.py", line 20, in trigger_divide_by_zero_error     return ExampleService.simulate_divide_by_zero_error()            ~~~~~~~~~~~~~~~~~~~~~~~~~~~~~~~~~~~~~~~~~~~~^^   File "/Users/nagabhaskar.alaparthi/hackweek-ai-debugger/services/example_service.py", line 23, in simulate_divide_by_zero_error     raise RuntimeError("A division by zero error occurred.") from e RuntimeError: A division by zero error occurred.
2025-04-21 12:42:13,027 - INFO - Extracted method code: 
    @staticmethod
    def simulate_divide_by_zero_error():
        try:
            # Simulate a divide by zero error
            result = 1 / 0
        except ZeroDivisionError as e:
            raise RuntimeError("A division by zero error occurred.") from e


2025-04-21 12:42:13,028 - INFO - Processing error message: 2025-04-21 12:42:12,155 - ERROR - Unhandled exception:
2025-04-21 12:42:13,028 - INFO - Processing method code: 
    @staticmethod
    def simulate_divide_by_zero_error():
        try:
            # Simulate a divide by zero error
            result = 1 / 0
        except ZeroDivisionError as e:
            raise RuntimeError("A division by zero error occurred.") from e


2025-04-21 12:42:13,028 - INFO - Notifying Slack about error: 2025-04-21 12:42:12,155 - ERROR - Unhandled exception: Traceback (most recent call last):   File "/Users/nagabhaskar.alaparthi/hackweek-ai-debugger/services/example_service.py", line 21, in simulate_divide_by_zero_error     result = 1 / 0              ~~^~~ ZeroDivisionError: division by zero  The above exception was the direct cause of the following exception:  Traceback (most recent call last):   File "/Users/nagabhaskar.alaparthi/hackweek-ai-debugger/venv/lib/python3.13/site-packages/starlette/middleware/errors.py", line 165, in __call__     await self.app(scope, receive, _send)   File "/Users/nagabhaskar.alaparthi/hackweek-ai-debugger/venv/lib/python3.13/site-packages/starlette/middleware/exceptions.py", line 62, in __call__     await wrap_app_handling_exceptions(self.app, conn)(scope, receive, send)   File "/Users/nagabhaskar.alaparthi/hackweek-ai-debugger/venv/lib/python3.13/site-packages/starlette/_exception_handler.py", line 53, in wrapped_app     raise exc   File "/Users/nagabhaskar.alaparthi/hackweek-ai-debugger/venv/lib/python3.13/site-packages/starlette/_exception_handler.py", line 42, in wrapped_app     await app(scope, receive, sender)   File "/Users/nagabhaskar.alaparthi/hackweek-ai-debugger/venv/lib/python3.13/site-packages/starlette/routing.py", line 714, in __call__     await self.middleware_stack(scope, receive, send)   File "/Users/nagabhaskar.alaparthi/hackweek-ai-debugger/venv/lib/python3.13/site-packages/starlette/routing.py", line 734, in app     await route.handle(scope, receive, send)   File "/Users/nagabhaskar.alaparthi/hackweek-ai-debugger/venv/lib/python3.13/site-packages/starlette/routing.py", line 288, in handle     await self.app(scope, receive, send)   File "/Users/nagabhaskar.alaparthi/hackweek-ai-debugger/venv/lib/python3.13/site-packages/starlette/routing.py", line 76, in app     await wrap_app_handling_exceptions(app, request)(scope, receive, send)   File "/Users/nagabhaskar.alaparthi/hackweek-ai-debugger/venv/lib/python3.13/site-packages/starlette/_exception_handler.py", line 53, in wrapped_app     raise exc   File "/Users/nagabhaskar.alaparthi/hackweek-ai-debugger/venv/lib/python3.13/site-packages/starlette/_exception_handler.py", line 42, in wrapped_app     await app(scope, receive, sender)   File "/Users/nagabhaskar.alaparthi/hackweek-ai-debugger/venv/lib/python3.13/site-packages/starlette/routing.py", line 73, in app     response = await f(request)                ^^^^^^^^^^^^^^^^   File "/Users/nagabhaskar.alaparthi/hackweek-ai-debugger/venv/lib/python3.13/site-packages/fastapi/routing.py", line 301, in app     raw_response = await run_endpoint_function(                    ^^^^^^^^^^^^^^^^^^^^^^^^^^^^     ...<3 lines>...     )     ^   File "/Users/nagabhaskar.alaparthi/hackweek-ai-debugger/venv/lib/python3.13/site-packages/fastapi/routing.py", line 214, in run_endpoint_function     return await run_in_threadpool(dependant.call, **values)            ^^^^^^^^^^^^^^^^^^^^^^^^^^^^^^^^^^^^^^^^^^^^^^^^^   File "/Users/nagabhaskar.alaparthi/hackweek-ai-debugger/venv/lib/python3.13/site-packages/starlette/concurrency.py", line 37, in run_in_threadpool     return await anyio.to_thread.run_sync(func)            ^^^^^^^^^^^^^^^^^^^^^^^^^^^^^^^^^^^^   File "/Users/nagabhaskar.alaparthi/hackweek-ai-debugger/venv/lib/python3.13/site-packages/anyio/to_thread.py", line 56, in run_sync     return await get_async_backend().run_sync_in_worker_thread(            ^^^^^^^^^^^^^^^^^^^^^^^^^^^^^^^^^^^^^^^^^^^^^^^^^^^^         func, args, abandon_on_cancel=abandon_on_cancel, limiter=limiter         ^^^^^^^^^^^^^^^^^^^^^^^^^^^^^^^^^^^^^^^^^^^^^^^^^^^^^^^^^^^^^^^^     )     ^   File "/Users/nagabhaskar.alaparthi/hackweek-ai-debugger/venv/lib/python3.13/site-packages/anyio/_backends/_asyncio.py", line 2470, in run_sync_in_worker_thread     return await future            ^^^^^^^^^^^^   File "/Users/nagabhaskar.alaparthi/hackweek-ai-debugger/venv/lib/python3.13/site-packages/anyio/_backends/_asyncio.py", line 967, in run     result = context.run(func, *args)   File "/Users/nagabhaskar.alaparthi/hackweek-ai-debugger/routers/example_router.py", line 20, in trigger_divide_by_zero_error     return ExampleService.simulate_divide_by_zero_error()            ~~~~~~~~~~~~~~~~~~~~~~~~~~~~~~~~~~~~~~~~~~~~^^   File "/Users/nagabhaskar.alaparthi/hackweek-ai-debugger/services/example_service.py", line 23, in simulate_divide_by_zero_error     raise RuntimeError("A division by zero error occurred.") from e RuntimeError: A division by zero error occurred. 

2025-04-21 12:42:14,033 - INFO - Error detected: 2025-04-21 12:42:13,530 - ERROR - Unhandled exception: Traceback (most recent call last):   File "/Users/nagabhaskar.alaparthi/hackweek-ai-debugger/services/example_service.py", line 21, in simulate_divide_by_zero_error     result = 1 / 0              ~~^~~ ZeroDivisionError: division by zero  The above exception was the direct cause of the following exception:  Traceback (most recent call last):   File "/Users/nagabhaskar.alaparthi/hackweek-ai-debugger/venv/lib/python3.13/site-packages/starlette/middleware/errors.py", line 165, in __call__     await self.app(scope, receive, _send)   File "/Users/nagabhaskar.alaparthi/hackweek-ai-debugger/venv/lib/python3.13/site-packages/starlette/middleware/exceptions.py", line 62, in __call__     await wrap_app_handling_exceptions(self.app, conn)(scope, receive, send)   File "/Users/nagabhaskar.alaparthi/hackweek-ai-debugger/venv/lib/python3.13/site-packages/starlette/_exception_handler.py", line 53, in wrapped_app     raise exc   File "/Users/nagabhaskar.alaparthi/hackweek-ai-debugger/venv/lib/python3.13/site-packages/starlette/_exception_handler.py", line 42, in wrapped_app     await app(scope, receive, sender)   File "/Users/nagabhaskar.alaparthi/hackweek-ai-debugger/venv/lib/python3.13/site-packages/starlette/routing.py", line 714, in __call__     await self.middleware_stack(scope, receive, send)   File "/Users/nagabhaskar.alaparthi/hackweek-ai-debugger/venv/lib/python3.13/site-packages/starlette/routing.py", line 734, in app     await route.handle(scope, receive, send)   File "/Users/nagabhaskar.alaparthi/hackweek-ai-debugger/venv/lib/python3.13/site-packages/starlette/routing.py", line 288, in handle     await self.app(scope, receive, send)   File "/Users/nagabhaskar.alaparthi/hackweek-ai-debugger/venv/lib/python3.13/site-packages/starlette/routing.py", line 76, in app     await wrap_app_handling_exceptions(app, request)(scope, receive, send)   File "/Users/nagabhaskar.alaparthi/hackweek-ai-debugger/venv/lib/python3.13/site-packages/starlette/_exception_handler.py", line 53, in wrapped_app     raise exc   File "/Users/nagabhaskar.alaparthi/hackweek-ai-debugger/venv/lib/python3.13/site-packages/starlette/_exception_handler.py", line 42, in wrapped_app     await app(scope, receive, sender)   File "/Users/nagabhaskar.alaparthi/hackweek-ai-debugger/venv/lib/python3.13/site-packages/starlette/routing.py", line 73, in app     response = await f(request)                ^^^^^^^^^^^^^^^^   File "/Users/nagabhaskar.alaparthi/hackweek-ai-debugger/venv/lib/python3.13/site-packages/fastapi/routing.py", line 301, in app     raw_response = await run_endpoint_function(                    ^^^^^^^^^^^^^^^^^^^^^^^^^^^^     ...<3 lines>...     )     ^   File "/Users/nagabhaskar.alaparthi/hackweek-ai-debugger/venv/lib/python3.13/site-packages/fastapi/routing.py", line 214, in run_endpoint_function     return await run_in_threadpool(dependant.call, **values)            ^^^^^^^^^^^^^^^^^^^^^^^^^^^^^^^^^^^^^^^^^^^^^^^^^   File "/Users/nagabhaskar.alaparthi/hackweek-ai-debugger/venv/lib/python3.13/site-packages/starlette/concurrency.py", line 37, in run_in_threadpool     return await anyio.to_thread.run_sync(func)            ^^^^^^^^^^^^^^^^^^^^^^^^^^^^^^^^^^^^   File "/Users/nagabhaskar.alaparthi/hackweek-ai-debugger/venv/lib/python3.13/site-packages/anyio/to_thread.py", line 56, in run_sync     return await get_async_backend().run_sync_in_worker_thread(            ^^^^^^^^^^^^^^^^^^^^^^^^^^^^^^^^^^^^^^^^^^^^^^^^^^^^         func, args, abandon_on_cancel=abandon_on_cancel, limiter=limiter         ^^^^^^^^^^^^^^^^^^^^^^^^^^^^^^^^^^^^^^^^^^^^^^^^^^^^^^^^^^^^^^^^     )     ^   File "/Users/nagabhaskar.alaparthi/hackweek-ai-debugger/venv/lib/python3.13/site-packages/anyio/_backends/_asyncio.py", line 2470, in run_sync_in_worker_thread     return await future            ^^^^^^^^^^^^   File "/Users/nagabhaskar.alaparthi/hackweek-ai-debugger/venv/lib/python3.13/site-packages/anyio/_backends/_asyncio.py", line 967, in run     result = context.run(func, *args)   File "/Users/nagabhaskar.alaparthi/hackweek-ai-debugger/routers/example_router.py", line 20, in trigger_divide_by_zero_error     return ExampleService.simulate_divide_by_zero_error()            ~~~~~~~~~~~~~~~~~~~~~~~~~~~~~~~~~~~~~~~~~~~~^^   File "/Users/nagabhaskar.alaparthi/hackweek-ai-debugger/services/example_service.py", line 23, in simulate_divide_by_zero_error     raise RuntimeError("A division by zero error occurred.") from e RuntimeError: A division by zero error occurred.
2025-04-21 12:42:14,034 - INFO - Extracted method code: 
    @staticmethod
    def simulate_divide_by_zero_error():
        try:
            # Simulate a divide by zero error
            result = 1 / 0
        except ZeroDivisionError as e:
            raise RuntimeError("A division by zero error occurred.") from e


2025-04-21 12:42:14,034 - INFO - Processing error message: 2025-04-21 12:42:13,530 - ERROR - Unhandled exception:
2025-04-21 12:42:14,034 - INFO - Processing method code: 
    @staticmethod
    def simulate_divide_by_zero_error():
        try:
            # Simulate a divide by zero error
            result = 1 / 0
        except ZeroDivisionError as e:
            raise RuntimeError("A division by zero error occurred.") from e


2025-04-21 12:42:14,034 - INFO - Notifying Slack about error: 2025-04-21 12:42:13,530 - ERROR - Unhandled exception: Traceback (most recent call last):   File "/Users/nagabhaskar.alaparthi/hackweek-ai-debugger/services/example_service.py", line 21, in simulate_divide_by_zero_error     result = 1 / 0              ~~^~~ ZeroDivisionError: division by zero  The above exception was the direct cause of the following exception:  Traceback (most recent call last):   File "/Users/nagabhaskar.alaparthi/hackweek-ai-debugger/venv/lib/python3.13/site-packages/starlette/middleware/errors.py", line 165, in __call__     await self.app(scope, receive, _send)   File "/Users/nagabhaskar.alaparthi/hackweek-ai-debugger/venv/lib/python3.13/site-packages/starlette/middleware/exceptions.py", line 62, in __call__     await wrap_app_handling_exceptions(self.app, conn)(scope, receive, send)   File "/Users/nagabhaskar.alaparthi/hackweek-ai-debugger/venv/lib/python3.13/site-packages/starlette/_exception_handler.py", line 53, in wrapped_app     raise exc   File "/Users/nagabhaskar.alaparthi/hackweek-ai-debugger/venv/lib/python3.13/site-packages/starlette/_exception_handler.py", line 42, in wrapped_app     await app(scope, receive, sender)   File "/Users/nagabhaskar.alaparthi/hackweek-ai-debugger/venv/lib/python3.13/site-packages/starlette/routing.py", line 714, in __call__     await self.middleware_stack(scope, receive, send)   File "/Users/nagabhaskar.alaparthi/hackweek-ai-debugger/venv/lib/python3.13/site-packages/starlette/routing.py", line 734, in app     await route.handle(scope, receive, send)   File "/Users/nagabhaskar.alaparthi/hackweek-ai-debugger/venv/lib/python3.13/site-packages/starlette/routing.py", line 288, in handle     await self.app(scope, receive, send)   File "/Users/nagabhaskar.alaparthi/hackweek-ai-debugger/venv/lib/python3.13/site-packages/starlette/routing.py", line 76, in app     await wrap_app_handling_exceptions(app, request)(scope, receive, send)   File "/Users/nagabhaskar.alaparthi/hackweek-ai-debugger/venv/lib/python3.13/site-packages/starlette/_exception_handler.py", line 53, in wrapped_app     raise exc   File "/Users/nagabhaskar.alaparthi/hackweek-ai-debugger/venv/lib/python3.13/site-packages/starlette/_exception_handler.py", line 42, in wrapped_app     await app(scope, receive, sender)   File "/Users/nagabhaskar.alaparthi/hackweek-ai-debugger/venv/lib/python3.13/site-packages/starlette/routing.py", line 73, in app     response = await f(request)                ^^^^^^^^^^^^^^^^   File "/Users/nagabhaskar.alaparthi/hackweek-ai-debugger/venv/lib/python3.13/site-packages/fastapi/routing.py", line 301, in app     raw_response = await run_endpoint_function(                    ^^^^^^^^^^^^^^^^^^^^^^^^^^^^     ...<3 lines>...     )     ^   File "/Users/nagabhaskar.alaparthi/hackweek-ai-debugger/venv/lib/python3.13/site-packages/fastapi/routing.py", line 214, in run_endpoint_function     return await run_in_threadpool(dependant.call, **values)            ^^^^^^^^^^^^^^^^^^^^^^^^^^^^^^^^^^^^^^^^^^^^^^^^^   File "/Users/nagabhaskar.alaparthi/hackweek-ai-debugger/venv/lib/python3.13/site-packages/starlette/concurrency.py", line 37, in run_in_threadpool     return await anyio.to_thread.run_sync(func)            ^^^^^^^^^^^^^^^^^^^^^^^^^^^^^^^^^^^^   File "/Users/nagabhaskar.alaparthi/hackweek-ai-debugger/venv/lib/python3.13/site-packages/anyio/to_thread.py", line 56, in run_sync     return await get_async_backend().run_sync_in_worker_thread(            ^^^^^^^^^^^^^^^^^^^^^^^^^^^^^^^^^^^^^^^^^^^^^^^^^^^^         func, args, abandon_on_cancel=abandon_on_cancel, limiter=limiter         ^^^^^^^^^^^^^^^^^^^^^^^^^^^^^^^^^^^^^^^^^^^^^^^^^^^^^^^^^^^^^^^^     )     ^   File "/Users/nagabhaskar.alaparthi/hackweek-ai-debugger/venv/lib/python3.13/site-packages/anyio/_backends/_asyncio.py", line 2470, in run_sync_in_worker_thread     return await future            ^^^^^^^^^^^^   File "/Users/nagabhaskar.alaparthi/hackweek-ai-debugger/venv/lib/python3.13/site-packages/anyio/_backends/_asyncio.py", line 967, in run     result = context.run(func, *args)   File "/Users/nagabhaskar.alaparthi/hackweek-ai-debugger/routers/example_router.py", line 20, in trigger_divide_by_zero_error     return ExampleService.simulate_divide_by_zero_error()            ~~~~~~~~~~~~~~~~~~~~~~~~~~~~~~~~~~~~~~~~~~~~^^   File "/Users/nagabhaskar.alaparthi/hackweek-ai-debugger/services/example_service.py", line 23, in simulate_divide_by_zero_error     raise RuntimeError("A division by zero error occurred.") from e RuntimeError: A division by zero error occurred. 

2025-04-21 12:45:03,825 - INFO - Starting log monitoring for file: application.log
2025-04-21 12:45:07,841 - INFO - Error detected: 2025-04-21 12:45:07,659 - ERROR - Unhandled exception: Traceback (most recent call last):   File "/Users/nagabhaskar.alaparthi/hackweek-ai-debugger/services/example_service.py", line 21, in simulate_divide_by_zero_error     result = 1 / 0              ~~^~~ ZeroDivisionError: division by zero  The above exception was the direct cause of the following exception:  Traceback (most recent call last):   File "/Users/nagabhaskar.alaparthi/hackweek-ai-debugger/venv/lib/python3.13/site-packages/starlette/middleware/errors.py", line 165, in __call__     await self.app(scope, receive, _send)   File "/Users/nagabhaskar.alaparthi/hackweek-ai-debugger/venv/lib/python3.13/site-packages/starlette/middleware/exceptions.py", line 62, in __call__     await wrap_app_handling_exceptions(self.app, conn)(scope, receive, send)   File "/Users/nagabhaskar.alaparthi/hackweek-ai-debugger/venv/lib/python3.13/site-packages/starlette/_exception_handler.py", line 53, in wrapped_app     raise exc   File "/Users/nagabhaskar.alaparthi/hackweek-ai-debugger/venv/lib/python3.13/site-packages/starlette/_exception_handler.py", line 42, in wrapped_app     await app(scope, receive, sender)   File "/Users/nagabhaskar.alaparthi/hackweek-ai-debugger/venv/lib/python3.13/site-packages/starlette/routing.py", line 714, in __call__     await self.middleware_stack(scope, receive, send)   File "/Users/nagabhaskar.alaparthi/hackweek-ai-debugger/venv/lib/python3.13/site-packages/starlette/routing.py", line 734, in app     await route.handle(scope, receive, send)   File "/Users/nagabhaskar.alaparthi/hackweek-ai-debugger/venv/lib/python3.13/site-packages/starlette/routing.py", line 288, in handle     await self.app(scope, receive, send)   File "/Users/nagabhaskar.alaparthi/hackweek-ai-debugger/venv/lib/python3.13/site-packages/starlette/routing.py", line 76, in app     await wrap_app_handling_exceptions(app, request)(scope, receive, send)   File "/Users/nagabhaskar.alaparthi/hackweek-ai-debugger/venv/lib/python3.13/site-packages/starlette/_exception_handler.py", line 53, in wrapped_app     raise exc   File "/Users/nagabhaskar.alaparthi/hackweek-ai-debugger/venv/lib/python3.13/site-packages/starlette/_exception_handler.py", line 42, in wrapped_app     await app(scope, receive, sender)   File "/Users/nagabhaskar.alaparthi/hackweek-ai-debugger/venv/lib/python3.13/site-packages/starlette/routing.py", line 73, in app     response = await f(request)                ^^^^^^^^^^^^^^^^   File "/Users/nagabhaskar.alaparthi/hackweek-ai-debugger/venv/lib/python3.13/site-packages/fastapi/routing.py", line 301, in app     raw_response = await run_endpoint_function(                    ^^^^^^^^^^^^^^^^^^^^^^^^^^^^     ...<3 lines>...     )     ^   File "/Users/nagabhaskar.alaparthi/hackweek-ai-debugger/venv/lib/python3.13/site-packages/fastapi/routing.py", line 214, in run_endpoint_function     return await run_in_threadpool(dependant.call, **values)            ^^^^^^^^^^^^^^^^^^^^^^^^^^^^^^^^^^^^^^^^^^^^^^^^^   File "/Users/nagabhaskar.alaparthi/hackweek-ai-debugger/venv/lib/python3.13/site-packages/starlette/concurrency.py", line 37, in run_in_threadpool     return await anyio.to_thread.run_sync(func)            ^^^^^^^^^^^^^^^^^^^^^^^^^^^^^^^^^^^^   File "/Users/nagabhaskar.alaparthi/hackweek-ai-debugger/venv/lib/python3.13/site-packages/anyio/to_thread.py", line 56, in run_sync     return await get_async_backend().run_sync_in_worker_thread(            ^^^^^^^^^^^^^^^^^^^^^^^^^^^^^^^^^^^^^^^^^^^^^^^^^^^^         func, args, abandon_on_cancel=abandon_on_cancel, limiter=limiter         ^^^^^^^^^^^^^^^^^^^^^^^^^^^^^^^^^^^^^^^^^^^^^^^^^^^^^^^^^^^^^^^^     )     ^   File "/Users/nagabhaskar.alaparthi/hackweek-ai-debugger/venv/lib/python3.13/site-packages/anyio/_backends/_asyncio.py", line 2470, in run_sync_in_worker_thread     return await future            ^^^^^^^^^^^^   File "/Users/nagabhaskar.alaparthi/hackweek-ai-debugger/venv/lib/python3.13/site-packages/anyio/_backends/_asyncio.py", line 967, in run     result = context.run(func, *args)   File "/Users/nagabhaskar.alaparthi/hackweek-ai-debugger/routers/example_router.py", line 20, in trigger_divide_by_zero_error     return ExampleService.simulate_divide_by_zero_error()            ~~~~~~~~~~~~~~~~~~~~~~~~~~~~~~~~~~~~~~~~~~~~^^   File "/Users/nagabhaskar.alaparthi/hackweek-ai-debugger/services/example_service.py", line 23, in simulate_divide_by_zero_error     raise RuntimeError("A division by zero error occurred.") from e RuntimeError: A division by zero error occurred.
2025-04-21 12:45:07,842 - INFO - Extracted method code: 
    @staticmethod
    def simulate_divide_by_zero_error():
        try:
            # Simulate a divide by zero error
            result = 1 / 0
        except ZeroDivisionError as e:
            raise RuntimeError("A division by zero error occurred.") from e


2025-04-21 12:45:07,842 - INFO - Processing error message: 2025-04-21 12:45:07,659 - ERROR - Unhandled exception: Traceback (most recent call last):   File "/Users/nagabhaskar.alaparthi/hackweek-ai-debugger/services/example_service.py", line 21, in simulate_divide_by_zero_error     result = 1 / 0              ~~^~~ ZeroDivisionError: division by zero  The above exception was the direct cause of the following exception:  Traceback (most recent call last):   File "/Users/nagabhaskar.alaparthi/hackweek-ai-debugger/venv/lib/python3.13/site-packages/starlette/middleware/errors.py", line 165, in __call__     await self.app(scope, receive, _send)   File "/Users/nagabhaskar.alaparthi/hackweek-ai-debugger/venv/lib/python3.13/site-packages/starlette/middleware/exceptions.py", line 62, in __call__     await wrap_app_handling_exceptions(self.app, conn)(scope, receive, send)   File "/Users/nagabhaskar.alaparthi/hackweek-ai-debugger/venv/lib/python3.13/site-packages/starlette/_exception_handler.py", line 53, in wrapped_app     raise exc   File "/Users/nagabhaskar.alaparthi/hackweek-ai-debugger/venv/lib/python3.13/site-packages/starlette/_exception_handler.py", line 42, in wrapped_app     await app(scope, receive, sender)   File "/Users/nagabhaskar.alaparthi/hackweek-ai-debugger/venv/lib/python3.13/site-packages/starlette/routing.py", line 714, in __call__     await self.middleware_stack(scope, receive, send)   File "/Users/nagabhaskar.alaparthi/hackweek-ai-debugger/venv/lib/python3.13/site-packages/starlette/routing.py", line 734, in app     await route.handle(scope, receive, send)   File "/Users/nagabhaskar.alaparthi/hackweek-ai-debugger/venv/lib/python3.13/site-packages/starlette/routing.py", line 288, in handle     await self.app(scope, receive, send)   File "/Users/nagabhaskar.alaparthi/hackweek-ai-debugger/venv/lib/python3.13/site-packages/starlette/routing.py", line 76, in app     await wrap_app_handling_exceptions(app, request)(scope, receive, send)   File "/Users/nagabhaskar.alaparthi/hackweek-ai-debugger/venv/lib/python3.13/site-packages/starlette/_exception_handler.py", line 53, in wrapped_app     raise exc   File "/Users/nagabhaskar.alaparthi/hackweek-ai-debugger/venv/lib/python3.13/site-packages/starlette/_exception_handler.py", line 42, in wrapped_app     await app(scope, receive, sender)   File "/Users/nagabhaskar.alaparthi/hackweek-ai-debugger/venv/lib/python3.13/site-packages/starlette/routing.py", line 73, in app     response = await f(request)                ^^^^^^^^^^^^^^^^   File "/Users/nagabhaskar.alaparthi/hackweek-ai-debugger/venv/lib/python3.13/site-packages/fastapi/routing.py", line 301, in app     raw_response = await run_endpoint_function(                    ^^^^^^^^^^^^^^^^^^^^^^^^^^^^     ...<3 lines>...     )     ^   File "/Users/nagabhaskar.alaparthi/hackweek-ai-debugger/venv/lib/python3.13/site-packages/fastapi/routing.py", line 214, in run_endpoint_function     return await run_in_threadpool(dependant.call, **values)            ^^^^^^^^^^^^^^^^^^^^^^^^^^^^^^^^^^^^^^^^^^^^^^^^^   File "/Users/nagabhaskar.alaparthi/hackweek-ai-debugger/venv/lib/python3.13/site-packages/starlette/concurrency.py", line 37, in run_in_threadpool     return await anyio.to_thread.run_sync(func)            ^^^^^^^^^^^^^^^^^^^^^^^^^^^^^^^^^^^^   File "/Users/nagabhaskar.alaparthi/hackweek-ai-debugger/venv/lib/python3.13/site-packages/anyio/to_thread.py", line 56, in run_sync     return await get_async_backend().run_sync_in_worker_thread(            ^^^^^^^^^^^^^^^^^^^^^^^^^^^^^^^^^^^^^^^^^^^^^^^^^^^^         func, args, abandon_on_cancel=abandon_on_cancel, limiter=limiter         ^^^^^^^^^^^^^^^^^^^^^^^^^^^^^^^^^^^^^^^^^^^^^^^^^^^^^^^^^^^^^^^^     )     ^   File "/Users/nagabhaskar.alaparthi/hackweek-ai-debugger/venv/lib/python3.13/site-packages/anyio/_backends/_asyncio.py", line 2470, in run_sync_in_worker_thread     return await future            ^^^^^^^^^^^^   File "/Users/nagabhaskar.alaparthi/hackweek-ai-debugger/venv/lib/python3.13/site-packages/anyio/_backends/_asyncio.py", line 967, in run     result = context.run(func, *args)   File "/Users/nagabhaskar.alaparthi/hackweek-ai-debugger/routers/example_router.py", line 20, in trigger_divide_by_zero_error     return ExampleService.simulate_divide_by_zero_error()            ~~~~~~~~~~~~~~~~~~~~~~~~~~~~~~~~~~~~~~~~~~~~^^   File "/Users/nagabhaskar.alaparthi/hackweek-ai-debugger/services/example_service.py", line 23, in simulate_divide_by_zero_error     raise RuntimeError("A division by zero error occurred.") from e RuntimeError: A division by zero error occurred. 
2025-04-21 12:45:07,842 - INFO - Processing method code: 
    @staticmethod
    def simulate_divide_by_zero_error():
        try:
            # Simulate a divide by zero error
            result = 1 / 0
        except ZeroDivisionError as e:
            raise RuntimeError("A division by zero error occurred.") from e


2025-04-21 12:45:07,842 - INFO - Notifying Slack about error: 2025-04-21 12:45:07,659 - ERROR - Unhandled exception: Traceback (most recent call last):   File "/Users/nagabhaskar.alaparthi/hackweek-ai-debugger/services/example_service.py", line 21, in simulate_divide_by_zero_error     result = 1 / 0              ~~^~~ ZeroDivisionError: division by zero  The above exception was the direct cause of the following exception:  Traceback (most recent call last):   File "/Users/nagabhaskar.alaparthi/hackweek-ai-debugger/venv/lib/python3.13/site-packages/starlette/middleware/errors.py", line 165, in __call__     await self.app(scope, receive, _send)   File "/Users/nagabhaskar.alaparthi/hackweek-ai-debugger/venv/lib/python3.13/site-packages/starlette/middleware/exceptions.py", line 62, in __call__     await wrap_app_handling_exceptions(self.app, conn)(scope, receive, send)   File "/Users/nagabhaskar.alaparthi/hackweek-ai-debugger/venv/lib/python3.13/site-packages/starlette/_exception_handler.py", line 53, in wrapped_app     raise exc   File "/Users/nagabhaskar.alaparthi/hackweek-ai-debugger/venv/lib/python3.13/site-packages/starlette/_exception_handler.py", line 42, in wrapped_app     await app(scope, receive, sender)   File "/Users/nagabhaskar.alaparthi/hackweek-ai-debugger/venv/lib/python3.13/site-packages/starlette/routing.py", line 714, in __call__     await self.middleware_stack(scope, receive, send)   File "/Users/nagabhaskar.alaparthi/hackweek-ai-debugger/venv/lib/python3.13/site-packages/starlette/routing.py", line 734, in app     await route.handle(scope, receive, send)   File "/Users/nagabhaskar.alaparthi/hackweek-ai-debugger/venv/lib/python3.13/site-packages/starlette/routing.py", line 288, in handle     await self.app(scope, receive, send)   File "/Users/nagabhaskar.alaparthi/hackweek-ai-debugger/venv/lib/python3.13/site-packages/starlette/routing.py", line 76, in app     await wrap_app_handling_exceptions(app, request)(scope, receive, send)   File "/Users/nagabhaskar.alaparthi/hackweek-ai-debugger/venv/lib/python3.13/site-packages/starlette/_exception_handler.py", line 53, in wrapped_app     raise exc   File "/Users/nagabhaskar.alaparthi/hackweek-ai-debugger/venv/lib/python3.13/site-packages/starlette/_exception_handler.py", line 42, in wrapped_app     await app(scope, receive, sender)   File "/Users/nagabhaskar.alaparthi/hackweek-ai-debugger/venv/lib/python3.13/site-packages/starlette/routing.py", line 73, in app     response = await f(request)                ^^^^^^^^^^^^^^^^   File "/Users/nagabhaskar.alaparthi/hackweek-ai-debugger/venv/lib/python3.13/site-packages/fastapi/routing.py", line 301, in app     raw_response = await run_endpoint_function(                    ^^^^^^^^^^^^^^^^^^^^^^^^^^^^     ...<3 lines>...     )     ^   File "/Users/nagabhaskar.alaparthi/hackweek-ai-debugger/venv/lib/python3.13/site-packages/fastapi/routing.py", line 214, in run_endpoint_function     return await run_in_threadpool(dependant.call, **values)            ^^^^^^^^^^^^^^^^^^^^^^^^^^^^^^^^^^^^^^^^^^^^^^^^^   File "/Users/nagabhaskar.alaparthi/hackweek-ai-debugger/venv/lib/python3.13/site-packages/starlette/concurrency.py", line 37, in run_in_threadpool     return await anyio.to_thread.run_sync(func)            ^^^^^^^^^^^^^^^^^^^^^^^^^^^^^^^^^^^^   File "/Users/nagabhaskar.alaparthi/hackweek-ai-debugger/venv/lib/python3.13/site-packages/anyio/to_thread.py", line 56, in run_sync     return await get_async_backend().run_sync_in_worker_thread(            ^^^^^^^^^^^^^^^^^^^^^^^^^^^^^^^^^^^^^^^^^^^^^^^^^^^^         func, args, abandon_on_cancel=abandon_on_cancel, limiter=limiter         ^^^^^^^^^^^^^^^^^^^^^^^^^^^^^^^^^^^^^^^^^^^^^^^^^^^^^^^^^^^^^^^^     )     ^   File "/Users/nagabhaskar.alaparthi/hackweek-ai-debugger/venv/lib/python3.13/site-packages/anyio/_backends/_asyncio.py", line 2470, in run_sync_in_worker_thread     return await future            ^^^^^^^^^^^^   File "/Users/nagabhaskar.alaparthi/hackweek-ai-debugger/venv/lib/python3.13/site-packages/anyio/_backends/_asyncio.py", line 967, in run     result = context.run(func, *args)   File "/Users/nagabhaskar.alaparthi/hackweek-ai-debugger/routers/example_router.py", line 20, in trigger_divide_by_zero_error     return ExampleService.simulate_divide_by_zero_error()            ~~~~~~~~~~~~~~~~~~~~~~~~~~~~~~~~~~~~~~~~~~~~^^   File "/Users/nagabhaskar.alaparthi/hackweek-ai-debugger/services/example_service.py", line 23, in simulate_divide_by_zero_error     raise RuntimeError("A division by zero error occurred.") from e RuntimeError: A division by zero error occurred. 

2025-04-21 12:46:17,513 - INFO - Starting log monitoring for file: application.log
2025-04-21 12:46:27,549 - INFO - Error detected: 2025-04-21 12:46:27,101 - ERROR - Unhandled exception: Traceback (most recent call last):   File "/Users/nagabhaskar.alaparthi/hackweek-ai-debugger/services/example_service.py", line 21, in simulate_divide_by_zero_error     result = 1 / 0              ~~^~~ ZeroDivisionError: division by zero  The above exception was the direct cause of the following exception:  Traceback (most recent call last):   File "/Users/nagabhaskar.alaparthi/hackweek-ai-debugger/venv/lib/python3.13/site-packages/starlette/middleware/errors.py", line 165, in __call__     await self.app(scope, receive, _send)   File "/Users/nagabhaskar.alaparthi/hackweek-ai-debugger/venv/lib/python3.13/site-packages/starlette/middleware/exceptions.py", line 62, in __call__     await wrap_app_handling_exceptions(self.app, conn)(scope, receive, send)   File "/Users/nagabhaskar.alaparthi/hackweek-ai-debugger/venv/lib/python3.13/site-packages/starlette/_exception_handler.py", line 53, in wrapped_app     raise exc   File "/Users/nagabhaskar.alaparthi/hackweek-ai-debugger/venv/lib/python3.13/site-packages/starlette/_exception_handler.py", line 42, in wrapped_app     await app(scope, receive, sender)   File "/Users/nagabhaskar.alaparthi/hackweek-ai-debugger/venv/lib/python3.13/site-packages/starlette/routing.py", line 714, in __call__     await self.middleware_stack(scope, receive, send)   File "/Users/nagabhaskar.alaparthi/hackweek-ai-debugger/venv/lib/python3.13/site-packages/starlette/routing.py", line 734, in app     await route.handle(scope, receive, send)   File "/Users/nagabhaskar.alaparthi/hackweek-ai-debugger/venv/lib/python3.13/site-packages/starlette/routing.py", line 288, in handle     await self.app(scope, receive, send)   File "/Users/nagabhaskar.alaparthi/hackweek-ai-debugger/venv/lib/python3.13/site-packages/starlette/routing.py", line 76, in app     await wrap_app_handling_exceptions(app, request)(scope, receive, send)   File "/Users/nagabhaskar.alaparthi/hackweek-ai-debugger/venv/lib/python3.13/site-packages/starlette/_exception_handler.py", line 53, in wrapped_app     raise exc   File "/Users/nagabhaskar.alaparthi/hackweek-ai-debugger/venv/lib/python3.13/site-packages/starlette/_exception_handler.py", line 42, in wrapped_app     await app(scope, receive, sender)   File "/Users/nagabhaskar.alaparthi/hackweek-ai-debugger/venv/lib/python3.13/site-packages/starlette/routing.py", line 73, in app     response = await f(request)                ^^^^^^^^^^^^^^^^   File "/Users/nagabhaskar.alaparthi/hackweek-ai-debugger/venv/lib/python3.13/site-packages/fastapi/routing.py", line 301, in app     raw_response = await run_endpoint_function(                    ^^^^^^^^^^^^^^^^^^^^^^^^^^^^     ...<3 lines>...     )     ^   File "/Users/nagabhaskar.alaparthi/hackweek-ai-debugger/venv/lib/python3.13/site-packages/fastapi/routing.py", line 214, in run_endpoint_function     return await run_in_threadpool(dependant.call, **values)            ^^^^^^^^^^^^^^^^^^^^^^^^^^^^^^^^^^^^^^^^^^^^^^^^^   File "/Users/nagabhaskar.alaparthi/hackweek-ai-debugger/venv/lib/python3.13/site-packages/starlette/concurrency.py", line 37, in run_in_threadpool     return await anyio.to_thread.run_sync(func)            ^^^^^^^^^^^^^^^^^^^^^^^^^^^^^^^^^^^^   File "/Users/nagabhaskar.alaparthi/hackweek-ai-debugger/venv/lib/python3.13/site-packages/anyio/to_thread.py", line 56, in run_sync     return await get_async_backend().run_sync_in_worker_thread(            ^^^^^^^^^^^^^^^^^^^^^^^^^^^^^^^^^^^^^^^^^^^^^^^^^^^^         func, args, abandon_on_cancel=abandon_on_cancel, limiter=limiter         ^^^^^^^^^^^^^^^^^^^^^^^^^^^^^^^^^^^^^^^^^^^^^^^^^^^^^^^^^^^^^^^^     )     ^   File "/Users/nagabhaskar.alaparthi/hackweek-ai-debugger/venv/lib/python3.13/site-packages/anyio/_backends/_asyncio.py", line 2470, in run_sync_in_worker_thread     return await future            ^^^^^^^^^^^^   File "/Users/nagabhaskar.alaparthi/hackweek-ai-debugger/venv/lib/python3.13/site-packages/anyio/_backends/_asyncio.py", line 967, in run     result = context.run(func, *args)   File "/Users/nagabhaskar.alaparthi/hackweek-ai-debugger/routers/example_router.py", line 20, in trigger_divide_by_zero_error     return ExampleService.simulate_divide_by_zero_error()            ~~~~~~~~~~~~~~~~~~~~~~~~~~~~~~~~~~~~~~~~~~~~^^   File "/Users/nagabhaskar.alaparthi/hackweek-ai-debugger/services/example_service.py", line 23, in simulate_divide_by_zero_error     raise RuntimeError("A division by zero error occurred.") from e RuntimeError: A division by zero error occurred.
2025-04-21 12:46:27,551 - INFO - Extracted method code: 
    @staticmethod
    def simulate_divide_by_zero_error():
        try:
            # Simulate a divide by zero error
            result = 1 / 0
        except ZeroDivisionError as e:
            raise RuntimeError("A division by zero error occurred.") from e


2025-04-21 12:46:27,551 - INFO - Processing error message: 2025-04-21 12:46:27,101 - ERROR - Unhandled exception: Traceback (most recent call last):   File "/Users/nagabhaskar.alaparthi/hackweek-ai-debugger/services/example_service.py", line 21, in simulate_divide_by_zero_error     result = 1 / 0              ~~^~~ ZeroDivisionError: division by zero  The above exception was the direct cause of the following exception:  Traceback (most recent call last):   File "/Users/nagabhaskar.alaparthi/hackweek-ai-debugger/venv/lib/python3.13/site-packages/starlette/middleware/errors.py", line 165, in __call__     await self.app(scope, receive, _send)   File "/Users/nagabhaskar.alaparthi/hackweek-ai-debugger/venv/lib/python3.13/site-packages/starlette/middleware/exceptions.py", line 62, in __call__     await wrap_app_handling_exceptions(self.app, conn)(scope, receive, send)   File "/Users/nagabhaskar.alaparthi/hackweek-ai-debugger/venv/lib/python3.13/site-packages/starlette/_exception_handler.py", line 53, in wrapped_app     raise exc   File "/Users/nagabhaskar.alaparthi/hackweek-ai-debugger/venv/lib/python3.13/site-packages/starlette/_exception_handler.py", line 42, in wrapped_app     await app(scope, receive, sender)   File "/Users/nagabhaskar.alaparthi/hackweek-ai-debugger/venv/lib/python3.13/site-packages/starlette/routing.py", line 714, in __call__     await self.middleware_stack(scope, receive, send)   File "/Users/nagabhaskar.alaparthi/hackweek-ai-debugger/venv/lib/python3.13/site-packages/starlette/routing.py", line 734, in app     await route.handle(scope, receive, send)   File "/Users/nagabhaskar.alaparthi/hackweek-ai-debugger/venv/lib/python3.13/site-packages/starlette/routing.py", line 288, in handle     await self.app(scope, receive, send)   File "/Users/nagabhaskar.alaparthi/hackweek-ai-debugger/venv/lib/python3.13/site-packages/starlette/routing.py", line 76, in app     await wrap_app_handling_exceptions(app, request)(scope, receive, send)   File "/Users/nagabhaskar.alaparthi/hackweek-ai-debugger/venv/lib/python3.13/site-packages/starlette/_exception_handler.py", line 53, in wrapped_app     raise exc   File "/Users/nagabhaskar.alaparthi/hackweek-ai-debugger/venv/lib/python3.13/site-packages/starlette/_exception_handler.py", line 42, in wrapped_app     await app(scope, receive, sender)   File "/Users/nagabhaskar.alaparthi/hackweek-ai-debugger/venv/lib/python3.13/site-packages/starlette/routing.py", line 73, in app     response = await f(request)                ^^^^^^^^^^^^^^^^   File "/Users/nagabhaskar.alaparthi/hackweek-ai-debugger/venv/lib/python3.13/site-packages/fastapi/routing.py", line 301, in app     raw_response = await run_endpoint_function(                    ^^^^^^^^^^^^^^^^^^^^^^^^^^^^     ...<3 lines>...     )     ^   File "/Users/nagabhaskar.alaparthi/hackweek-ai-debugger/venv/lib/python3.13/site-packages/fastapi/routing.py", line 214, in run_endpoint_function     return await run_in_threadpool(dependant.call, **values)            ^^^^^^^^^^^^^^^^^^^^^^^^^^^^^^^^^^^^^^^^^^^^^^^^^   File "/Users/nagabhaskar.alaparthi/hackweek-ai-debugger/venv/lib/python3.13/site-packages/starlette/concurrency.py", line 37, in run_in_threadpool     return await anyio.to_thread.run_sync(func)            ^^^^^^^^^^^^^^^^^^^^^^^^^^^^^^^^^^^^   File "/Users/nagabhaskar.alaparthi/hackweek-ai-debugger/venv/lib/python3.13/site-packages/anyio/to_thread.py", line 56, in run_sync     return await get_async_backend().run_sync_in_worker_thread(            ^^^^^^^^^^^^^^^^^^^^^^^^^^^^^^^^^^^^^^^^^^^^^^^^^^^^         func, args, abandon_on_cancel=abandon_on_cancel, limiter=limiter         ^^^^^^^^^^^^^^^^^^^^^^^^^^^^^^^^^^^^^^^^^^^^^^^^^^^^^^^^^^^^^^^^     )     ^   File "/Users/nagabhaskar.alaparthi/hackweek-ai-debugger/venv/lib/python3.13/site-packages/anyio/_backends/_asyncio.py", line 2470, in run_sync_in_worker_thread     return await future            ^^^^^^^^^^^^   File "/Users/nagabhaskar.alaparthi/hackweek-ai-debugger/venv/lib/python3.13/site-packages/anyio/_backends/_asyncio.py", line 967, in run     result = context.run(func, *args)   File "/Users/nagabhaskar.alaparthi/hackweek-ai-debugger/routers/example_router.py", line 20, in trigger_divide_by_zero_error     return ExampleService.simulate_divide_by_zero_error()            ~~~~~~~~~~~~~~~~~~~~~~~~~~~~~~~~~~~~~~~~~~~~^^   File "/Users/nagabhaskar.alaparthi/hackweek-ai-debugger/services/example_service.py", line 23, in simulate_divide_by_zero_error     raise RuntimeError("A division by zero error occurred.") from e RuntimeError: A division by zero error occurred. 
2025-04-21 12:46:27,551 - INFO - Processing method code: 
    @staticmethod
    def simulate_divide_by_zero_error():
        try:
            # Simulate a divide by zero error
            result = 1 / 0
        except ZeroDivisionError as e:
            raise RuntimeError("A division by zero error occurred.") from e


2025-04-21 12:56:34,390 - INFO - Starting log monitoring for file: application.log
2025-04-21 12:56:44,435 - INFO - Error detected: 2025-04-21 12:56:43,634 - ERROR - Unhandled exception: Traceback (most recent call last):   File "/Users/nagabhaskar.alaparthi/hackweek-ai-debugger/services/example_service.py", line 21, in simulate_divide_by_zero_error     result = 1 / 0              ~~^~~ ZeroDivisionError: division by zero  The above exception was the direct cause of the following exception:  Traceback (most recent call last):   File "/Users/nagabhaskar.alaparthi/hackweek-ai-debugger/venv/lib/python3.13/site-packages/starlette/middleware/errors.py", line 165, in __call__     await self.app(scope, receive, _send)   File "/Users/nagabhaskar.alaparthi/hackweek-ai-debugger/venv/lib/python3.13/site-packages/starlette/middleware/exceptions.py", line 62, in __call__     await wrap_app_handling_exceptions(self.app, conn)(scope, receive, send)   File "/Users/nagabhaskar.alaparthi/hackweek-ai-debugger/venv/lib/python3.13/site-packages/starlette/_exception_handler.py", line 53, in wrapped_app     raise exc   File "/Users/nagabhaskar.alaparthi/hackweek-ai-debugger/venv/lib/python3.13/site-packages/starlette/_exception_handler.py", line 42, in wrapped_app     await app(scope, receive, sender)   File "/Users/nagabhaskar.alaparthi/hackweek-ai-debugger/venv/lib/python3.13/site-packages/starlette/routing.py", line 714, in __call__     await self.middleware_stack(scope, receive, send)   File "/Users/nagabhaskar.alaparthi/hackweek-ai-debugger/venv/lib/python3.13/site-packages/starlette/routing.py", line 734, in app     await route.handle(scope, receive, send)   File "/Users/nagabhaskar.alaparthi/hackweek-ai-debugger/venv/lib/python3.13/site-packages/starlette/routing.py", line 288, in handle     await self.app(scope, receive, send)   File "/Users/nagabhaskar.alaparthi/hackweek-ai-debugger/venv/lib/python3.13/site-packages/starlette/routing.py", line 76, in app     await wrap_app_handling_exceptions(app, request)(scope, receive, send)   File "/Users/nagabhaskar.alaparthi/hackweek-ai-debugger/venv/lib/python3.13/site-packages/starlette/_exception_handler.py", line 53, in wrapped_app     raise exc   File "/Users/nagabhaskar.alaparthi/hackweek-ai-debugger/venv/lib/python3.13/site-packages/starlette/_exception_handler.py", line 42, in wrapped_app     await app(scope, receive, sender)   File "/Users/nagabhaskar.alaparthi/hackweek-ai-debugger/venv/lib/python3.13/site-packages/starlette/routing.py", line 73, in app     response = await f(request)                ^^^^^^^^^^^^^^^^   File "/Users/nagabhaskar.alaparthi/hackweek-ai-debugger/venv/lib/python3.13/site-packages/fastapi/routing.py", line 301, in app     raw_response = await run_endpoint_function(                    ^^^^^^^^^^^^^^^^^^^^^^^^^^^^     ...<3 lines>...     )     ^   File "/Users/nagabhaskar.alaparthi/hackweek-ai-debugger/venv/lib/python3.13/site-packages/fastapi/routing.py", line 214, in run_endpoint_function     return await run_in_threadpool(dependant.call, **values)            ^^^^^^^^^^^^^^^^^^^^^^^^^^^^^^^^^^^^^^^^^^^^^^^^^   File "/Users/nagabhaskar.alaparthi/hackweek-ai-debugger/venv/lib/python3.13/site-packages/starlette/concurrency.py", line 37, in run_in_threadpool     return await anyio.to_thread.run_sync(func)            ^^^^^^^^^^^^^^^^^^^^^^^^^^^^^^^^^^^^   File "/Users/nagabhaskar.alaparthi/hackweek-ai-debugger/venv/lib/python3.13/site-packages/anyio/to_thread.py", line 56, in run_sync     return await get_async_backend().run_sync_in_worker_thread(            ^^^^^^^^^^^^^^^^^^^^^^^^^^^^^^^^^^^^^^^^^^^^^^^^^^^^         func, args, abandon_on_cancel=abandon_on_cancel, limiter=limiter         ^^^^^^^^^^^^^^^^^^^^^^^^^^^^^^^^^^^^^^^^^^^^^^^^^^^^^^^^^^^^^^^^     )     ^   File "/Users/nagabhaskar.alaparthi/hackweek-ai-debugger/venv/lib/python3.13/site-packages/anyio/_backends/_asyncio.py", line 2470, in run_sync_in_worker_thread     return await future            ^^^^^^^^^^^^   File "/Users/nagabhaskar.alaparthi/hackweek-ai-debugger/venv/lib/python3.13/site-packages/anyio/_backends/_asyncio.py", line 967, in run     result = context.run(func, *args)   File "/Users/nagabhaskar.alaparthi/hackweek-ai-debugger/routers/example_router.py", line 20, in trigger_divide_by_zero_error     return ExampleService.simulate_divide_by_zero_error()            ~~~~~~~~~~~~~~~~~~~~~~~~~~~~~~~~~~~~~~~~~~~~^^   File "/Users/nagabhaskar.alaparthi/hackweek-ai-debugger/services/example_service.py", line 23, in simulate_divide_by_zero_error     raise RuntimeError("A division by zero error occurred.") from e RuntimeError: A division by zero error occurred.
2025-04-21 12:56:44,436 - INFO - Extracted method code: 
    @staticmethod
    def simulate_divide_by_zero_error():
        try:
            # Simulate a divide by zero error
            result = 1 / 0
        except ZeroDivisionError as e:
            raise RuntimeError("A division by zero error occurred.") from e


2025-04-21 12:56:44,436 - INFO - Processing error message: 2025-04-21 12:56:43,634 - ERROR - Unhandled exception: Traceback (most recent call last):   File "/Users/nagabhaskar.alaparthi/hackweek-ai-debugger/services/example_service.py", line 21, in simulate_divide_by_zero_error     result = 1 / 0              ~~^~~ ZeroDivisionError: division by zero  The above exception was the direct cause of the following exception:  Traceback (most recent call last):   File "/Users/nagabhaskar.alaparthi/hackweek-ai-debugger/venv/lib/python3.13/site-packages/starlette/middleware/errors.py", line 165, in __call__     await self.app(scope, receive, _send)   File "/Users/nagabhaskar.alaparthi/hackweek-ai-debugger/venv/lib/python3.13/site-packages/starlette/middleware/exceptions.py", line 62, in __call__     await wrap_app_handling_exceptions(self.app, conn)(scope, receive, send)   File "/Users/nagabhaskar.alaparthi/hackweek-ai-debugger/venv/lib/python3.13/site-packages/starlette/_exception_handler.py", line 53, in wrapped_app     raise exc   File "/Users/nagabhaskar.alaparthi/hackweek-ai-debugger/venv/lib/python3.13/site-packages/starlette/_exception_handler.py", line 42, in wrapped_app     await app(scope, receive, sender)   File "/Users/nagabhaskar.alaparthi/hackweek-ai-debugger/venv/lib/python3.13/site-packages/starlette/routing.py", line 714, in __call__     await self.middleware_stack(scope, receive, send)   File "/Users/nagabhaskar.alaparthi/hackweek-ai-debugger/venv/lib/python3.13/site-packages/starlette/routing.py", line 734, in app     await route.handle(scope, receive, send)   File "/Users/nagabhaskar.alaparthi/hackweek-ai-debugger/venv/lib/python3.13/site-packages/starlette/routing.py", line 288, in handle     await self.app(scope, receive, send)   File "/Users/nagabhaskar.alaparthi/hackweek-ai-debugger/venv/lib/python3.13/site-packages/starlette/routing.py", line 76, in app     await wrap_app_handling_exceptions(app, request)(scope, receive, send)   File "/Users/nagabhaskar.alaparthi/hackweek-ai-debugger/venv/lib/python3.13/site-packages/starlette/_exception_handler.py", line 53, in wrapped_app     raise exc   File "/Users/nagabhaskar.alaparthi/hackweek-ai-debugger/venv/lib/python3.13/site-packages/starlette/_exception_handler.py", line 42, in wrapped_app     await app(scope, receive, sender)   File "/Users/nagabhaskar.alaparthi/hackweek-ai-debugger/venv/lib/python3.13/site-packages/starlette/routing.py", line 73, in app     response = await f(request)                ^^^^^^^^^^^^^^^^   File "/Users/nagabhaskar.alaparthi/hackweek-ai-debugger/venv/lib/python3.13/site-packages/fastapi/routing.py", line 301, in app     raw_response = await run_endpoint_function(                    ^^^^^^^^^^^^^^^^^^^^^^^^^^^^     ...<3 lines>...     )     ^   File "/Users/nagabhaskar.alaparthi/hackweek-ai-debugger/venv/lib/python3.13/site-packages/fastapi/routing.py", line 214, in run_endpoint_function     return await run_in_threadpool(dependant.call, **values)            ^^^^^^^^^^^^^^^^^^^^^^^^^^^^^^^^^^^^^^^^^^^^^^^^^   File "/Users/nagabhaskar.alaparthi/hackweek-ai-debugger/venv/lib/python3.13/site-packages/starlette/concurrency.py", line 37, in run_in_threadpool     return await anyio.to_thread.run_sync(func)            ^^^^^^^^^^^^^^^^^^^^^^^^^^^^^^^^^^^^   File "/Users/nagabhaskar.alaparthi/hackweek-ai-debugger/venv/lib/python3.13/site-packages/anyio/to_thread.py", line 56, in run_sync     return await get_async_backend().run_sync_in_worker_thread(            ^^^^^^^^^^^^^^^^^^^^^^^^^^^^^^^^^^^^^^^^^^^^^^^^^^^^         func, args, abandon_on_cancel=abandon_on_cancel, limiter=limiter         ^^^^^^^^^^^^^^^^^^^^^^^^^^^^^^^^^^^^^^^^^^^^^^^^^^^^^^^^^^^^^^^^     )     ^   File "/Users/nagabhaskar.alaparthi/hackweek-ai-debugger/venv/lib/python3.13/site-packages/anyio/_backends/_asyncio.py", line 2470, in run_sync_in_worker_thread     return await future            ^^^^^^^^^^^^   File "/Users/nagabhaskar.alaparthi/hackweek-ai-debugger/venv/lib/python3.13/site-packages/anyio/_backends/_asyncio.py", line 967, in run     result = context.run(func, *args)   File "/Users/nagabhaskar.alaparthi/hackweek-ai-debugger/routers/example_router.py", line 20, in trigger_divide_by_zero_error     return ExampleService.simulate_divide_by_zero_error()            ~~~~~~~~~~~~~~~~~~~~~~~~~~~~~~~~~~~~~~~~~~~~^^   File "/Users/nagabhaskar.alaparthi/hackweek-ai-debugger/services/example_service.py", line 23, in simulate_divide_by_zero_error     raise RuntimeError("A division by zero error occurred.") from e RuntimeError: A division by zero error occurred. 

2025-04-21 12:56:44,436 - INFO - Processing method code: 
    @staticmethod
    def simulate_divide_by_zero_error():
        try:
            # Simulate a divide by zero error
            result = 1 / 0
        except ZeroDivisionError as e:
            raise RuntimeError("A division by zero error occurred.") from e


2025-04-21 12:56:47,598 - INFO - AI Response: {'version': '1', 'choices': [{'text': 'The error you\'re encountering is a `ZeroDivisionError`, which occurs when you attempt to divide by zero in the line `result = 1 / 0`. This is happening within the `simulate_divide_by_zero_error` method.\n\nTo resolve this issue, you can modify the code to handle the division operation safely. Here’s a possible solution:\n\n```python\n@staticmethod\ndef simulate_divide_by_zero_error():\n    try:\n        # Check if the divisor is zero before performing the division\n        divisor = 0\n        if divisor == 0:\n            raise ValueError("Divisor cannot be zero.")\n        result = 1 / divisor\n    except (ZeroDivisionError, ValueError) as e:\n        raise RuntimeError("A division by zero error occurred.") from e\n```\n\nThis way, you prevent the division by zero by checking if the divisor is zero beforehand and raising an appropriate error if it is.', 'duration': 1.9191517739964183, 'references': []}], 'model': 'gpt-4o-mini-128k-2024-07-18', 'feedback_id': 'v1_highspot.com_53542d42-d578-40f9-9908-e87a1ba63c51', 'domain_id': 'highspot.com'}
2025-04-21 12:58:28,013 - INFO - Error detected: 2025-04-21 12:58:27,751 - ERROR - Unhandled exception: Traceback (most recent call last):   File "/Users/nagabhaskar.alaparthi/hackweek-ai-debugger/services/example_service.py", line 21, in simulate_divide_by_zero_error     result = 1 / 0              ~~^~~ ZeroDivisionError: division by zero  The above exception was the direct cause of the following exception:  Traceback (most recent call last):   File "/Users/nagabhaskar.alaparthi/hackweek-ai-debugger/venv/lib/python3.13/site-packages/starlette/middleware/errors.py", line 165, in __call__     await self.app(scope, receive, _send)   File "/Users/nagabhaskar.alaparthi/hackweek-ai-debugger/venv/lib/python3.13/site-packages/starlette/middleware/exceptions.py", line 62, in __call__     await wrap_app_handling_exceptions(self.app, conn)(scope, receive, send)   File "/Users/nagabhaskar.alaparthi/hackweek-ai-debugger/venv/lib/python3.13/site-packages/starlette/_exception_handler.py", line 53, in wrapped_app     raise exc   File "/Users/nagabhaskar.alaparthi/hackweek-ai-debugger/venv/lib/python3.13/site-packages/starlette/_exception_handler.py", line 42, in wrapped_app     await app(scope, receive, sender)   File "/Users/nagabhaskar.alaparthi/hackweek-ai-debugger/venv/lib/python3.13/site-packages/starlette/routing.py", line 714, in __call__     await self.middleware_stack(scope, receive, send)   File "/Users/nagabhaskar.alaparthi/hackweek-ai-debugger/venv/lib/python3.13/site-packages/starlette/routing.py", line 734, in app     await route.handle(scope, receive, send)   File "/Users/nagabhaskar.alaparthi/hackweek-ai-debugger/venv/lib/python3.13/site-packages/starlette/routing.py", line 288, in handle     await self.app(scope, receive, send)   File "/Users/nagabhaskar.alaparthi/hackweek-ai-debugger/venv/lib/python3.13/site-packages/starlette/routing.py", line 76, in app     await wrap_app_handling_exceptions(app, request)(scope, receive, send)   File "/Users/nagabhaskar.alaparthi/hackweek-ai-debugger/venv/lib/python3.13/site-packages/starlette/_exception_handler.py", line 53, in wrapped_app     raise exc   File "/Users/nagabhaskar.alaparthi/hackweek-ai-debugger/venv/lib/python3.13/site-packages/starlette/_exception_handler.py", line 42, in wrapped_app     await app(scope, receive, sender)   File "/Users/nagabhaskar.alaparthi/hackweek-ai-debugger/venv/lib/python3.13/site-packages/starlette/routing.py", line 73, in app     response = await f(request)                ^^^^^^^^^^^^^^^^   File "/Users/nagabhaskar.alaparthi/hackweek-ai-debugger/venv/lib/python3.13/site-packages/fastapi/routing.py", line 301, in app     raw_response = await run_endpoint_function(                    ^^^^^^^^^^^^^^^^^^^^^^^^^^^^     ...<3 lines>...     )     ^   File "/Users/nagabhaskar.alaparthi/hackweek-ai-debugger/venv/lib/python3.13/site-packages/fastapi/routing.py", line 214, in run_endpoint_function     return await run_in_threadpool(dependant.call, **values)            ^^^^^^^^^^^^^^^^^^^^^^^^^^^^^^^^^^^^^^^^^^^^^^^^^   File "/Users/nagabhaskar.alaparthi/hackweek-ai-debugger/venv/lib/python3.13/site-packages/starlette/concurrency.py", line 37, in run_in_threadpool     return await anyio.to_thread.run_sync(func)            ^^^^^^^^^^^^^^^^^^^^^^^^^^^^^^^^^^^^   File "/Users/nagabhaskar.alaparthi/hackweek-ai-debugger/venv/lib/python3.13/site-packages/anyio/to_thread.py", line 56, in run_sync     return await get_async_backend().run_sync_in_worker_thread(            ^^^^^^^^^^^^^^^^^^^^^^^^^^^^^^^^^^^^^^^^^^^^^^^^^^^^         func, args, abandon_on_cancel=abandon_on_cancel, limiter=limiter         ^^^^^^^^^^^^^^^^^^^^^^^^^^^^^^^^^^^^^^^^^^^^^^^^^^^^^^^^^^^^^^^^     )     ^   File "/Users/nagabhaskar.alaparthi/hackweek-ai-debugger/venv/lib/python3.13/site-packages/anyio/_backends/_asyncio.py", line 2470, in run_sync_in_worker_thread     return await future            ^^^^^^^^^^^^   File "/Users/nagabhaskar.alaparthi/hackweek-ai-debugger/venv/lib/python3.13/site-packages/anyio/_backends/_asyncio.py", line 967, in run     result = context.run(func, *args)   File "/Users/nagabhaskar.alaparthi/hackweek-ai-debugger/routers/example_router.py", line 20, in trigger_divide_by_zero_error     return ExampleService.simulate_divide_by_zero_error()            ~~~~~~~~~~~~~~~~~~~~~~~~~~~~~~~~~~~~~~~~~~~~^^   File "/Users/nagabhaskar.alaparthi/hackweek-ai-debugger/services/example_service.py", line 23, in simulate_divide_by_zero_error     raise RuntimeError("A division by zero error occurred.") from e RuntimeError: A division by zero error occurred.
2025-04-21 12:58:28,013 - INFO - Extracted method code: 
    @staticmethod
    def simulate_divide_by_zero_error():
        try:
            # Simulate a divide by zero error
            result = 1 / 0
        except ZeroDivisionError as e:
            raise RuntimeError("A division by zero error occurred.") from e


2025-04-21 12:58:28,014 - INFO - Processing error message: 2025-04-21 12:58:27,751 - ERROR - Unhandled exception: Traceback (most recent call last):   File "/Users/nagabhaskar.alaparthi/hackweek-ai-debugger/services/example_service.py", line 21, in simulate_divide_by_zero_error     result = 1 / 0              ~~^~~ ZeroDivisionError: division by zero  The above exception was the direct cause of the following exception:  Traceback (most recent call last):   File "/Users/nagabhaskar.alaparthi/hackweek-ai-debugger/venv/lib/python3.13/site-packages/starlette/middleware/errors.py", line 165, in __call__     await self.app(scope, receive, _send)   File "/Users/nagabhaskar.alaparthi/hackweek-ai-debugger/venv/lib/python3.13/site-packages/starlette/middleware/exceptions.py", line 62, in __call__     await wrap_app_handling_exceptions(self.app, conn)(scope, receive, send)   File "/Users/nagabhaskar.alaparthi/hackweek-ai-debugger/venv/lib/python3.13/site-packages/starlette/_exception_handler.py", line 53, in wrapped_app     raise exc   File "/Users/nagabhaskar.alaparthi/hackweek-ai-debugger/venv/lib/python3.13/site-packages/starlette/_exception_handler.py", line 42, in wrapped_app     await app(scope, receive, sender)   File "/Users/nagabhaskar.alaparthi/hackweek-ai-debugger/venv/lib/python3.13/site-packages/starlette/routing.py", line 714, in __call__     await self.middleware_stack(scope, receive, send)   File "/Users/nagabhaskar.alaparthi/hackweek-ai-debugger/venv/lib/python3.13/site-packages/starlette/routing.py", line 734, in app     await route.handle(scope, receive, send)   File "/Users/nagabhaskar.alaparthi/hackweek-ai-debugger/venv/lib/python3.13/site-packages/starlette/routing.py", line 288, in handle     await self.app(scope, receive, send)   File "/Users/nagabhaskar.alaparthi/hackweek-ai-debugger/venv/lib/python3.13/site-packages/starlette/routing.py", line 76, in app     await wrap_app_handling_exceptions(app, request)(scope, receive, send)   File "/Users/nagabhaskar.alaparthi/hackweek-ai-debugger/venv/lib/python3.13/site-packages/starlette/_exception_handler.py", line 53, in wrapped_app     raise exc   File "/Users/nagabhaskar.alaparthi/hackweek-ai-debugger/venv/lib/python3.13/site-packages/starlette/_exception_handler.py", line 42, in wrapped_app     await app(scope, receive, sender)   File "/Users/nagabhaskar.alaparthi/hackweek-ai-debugger/venv/lib/python3.13/site-packages/starlette/routing.py", line 73, in app     response = await f(request)                ^^^^^^^^^^^^^^^^   File "/Users/nagabhaskar.alaparthi/hackweek-ai-debugger/venv/lib/python3.13/site-packages/fastapi/routing.py", line 301, in app     raw_response = await run_endpoint_function(                    ^^^^^^^^^^^^^^^^^^^^^^^^^^^^     ...<3 lines>...     )     ^   File "/Users/nagabhaskar.alaparthi/hackweek-ai-debugger/venv/lib/python3.13/site-packages/fastapi/routing.py", line 214, in run_endpoint_function     return await run_in_threadpool(dependant.call, **values)            ^^^^^^^^^^^^^^^^^^^^^^^^^^^^^^^^^^^^^^^^^^^^^^^^^   File "/Users/nagabhaskar.alaparthi/hackweek-ai-debugger/venv/lib/python3.13/site-packages/starlette/concurrency.py", line 37, in run_in_threadpool     return await anyio.to_thread.run_sync(func)            ^^^^^^^^^^^^^^^^^^^^^^^^^^^^^^^^^^^^   File "/Users/nagabhaskar.alaparthi/hackweek-ai-debugger/venv/lib/python3.13/site-packages/anyio/to_thread.py", line 56, in run_sync     return await get_async_backend().run_sync_in_worker_thread(            ^^^^^^^^^^^^^^^^^^^^^^^^^^^^^^^^^^^^^^^^^^^^^^^^^^^^         func, args, abandon_on_cancel=abandon_on_cancel, limiter=limiter         ^^^^^^^^^^^^^^^^^^^^^^^^^^^^^^^^^^^^^^^^^^^^^^^^^^^^^^^^^^^^^^^^     )     ^   File "/Users/nagabhaskar.alaparthi/hackweek-ai-debugger/venv/lib/python3.13/site-packages/anyio/_backends/_asyncio.py", line 2470, in run_sync_in_worker_thread     return await future            ^^^^^^^^^^^^   File "/Users/nagabhaskar.alaparthi/hackweek-ai-debugger/venv/lib/python3.13/site-packages/anyio/_backends/_asyncio.py", line 967, in run     result = context.run(func, *args)   File "/Users/nagabhaskar.alaparthi/hackweek-ai-debugger/routers/example_router.py", line 20, in trigger_divide_by_zero_error     return ExampleService.simulate_divide_by_zero_error()            ~~~~~~~~~~~~~~~~~~~~~~~~~~~~~~~~~~~~~~~~~~~~^^   File "/Users/nagabhaskar.alaparthi/hackweek-ai-debugger/services/example_service.py", line 23, in simulate_divide_by_zero_error     raise RuntimeError("A division by zero error occurred.") from e RuntimeError: A division by zero error occurred. 

2025-04-21 12:58:28,014 - INFO - Processing method code: 
    @staticmethod
    def simulate_divide_by_zero_error():
        try:
            # Simulate a divide by zero error
            result = 1 / 0
        except ZeroDivisionError as e:
            raise RuntimeError("A division by zero error occurred.") from e


2025-04-21 12:58:32,118 - INFO - AI Response: {'version': '1', 'choices': [{'text': 'The error you\'re encountering is a `ZeroDivisionError` caused by attempting to divide by zero in the `simulate_divide_by_zero_error` method. \n\nTo resolve this issue, you can modify the code to check for zero before performing the division. Here\'s a possible solution:\n\n```python\n@staticmethod\ndef simulate_divide_by_zero_error():\n    try:\n        # Simulate a divide by zero error\n        denominator = 0  # This could be any variable that might be zero\n        if denominator == 0:\n            raise ValueError("Denominator cannot be zero.")\n        result = 1 / denominator\n    except (ZeroDivisionError, ValueError) as e:\n        raise RuntimeError("A division by zero error occurred.") from e\n```\n\nThis way, you prevent the division by zero error by raising a `ValueError` if the denominator is zero, which can be caught and handled appropriately.', 'duration': 2.863182218745351, 'references': []}], 'model': 'gpt-4o-mini-128k-2024-07-18', 'feedback_id': 'v1_highspot.com_a8a884d0-6533-44ba-a28a-36044da1397c', 'domain_id': 'highspot.com'}
2025-04-21 12:59:12,755 - INFO - Starting log monitoring for file: application.log
2025-04-21 12:59:15,764 - INFO - Error detected: 2025-04-21 12:59:14,866 - ERROR - Unhandled exception: Traceback (most recent call last):   File "/Users/nagabhaskar.alaparthi/hackweek-ai-debugger/services/example_service.py", line 21, in simulate_divide_by_zero_error     result = 1 / 0              ~~^~~ ZeroDivisionError: division by zero  The above exception was the direct cause of the following exception:  Traceback (most recent call last):   File "/Users/nagabhaskar.alaparthi/hackweek-ai-debugger/venv/lib/python3.13/site-packages/starlette/middleware/errors.py", line 165, in __call__     await self.app(scope, receive, _send)   File "/Users/nagabhaskar.alaparthi/hackweek-ai-debugger/venv/lib/python3.13/site-packages/starlette/middleware/exceptions.py", line 62, in __call__     await wrap_app_handling_exceptions(self.app, conn)(scope, receive, send)   File "/Users/nagabhaskar.alaparthi/hackweek-ai-debugger/venv/lib/python3.13/site-packages/starlette/_exception_handler.py", line 53, in wrapped_app     raise exc   File "/Users/nagabhaskar.alaparthi/hackweek-ai-debugger/venv/lib/python3.13/site-packages/starlette/_exception_handler.py", line 42, in wrapped_app     await app(scope, receive, sender)   File "/Users/nagabhaskar.alaparthi/hackweek-ai-debugger/venv/lib/python3.13/site-packages/starlette/routing.py", line 714, in __call__     await self.middleware_stack(scope, receive, send)   File "/Users/nagabhaskar.alaparthi/hackweek-ai-debugger/venv/lib/python3.13/site-packages/starlette/routing.py", line 734, in app     await route.handle(scope, receive, send)   File "/Users/nagabhaskar.alaparthi/hackweek-ai-debugger/venv/lib/python3.13/site-packages/starlette/routing.py", line 288, in handle     await self.app(scope, receive, send)   File "/Users/nagabhaskar.alaparthi/hackweek-ai-debugger/venv/lib/python3.13/site-packages/starlette/routing.py", line 76, in app     await wrap_app_handling_exceptions(app, request)(scope, receive, send)   File "/Users/nagabhaskar.alaparthi/hackweek-ai-debugger/venv/lib/python3.13/site-packages/starlette/_exception_handler.py", line 53, in wrapped_app     raise exc   File "/Users/nagabhaskar.alaparthi/hackweek-ai-debugger/venv/lib/python3.13/site-packages/starlette/_exception_handler.py", line 42, in wrapped_app     await app(scope, receive, sender)   File "/Users/nagabhaskar.alaparthi/hackweek-ai-debugger/venv/lib/python3.13/site-packages/starlette/routing.py", line 73, in app     response = await f(request)                ^^^^^^^^^^^^^^^^   File "/Users/nagabhaskar.alaparthi/hackweek-ai-debugger/venv/lib/python3.13/site-packages/fastapi/routing.py", line 301, in app     raw_response = await run_endpoint_function(                    ^^^^^^^^^^^^^^^^^^^^^^^^^^^^     ...<3 lines>...     )     ^   File "/Users/nagabhaskar.alaparthi/hackweek-ai-debugger/venv/lib/python3.13/site-packages/fastapi/routing.py", line 214, in run_endpoint_function     return await run_in_threadpool(dependant.call, **values)            ^^^^^^^^^^^^^^^^^^^^^^^^^^^^^^^^^^^^^^^^^^^^^^^^^   File "/Users/nagabhaskar.alaparthi/hackweek-ai-debugger/venv/lib/python3.13/site-packages/starlette/concurrency.py", line 37, in run_in_threadpool     return await anyio.to_thread.run_sync(func)            ^^^^^^^^^^^^^^^^^^^^^^^^^^^^^^^^^^^^   File "/Users/nagabhaskar.alaparthi/hackweek-ai-debugger/venv/lib/python3.13/site-packages/anyio/to_thread.py", line 56, in run_sync     return await get_async_backend().run_sync_in_worker_thread(            ^^^^^^^^^^^^^^^^^^^^^^^^^^^^^^^^^^^^^^^^^^^^^^^^^^^^         func, args, abandon_on_cancel=abandon_on_cancel, limiter=limiter         ^^^^^^^^^^^^^^^^^^^^^^^^^^^^^^^^^^^^^^^^^^^^^^^^^^^^^^^^^^^^^^^^     )     ^   File "/Users/nagabhaskar.alaparthi/hackweek-ai-debugger/venv/lib/python3.13/site-packages/anyio/_backends/_asyncio.py", line 2470, in run_sync_in_worker_thread     return await future            ^^^^^^^^^^^^   File "/Users/nagabhaskar.alaparthi/hackweek-ai-debugger/venv/lib/python3.13/site-packages/anyio/_backends/_asyncio.py", line 967, in run     result = context.run(func, *args)   File "/Users/nagabhaskar.alaparthi/hackweek-ai-debugger/routers/example_router.py", line 20, in trigger_divide_by_zero_error     return ExampleService.simulate_divide_by_zero_error()            ~~~~~~~~~~~~~~~~~~~~~~~~~~~~~~~~~~~~~~~~~~~~^^   File "/Users/nagabhaskar.alaparthi/hackweek-ai-debugger/services/example_service.py", line 23, in simulate_divide_by_zero_error     raise RuntimeError("A division by zero error occurred.") from e RuntimeError: A division by zero error occurred.
2025-04-21 12:59:15,765 - INFO - Extracted method code: 
    @staticmethod
    def simulate_divide_by_zero_error():
        try:
            # Simulate a divide by zero error
            result = 1 / 0
        except ZeroDivisionError as e:
            raise RuntimeError("A division by zero error occurred.") from e


2025-04-21 12:59:15,765 - INFO - Processing error message: 2025-04-21 12:59:14,866 - ERROR - Unhandled exception: Traceback (most recent call last):   File "/Users/nagabhaskar.alaparthi/hackweek-ai-debugger/services/example_service.py", line 21, in simulate_divide_by_zero_error     result = 1 / 0              ~~^~~ ZeroDivisionError: division by zero  The above exception was the direct cause of the following exception:  Traceback (most recent call last):   File "/Users/nagabhaskar.alaparthi/hackweek-ai-debugger/venv/lib/python3.13/site-packages/starlette/middleware/errors.py", line 165, in __call__     await self.app(scope, receive, _send)   File "/Users/nagabhaskar.alaparthi/hackweek-ai-debugger/venv/lib/python3.13/site-packages/starlette/middleware/exceptions.py", line 62, in __call__     await wrap_app_handling_exceptions(self.app, conn)(scope, receive, send)   File "/Users/nagabhaskar.alaparthi/hackweek-ai-debugger/venv/lib/python3.13/site-packages/starlette/_exception_handler.py", line 53, in wrapped_app     raise exc   File "/Users/nagabhaskar.alaparthi/hackweek-ai-debugger/venv/lib/python3.13/site-packages/starlette/_exception_handler.py", line 42, in wrapped_app     await app(scope, receive, sender)   File "/Users/nagabhaskar.alaparthi/hackweek-ai-debugger/venv/lib/python3.13/site-packages/starlette/routing.py", line 714, in __call__     await self.middleware_stack(scope, receive, send)   File "/Users/nagabhaskar.alaparthi/hackweek-ai-debugger/venv/lib/python3.13/site-packages/starlette/routing.py", line 734, in app     await route.handle(scope, receive, send)   File "/Users/nagabhaskar.alaparthi/hackweek-ai-debugger/venv/lib/python3.13/site-packages/starlette/routing.py", line 288, in handle     await self.app(scope, receive, send)   File "/Users/nagabhaskar.alaparthi/hackweek-ai-debugger/venv/lib/python3.13/site-packages/starlette/routing.py", line 76, in app     await wrap_app_handling_exceptions(app, request)(scope, receive, send)   File "/Users/nagabhaskar.alaparthi/hackweek-ai-debugger/venv/lib/python3.13/site-packages/starlette/_exception_handler.py", line 53, in wrapped_app     raise exc   File "/Users/nagabhaskar.alaparthi/hackweek-ai-debugger/venv/lib/python3.13/site-packages/starlette/_exception_handler.py", line 42, in wrapped_app     await app(scope, receive, sender)   File "/Users/nagabhaskar.alaparthi/hackweek-ai-debugger/venv/lib/python3.13/site-packages/starlette/routing.py", line 73, in app     response = await f(request)                ^^^^^^^^^^^^^^^^   File "/Users/nagabhaskar.alaparthi/hackweek-ai-debugger/venv/lib/python3.13/site-packages/fastapi/routing.py", line 301, in app     raw_response = await run_endpoint_function(                    ^^^^^^^^^^^^^^^^^^^^^^^^^^^^     ...<3 lines>...     )     ^   File "/Users/nagabhaskar.alaparthi/hackweek-ai-debugger/venv/lib/python3.13/site-packages/fastapi/routing.py", line 214, in run_endpoint_function     return await run_in_threadpool(dependant.call, **values)            ^^^^^^^^^^^^^^^^^^^^^^^^^^^^^^^^^^^^^^^^^^^^^^^^^   File "/Users/nagabhaskar.alaparthi/hackweek-ai-debugger/venv/lib/python3.13/site-packages/starlette/concurrency.py", line 37, in run_in_threadpool     return await anyio.to_thread.run_sync(func)            ^^^^^^^^^^^^^^^^^^^^^^^^^^^^^^^^^^^^   File "/Users/nagabhaskar.alaparthi/hackweek-ai-debugger/venv/lib/python3.13/site-packages/anyio/to_thread.py", line 56, in run_sync     return await get_async_backend().run_sync_in_worker_thread(            ^^^^^^^^^^^^^^^^^^^^^^^^^^^^^^^^^^^^^^^^^^^^^^^^^^^^         func, args, abandon_on_cancel=abandon_on_cancel, limiter=limiter         ^^^^^^^^^^^^^^^^^^^^^^^^^^^^^^^^^^^^^^^^^^^^^^^^^^^^^^^^^^^^^^^^     )     ^   File "/Users/nagabhaskar.alaparthi/hackweek-ai-debugger/venv/lib/python3.13/site-packages/anyio/_backends/_asyncio.py", line 2470, in run_sync_in_worker_thread     return await future            ^^^^^^^^^^^^   File "/Users/nagabhaskar.alaparthi/hackweek-ai-debugger/venv/lib/python3.13/site-packages/anyio/_backends/_asyncio.py", line 967, in run     result = context.run(func, *args)   File "/Users/nagabhaskar.alaparthi/hackweek-ai-debugger/routers/example_router.py", line 20, in trigger_divide_by_zero_error     return ExampleService.simulate_divide_by_zero_error()            ~~~~~~~~~~~~~~~~~~~~~~~~~~~~~~~~~~~~~~~~~~~~^^   File "/Users/nagabhaskar.alaparthi/hackweek-ai-debugger/services/example_service.py", line 23, in simulate_divide_by_zero_error     raise RuntimeError("A division by zero error occurred.") from e RuntimeError: A division by zero error occurred. 

2025-04-21 12:59:15,765 - INFO - Processing method code: 
    @staticmethod
    def simulate_divide_by_zero_error():
        try:
            # Simulate a divide by zero error
            result = 1 / 0
        except ZeroDivisionError as e:
            raise RuntimeError("A division by zero error occurred.") from e


2025-04-21 12:59:20,260 - INFO - AI Response Text: The error you're encountering is a `ZeroDivisionError`, which occurs when you attempt to divide by zero. In your method `simulate_divide_by_zero_error`, you are intentionally triggering this error with the line `result = 1 / 0`. 

To resolve the issue, you can modify the method to handle the division more safely. Here’s a possible solution:

```python
@staticmethod
def simulate_divide_by_zero_error():
    try:
        # Ensure the denominator is not zero
        denominator = 0
        if denominator == 0:
            raise ValueError("Denominator cannot be zero.")
        result = 1 / denominator
    except ZeroDivisionError as e:
        raise RuntimeError("A division by zero error occurred.") from e
    except ValueError as e:
        raise RuntimeError("A division by zero error occurred due to invalid input.") from e
```

In this modification, we've added a check for the denominator before performing the division, raising a `ValueError` if it is zero. This way, you avoid the `ZeroDivisionError` altogether.
